Workbook

Sheet 總覽
B1: 商品半成品與調理設備應用盤點｜總覽目錄
B3: 盤點基本資訊（黃底請填寫） | E3: 本廠總體統計（自動計算）
B4: 盤點工廠 | E4: 生產總品項數 | F4: =SUM(MAX('18℃'!$AA$5:$AA$319),MAX('4℃飯'!$AA$5:$AA$319),MAX('4℃麵'!$AA$5:$AA$310),MAX('4℃其他'!$AA$5:$AA$322),MAX(冷凍品!$AA$5:$AA$322)) -> 100
B5: 盤點日期 | E5: 半成品總筆數 | F5: =COUNTA('18℃'!$E$5:$E$319)+COUNTA('4℃飯'!$E$5:$E$319)+COUNTA('4℃麵'!$E$5:$E$310)+COUNTA('4℃其他'!$E$5:$E$322)+COUNTA(冷凍品!$E$5:$E$322) -> 535
B6: 盤點負責人 | E6: 資料缺漏/矛盾筆數 | F6: =COUNTIF('18℃'!$V$5:$V$319,"⚠*")+COUNTIF('4℃飯'!$V$5:$V$319,"⚠*")+COUNTIF('4℃麵'!$V$5:$V$310,"⚠*")+COUNTIF('4℃其他'!$V$5:$V$322,"⚠*")+COUNTIF(冷凍品!$V$5:$V$322,"⚠*") -> 0
E7: 單一設備依賴筆數 | F7: =COUNTIF('18℃'!$V$5:$V$319,"▲ 單一設備依賴")+COUNTIF('4℃飯'!$V$5:$V$319,"▲ 單一設備依賴")+COUNTIF('4℃麵'!$V$5:$V$310,"▲ 單一設備依賴")+COUNTIF('4℃其他'!$V$5:$V$322,"▲ 單一設備依賴")+COUNTIF(冷凍品!$V$5:$V$322,"▲ 單一設備依賴") -> 292
E8: 免調理半成品筆數 | F8: =COUNTIF('18℃'!$V$5:$V$319,"○ 免調理")+COUNTIF('4℃飯'!$V$5:$V$319,"○ 免調理")+COUNTIF('4℃麵'!$V$5:$V$310,"○ 免調理")+COUNTIF('4℃其他'!$V$5:$V$322,"○ 免調理")+COUNTIF(冷凍品!$V$5:$V$322,"○ 免調理") -> 171
B10: 商品分類分布
B11: 分類 | C11: 品項數 | D11: 品項佔比 | E11: 半成品筆數 | F11: 半成品佔比
B12: 18℃ | C12: =MAX('18℃'!$AA$5:$AA$319) -> 38 | D12: =IF($F$4=0,0,C12/$F$4) -> 0.38 | E12: =COUNTA('18℃'!$E$5:$E$319) -> 165 | F12: =IF($F$5=0,0,E12/$F$5) -> 0.30841121
B13: 4℃飯 | C13: =MAX('4℃飯'!$AA$5:$AA$319) -> 40 | D13: =IF($F$4=0,0,C13/$F$4) -> 0.4 | E13: =COUNTA('4℃飯'!$E$5:$E$319) -> 254 | F13: =IF($F$5=0,0,E13/$F$5) -> 0.47476636
B14: 4℃麵 | C14: =MAX('4℃麵'!$AA$5:$AA$310) -> 14 | D14: =IF($F$4=0,0,C14/$F$4) -> 0.14 | E14: =COUNTA('4℃麵'!$E$5:$E$310) -> 74 | F14: =IF($F$5=0,0,E14/$F$5) -> 0.13831776
B15: 4℃其他 | C15: =MAX('4℃其他'!$AA$5:$AA$322) -> 8 | D15: =IF($F$4=0,0,C15/$F$4) -> 0.08 | E15: =COUNTA('4℃其他'!$E$5:$E$322) -> 42 | F15: =IF($F$5=0,0,E15/$F$5) -> 0.078504673
B16: 冷凍品 | C16: =MAX(冷凍品!$AA$5:$AA$322) -> 0 | D16: =IF($F$4=0,0,C16/$F$4) -> 0 | E16: =COUNTA(冷凍品!$E$5:$E$322) -> 0 | F16: =IF($F$5=0,0,E16/$F$5) -> 0
B17: 合計 | C17: =SUM(C12:C16) -> 100 | E17: =SUM(E12:E16) -> 535
B19: 商品目錄（自動列出各分頁不重複品項，勿手動修改）
B20: 18℃ | C20: 4℃飯 | D20: 4℃麵 | E20: 4℃其他 | F20: 冷凍品
B21: ="品項數："&MAX('18℃'!$AA$5:$AA$319) -> 品項數：38 | C21: ="品項數："&MAX('4℃飯'!$AA$5:$AA$319) -> 品項數：40 | D21: ="品項數："&MAX('4℃麵'!$AA$5:$AA$310) -> 品項數：14 | E21: ="品項數："&MAX('4℃其他'!$AA$5:$AA$322) -> 品項數：8 | F21: ="品項數："&MAX(冷凍品!$AA$5:$AA$322) -> 品項數：0
B22: =IF(1>MAX('18℃'!$AA$5:$AA$319),"",HYPERLINK("#'18℃'!D"&(MATCH(1,'18℃'!$AA$5:$AA$319,0)+4),INDEX('18℃'!$D$5:$D$319,MATCH(1,'18℃'!$AA$5:$AA$319,0)))) -> 柚檸海灣貝飯糰 | C22: =IF(1>MAX('4℃飯'!$AA$5:$AA$319),"",HYPERLINK("#'4℃飯'!D"&(MATCH(1,'4℃飯'!$AA$5:$AA$319,0)+4),INDEX('4℃飯'!$D$5:$D$319,MATCH(1,'4℃飯'!$AA$5:$AA$319,0)))) -> 日式鮭魚茶泡烤飯 | D22: =IF(1>MAX('4℃麵'!$AA$5:$AA$310),"",HYPERLINK("#'4℃麵'!D"&(MATCH(1,'4℃麵'!$AA$5:$AA$310,0)+4),INDEX('4℃麵'!$D$5:$D$310,MATCH(1,'4℃麵'!$AA$5:$AA$310,0)))) -> 和風涓絲冷麵 | E22: =IF(1>MAX('4℃其他'!$AA$5:$AA$322),"",HYPERLINK("#'4℃其他'!D"&(MATCH(1,'4℃其他'!$AA$5:$AA$322,0)+4),INDEX('4℃其他'!$D$5:$D$322,MATCH(1,'4℃其他'!$AA$5:$AA$322,0)))) -> 越式牛肉寬粉 | F22: =IF(1>MAX('冷凍品'!$AA$5:$AA$322),"",HYPERLINK("#'冷凍品'!D"&(MATCH(1,'冷凍品'!$AA$5:$AA$322,0)+4),INDEX('冷凍品'!$D$5:$D$322,MATCH(1,'冷凍品'!$AA$5:$AA$322,0))))
B23: =IF(2>MAX('18℃'!$AA$5:$AA$319),"",HYPERLINK("#'18℃'!D"&(MATCH(2,'18℃'!$AA$5:$AA$319,0)+4),INDEX('18℃'!$D$5:$D$319,MATCH(2,'18℃'!$AA$5:$AA$319,0)))) -> 筋子銀鮭飯糰 | C23: =IF(2>MAX('4℃飯'!$AA$5:$AA$319),"",HYPERLINK("#'4℃飯'!D"&(MATCH(2,'4℃飯'!$AA$5:$AA$319,0)+4),INDEX('4℃飯'!$D$5:$D$319,MATCH(2,'4℃飯'!$AA$5:$AA$319,0)))) -> 糖燻野郎三十天熟成牛飯(115年) | D23: =IF(2>MAX('4℃麵'!$AA$5:$AA$310),"",HYPERLINK("#'4℃麵'!D"&(MATCH(2,'4℃麵'!$AA$5:$AA$310,0)+4),INDEX('4℃麵'!$D$5:$D$310,MATCH(2,'4℃麵'!$AA$5:$AA$310,0)))) -> 嘉義崇文白醋涼麵 | E23: =IF(2>MAX('4℃其他'!$AA$5:$AA$322),"",HYPERLINK("#'4℃其他'!D"&(MATCH(2,'4℃其他'!$AA$5:$AA$322,0)+4),INDEX('4℃其他'!$D$5:$D$322,MATCH(2,'4℃其他'!$AA$5:$AA$322,0)))) -> 三合一味噌湯 | F23: =IF(2>MAX('冷凍品'!$AA$5:$AA$322),"",HYPERLINK("#'冷凍品'!D"&(MATCH(2,'冷凍品'!$AA$5:$AA$322,0)+4),INDEX('冷凍品'!$D$5:$D$322,MATCH(2,'冷凍品'!$AA$5:$AA$322,0))))
B24: =IF(3>MAX('18℃'!$AA$5:$AA$319),"",HYPERLINK("#'18℃'!D"&(MATCH(3,'18℃'!$AA$5:$AA$319,0)+4),INDEX('18℃'!$D$5:$D$319,MATCH(3,'18℃'!$AA$5:$AA$319,0)))) -> 鮭魚奶油醬油飯糰 | C24: =IF(3>MAX('4℃飯'!$AA$5:$AA$319),"",HYPERLINK("#'4℃飯'!D"&(MATCH(3,'4℃飯'!$AA$5:$AA$319,0)+4),INDEX('4℃飯'!$D$5:$D$319,MATCH(3,'4℃飯'!$AA$5:$AA$319,0)))) -> 健身G肉餐盒 | D24: =IF(3>MAX('4℃麵'!$AA$5:$AA$310),"",HYPERLINK("#'4℃麵'!D"&(MATCH(3,'4℃麵'!$AA$5:$AA$310,0)+4),INDEX('4℃麵'!$D$5:$D$310,MATCH(3,'4℃麵'!$AA$5:$AA$310,0)))) -> 大滿足香辣涼麵(115年) | E24: =IF(3>MAX('4℃其他'!$AA$5:$AA$322),"",HYPERLINK("#'4℃其他'!D"&(MATCH(3,'4℃其他'!$AA$5:$AA$322,0)+4),INDEX('4℃其他'!$D$5:$D$322,MATCH(3,'4℃其他'!$AA$5:$AA$322,0)))) -> 馬鈴薯玉米濃湯 | F24: =IF(3>MAX('冷凍品'!$AA$5:$AA$322),"",HYPERLINK("#'冷凍品'!D"&(MATCH(3,'冷凍品'!$AA$5:$AA$322,0)+4),INDEX('冷凍品'!$D$5:$D$322,MATCH(3,'冷凍品'!$AA$5:$AA$322,0))))
B25: =IF(4>MAX('18℃'!$AA$5:$AA$319),"",HYPERLINK("#'18℃'!D"&(MATCH(4,'18℃'!$AA$5:$AA$319,0)+4),INDEX('18℃'!$D$5:$D$319,MATCH(4,'18℃'!$AA$5:$AA$319,0)))) -> 黑胡椒洋蔥豬飯糰 | C25: =IF(4>MAX('4℃飯'!$AA$5:$AA$319),"",HYPERLINK("#'4℃飯'!D"&(MATCH(4,'4℃飯'!$AA$5:$AA$319,0)+4),INDEX('4℃飯'!$D$5:$D$319,MATCH(4,'4℃飯'!$AA$5:$AA$319,0)))) -> 地中海布格麥烤魚餐盒 | D25: =IF(4>MAX('4℃麵'!$AA$5:$AA$310),"",HYPERLINK("#'4℃麵'!D"&(MATCH(4,'4℃麵'!$AA$5:$AA$310,0)+4),INDEX('4℃麵'!$D$5:$D$310,MATCH(4,'4℃麵'!$AA$5:$AA$310,0)))) -> 大滿足香辣涼麵(區) | E25: =IF(4>MAX('4℃其他'!$AA$5:$AA$322),"",HYPERLINK("#'4℃其他'!D"&(MATCH(4,'4℃其他'!$AA$5:$AA$322,0)+4),INDEX('4℃其他'!$D$5:$D$322,MATCH(4,'4℃其他'!$AA$5:$AA$322,0)))) -> 蒸蛋湯 | F25: =IF(4>MAX('冷凍品'!$AA$5:$AA$322),"",HYPERLINK("#'冷凍品'!D"&(MATCH(4,'冷凍品'!$AA$5:$AA$322,0)+4),INDEX('冷凍品'!$D$5:$D$322,MATCH(4,'冷凍品'!$AA$5:$AA$322,0))))
B26: =IF(5>MAX('18℃'!$AA$5:$AA$319),"",HYPERLINK("#'18℃'!D"&(MATCH(5,'18℃'!$AA$5:$AA$319,0)+4),INDEX('18℃'!$D$5:$D$319,MATCH(5,'18℃'!$AA$5:$AA$319,0)))) -> 三杯醬爆菇菇飯糰 | C26: =IF(5>MAX('4℃飯'!$AA$5:$AA$319),"",HYPERLINK("#'4℃飯'!D"&(MATCH(5,'4℃飯'!$AA$5:$AA$319,0)+4),INDEX('4℃飯'!$D$5:$D$319,MATCH(5,'4℃飯'!$AA$5:$AA$319,0)))) -> 嫩烤香料雞胸排蔬滿盒 | D26: =IF(5>MAX('4℃麵'!$AA$5:$AA$310),"",HYPERLINK("#'4℃麵'!D"&(MATCH(5,'4℃麵'!$AA$5:$AA$310,0)+4),INDEX('4℃麵'!$D$5:$D$310,MATCH(5,'4℃麵'!$AA$5:$AA$310,0)))) -> 大滿足麻醬涼麵(115年) | E26: =IF(5>MAX('4℃其他'!$AA$5:$AA$322),"",HYPERLINK("#'4℃其他'!D"&(MATCH(5,'4℃其他'!$AA$5:$AA$322,0)+4),INDEX('4℃其他'!$D$5:$D$322,MATCH(5,'4℃其他'!$AA$5:$AA$322,0)))) -> 香蕉卡士達泡芙 | F26: =IF(5>MAX('冷凍品'!$AA$5:$AA$322),"",HYPERLINK("#'冷凍品'!D"&(MATCH(5,'冷凍品'!$AA$5:$AA$322,0)+4),INDEX('冷凍品'!$D$5:$D$322,MATCH(5,'冷凍品'!$AA$5:$AA$322,0))))
B27: =IF(6>MAX('18℃'!$AA$5:$AA$319),"",HYPERLINK("#'18℃'!D"&(MATCH(6,'18℃'!$AA$5:$AA$319,0)+4),INDEX('18℃'!$D$5:$D$319,MATCH(6,'18℃'!$AA$5:$AA$319,0)))) -> 大飯糰乾燒風味鮮蝦 | C27: =IF(6>MAX('4℃飯'!$AA$5:$AA$319),"",HYPERLINK("#'4℃飯'!D"&(MATCH(6,'4℃飯'!$AA$5:$AA$319,0)+4),INDEX('4℃飯'!$D$5:$D$319,MATCH(6,'4℃飯'!$AA$5:$AA$319,0)))) -> 懷舊滷雙拼便當 | D27: =IF(6>MAX('4℃麵'!$AA$5:$AA$310),"",HYPERLINK("#'4℃麵'!D"&(MATCH(6,'4℃麵'!$AA$5:$AA$310,0)+4),INDEX('4℃麵'!$D$5:$D$310,MATCH(6,'4℃麵'!$AA$5:$AA$310,0)))) -> 大滿足麻醬涼麵(區) | E27: =IF(6>MAX('4℃其他'!$AA$5:$AA$322),"",HYPERLINK("#'4℃其他'!D"&(MATCH(6,'4℃其他'!$AA$5:$AA$322,0)+4),INDEX('4℃其他'!$D$5:$D$322,MATCH(6,'4℃其他'!$AA$5:$AA$322,0)))) -> 和風豆乳鍋 | F27: =IF(6>MAX('冷凍品'!$AA$5:$AA$322),"",HYPERLINK("#'冷凍品'!D"&(MATCH(6,'冷凍品'!$AA$5:$AA$322,0)+4),INDEX('冷凍品'!$D$5:$D$322,MATCH(6,'冷凍品'!$AA$5:$AA$322,0))))
B28: =IF(7>MAX('18℃'!$AA$5:$AA$319),"",HYPERLINK("#'18℃'!D"&(MATCH(7,'18℃'!$AA$5:$AA$319,0)+4),INDEX('18℃'!$D$5:$D$319,MATCH(7,'18℃'!$AA$5:$AA$319,0)))) -> 大飯糰泡菜鮪魚 | C28: =IF(7>MAX('4℃飯'!$AA$5:$AA$319),"",HYPERLINK("#'4℃飯'!D"&(MATCH(7,'4℃飯'!$AA$5:$AA$319,0)+4),INDEX('4℃飯'!$D$5:$D$319,MATCH(7,'4℃飯'!$AA$5:$AA$319,0)))) -> 海陸雙拼肉肉餐盒 | D28: =IF(7>MAX('4℃麵'!$AA$5:$AA$310),"",HYPERLINK("#'4℃麵'!D"&(MATCH(7,'4℃麵'!$AA$5:$AA$310,0)+4),INDEX('4℃麵'!$D$5:$D$310,MATCH(7,'4℃麵'!$AA$5:$AA$310,0)))) -> 招牌雞絲胡麻涼麵 | E28: =IF(7>MAX('4℃其他'!$AA$5:$AA$322),"",HYPERLINK("#'4℃其他'!D"&(MATCH(7,'4℃其他'!$AA$5:$AA$322,0)+4),INDEX('4℃其他'!$D$5:$D$322,MATCH(7,'4℃其他'!$AA$5:$AA$322,0)))) -> 韓式部隊鍋 | F28: =IF(7>MAX('冷凍品'!$AA$5:$AA$322),"",HYPERLINK("#'冷凍品'!D"&(MATCH(7,'冷凍品'!$AA$5:$AA$322,0)+4),INDEX('冷凍品'!$D$5:$D$322,MATCH(7,'冷凍品'!$AA$5:$AA$322,0))))
B29: =IF(8>MAX('18℃'!$AA$5:$AA$319),"",HYPERLINK("#'18℃'!D"&(MATCH(8,'18℃'!$AA$5:$AA$319,0)+4),INDEX('18℃'!$D$5:$D$319,MATCH(8,'18℃'!$AA$5:$AA$319,0)))) -> 大飯糰韓式蒜烤豬五花 | C29: =IF(8>MAX('4℃飯'!$AA$5:$AA$319),"",HYPERLINK("#'4℃飯'!D"&(MATCH(8,'4℃飯'!$AA$5:$AA$319,0)+4),INDEX('4℃飯'!$D$5:$D$319,MATCH(8,'4℃飯'!$AA$5:$AA$319,0)))) -> 烤蛋白餐盒 | D29: =IF(8>MAX('4℃麵'!$AA$5:$AA$310),"",HYPERLINK("#'4℃麵'!D"&(MATCH(8,'4℃麵'!$AA$5:$AA$310,0)+4),INDEX('4℃麵'!$D$5:$D$310,MATCH(8,'4℃麵'!$AA$5:$AA$310,0)))) -> 日式胡麻雞絲冷麵 | E29: =IF(8>MAX('4℃其他'!$AA$5:$AA$322),"",HYPERLINK("#'4℃其他'!D"&(MATCH(8,'4℃其他'!$AA$5:$AA$322,0)+4),INDEX('4℃其他'!$D$5:$D$322,MATCH(8,'4℃其他'!$AA$5:$AA$322,0)))) -> 莓莓乳酪慕斯蛋糕 | F29: =IF(8>MAX('冷凍品'!$AA$5:$AA$322),"",HYPERLINK("#'冷凍品'!D"&(MATCH(8,'冷凍品'!$AA$5:$AA$322,0)+4),INDEX('冷凍品'!$D$5:$D$322,MATCH(8,'冷凍品'!$AA$5:$AA$322,0))))
B30: =IF(9>MAX('18℃'!$AA$5:$AA$319),"",HYPERLINK("#'18℃'!D"&(MATCH(9,'18℃'!$AA$5:$AA$319,0)+4),INDEX('18℃'!$D$5:$D$319,MATCH(9,'18℃'!$AA$5:$AA$319,0)))) -> 芝麻香鬆飯糰 | C30: =IF(9>MAX('4℃飯'!$AA$5:$AA$319),"",HYPERLINK("#'4℃飯'!D"&(MATCH(9,'4℃飯'!$AA$5:$AA$319,0)+4),INDEX('4℃飯'!$D$5:$D$319,MATCH(9,'4℃飯'!$AA$5:$AA$319,0)))) -> 蔬活腿排補力餐盒 | D30: =IF(9>MAX('4℃麵'!$AA$5:$AA$310),"",HYPERLINK("#'4℃麵'!D"&(MATCH(9,'4℃麵'!$AA$5:$AA$310,0)+4),INDEX('4℃麵'!$D$5:$D$310,MATCH(9,'4℃麵'!$AA$5:$AA$310,0)))) -> 日式蕎麥沾麵 | E30: =IF(9>MAX('4℃其他'!$AA$5:$AA$322),"",HYPERLINK("#'4℃其他'!D"&(MATCH(9,'4℃其他'!$AA$5:$AA$322,0)+4),INDEX('4℃其他'!$D$5:$D$322,MATCH(9,'4℃其他'!$AA$5:$AA$322,0)))) | F30: =IF(9>MAX('冷凍品'!$AA$5:$AA$322),"",HYPERLINK("#'冷凍品'!D"&(MATCH(9,'冷凍品'!$AA$5:$AA$322,0)+4),INDEX('冷凍品'!$D$5:$D$322,MATCH(9,'冷凍品'!$AA$5:$AA$322,0))))
B31: =IF(10>MAX('18℃'!$AA$5:$AA$319),"",HYPERLINK("#'18℃'!D"&(MATCH(10,'18℃'!$AA$5:$AA$319,0)+4),INDEX('18℃'!$D$5:$D$319,MATCH(10,'18℃'!$AA$5:$AA$319,0)))) -> 北海道秋鮭親子飯糰 | C31: =IF(10>MAX('4℃飯'!$AA$5:$AA$319),"",HYPERLINK("#'4℃飯'!D"&(MATCH(10,'4℃飯'!$AA$5:$AA$319,0)+4),INDEX('4℃飯'!$D$5:$D$319,MATCH(10,'4℃飯'!$AA$5:$AA$319,0)))) -> 香檸奶油魚排蔬滿盒 | D31: =IF(10>MAX('4℃麵'!$AA$5:$AA$310),"",HYPERLINK("#'4℃麵'!D"&(MATCH(10,'4℃麵'!$AA$5:$AA$310,0)+4),INDEX('4℃麵'!$D$5:$D$310,MATCH(10,'4℃麵'!$AA$5:$AA$310,0)))) -> 月見烏龍冷麵 | E31: =IF(10>MAX('4℃其他'!$AA$5:$AA$322),"",HYPERLINK("#'4℃其他'!D"&(MATCH(10,'4℃其他'!$AA$5:$AA$322,0)+4),INDEX('4℃其他'!$D$5:$D$322,MATCH(10,'4℃其他'!$AA$5:$AA$322,0)))) | F31: =IF(10>MAX('冷凍品'!$AA$5:$AA$322),"",HYPERLINK("#'冷凍品'!D"&(MATCH(10,'冷凍品'!$AA$5:$AA$322,0)+4),INDEX('冷凍品'!$D$5:$D$322,MATCH(10,'冷凍品'!$AA$5:$AA$322,0))))
B32: =IF(11>MAX('18℃'!$AA$5:$AA$319),"",HYPERLINK("#'18℃'!D"&(MATCH(11,'18℃'!$AA$5:$AA$319,0)+4),INDEX('18℃'!$D$5:$D$319,MATCH(11,'18℃'!$AA$5:$AA$319,0)))) -> 壹號醬炙烤牛飯糰 | C32: =IF(11>MAX('4℃飯'!$AA$5:$AA$319),"",HYPERLINK("#'4℃飯'!D"&(MATCH(11,'4℃飯'!$AA$5:$AA$319,0)+4),INDEX('4℃飯'!$D$5:$D$319,MATCH(11,'4℃飯'!$AA$5:$AA$319,0)))) -> 香腸腿排雙拼便當 | D32: =IF(11>MAX('4℃麵'!$AA$5:$AA$310),"",HYPERLINK("#'4℃麵'!D"&(MATCH(11,'4℃麵'!$AA$5:$AA$310,0)+4),INDEX('4℃麵'!$D$5:$D$310,MATCH(11,'4℃麵'!$AA$5:$AA$310,0)))) -> 韓式泡菜冷麵 | E32: =IF(11>MAX('4℃其他'!$AA$5:$AA$322),"",HYPERLINK("#'4℃其他'!D"&(MATCH(11,'4℃其他'!$AA$5:$AA$322,0)+4),INDEX('4℃其他'!$D$5:$D$322,MATCH(11,'4℃其他'!$AA$5:$AA$322,0)))) | F32: =IF(11>MAX('冷凍品'!$AA$5:$AA$322),"",HYPERLINK("#'冷凍品'!D"&(MATCH(11,'冷凍品'!$AA$5:$AA$322,0)+4),INDEX('冷凍品'!$D$5:$D$322,MATCH(11,'冷凍品'!$AA$5:$AA$322,0))))
B33: =IF(12>MAX('18℃'!$AA$5:$AA$319),"",HYPERLINK("#'18℃'!D"&(MATCH(12,'18℃'!$AA$5:$AA$319,0)+4),INDEX('18℃'!$D$5:$D$319,MATCH(12,'18℃'!$AA$5:$AA$319,0)))) -> 明太子龍蝦風味沙拉飯糰 | C33: =IF(12>MAX('4℃飯'!$AA$5:$AA$319),"",HYPERLINK("#'4℃飯'!D"&(MATCH(12,'4℃飯'!$AA$5:$AA$319,0)+4),INDEX('4℃飯'!$D$5:$D$319,MATCH(12,'4℃飯'!$AA$5:$AA$319,0)))) -> 哞哞培根奶香海陸焗飯 | D33: =IF(12>MAX('4℃麵'!$AA$5:$AA$310),"",HYPERLINK("#'4℃麵'!D"&(MATCH(12,'4℃麵'!$AA$5:$AA$310,0)+4),INDEX('4℃麵'!$D$5:$D$310,MATCH(12,'4℃麵'!$AA$5:$AA$310,0)))) -> 麻油菇菇拌麵 | E33: =IF(12>MAX('4℃其他'!$AA$5:$AA$322),"",HYPERLINK("#'4℃其他'!D"&(MATCH(12,'4℃其他'!$AA$5:$AA$322,0)+4),INDEX('4℃其他'!$D$5:$D$322,MATCH(12,'4℃其他'!$AA$5:$AA$322,0)))) | F33: =IF(12>MAX('冷凍品'!$AA$5:$AA$322),"",HYPERLINK("#'冷凍品'!D"&(MATCH(12,'冷凍品'!$AA$5:$AA$322,0)+4),INDEX('冷凍品'!$D$5:$D$322,MATCH(12,'冷凍品'!$AA$5:$AA$322,0))))
B34: =IF(13>MAX('18℃'!$AA$5:$AA$319),"",HYPERLINK("#'18℃'!D"&(MATCH(13,'18℃'!$AA$5:$AA$319,0)+4),INDEX('18℃'!$D$5:$D$319,MATCH(13,'18℃'!$AA$5:$AA$319,0)))) -> 熟成紅鮭飯糰 | C34: =IF(13>MAX('4℃飯'!$AA$5:$AA$319),"",HYPERLINK("#'4℃飯'!D"&(MATCH(13,'4℃飯'!$AA$5:$AA$319,0)+4),INDEX('4℃飯'!$D$5:$D$319,MATCH(13,'4℃飯'!$AA$5:$AA$319,0)))) -> 濃起司燻腸紅醬焗烤飯 | D34: =IF(13>MAX('4℃麵'!$AA$5:$AA$310),"",HYPERLINK("#'4℃麵'!D"&(MATCH(13,'4℃麵'!$AA$5:$AA$310,0)+4),INDEX('4℃麵'!$D$5:$D$310,MATCH(13,'4℃麵'!$AA$5:$AA$310,0)))) -> 松露雞白湯拉麵 | E34: =IF(13>MAX('4℃其他'!$AA$5:$AA$322),"",HYPERLINK("#'4℃其他'!D"&(MATCH(13,'4℃其他'!$AA$5:$AA$322,0)+4),INDEX('4℃其他'!$D$5:$D$322,MATCH(13,'4℃其他'!$AA$5:$AA$322,0)))) | F34: =IF(13>MAX('冷凍品'!$AA$5:$AA$322),"",HYPERLINK("#'冷凍品'!D"&(MATCH(13,'冷凍品'!$AA$5:$AA$322,0)+4),INDEX('冷凍品'!$D$5:$D$322,MATCH(13,'冷凍品'!$AA$5:$AA$322,0))))
B35: =IF(14>MAX('18℃'!$AA$5:$AA$319),"",HYPERLINK("#'18℃'!D"&(MATCH(14,'18℃'!$AA$5:$AA$319,0)+4),INDEX('18℃'!$D$5:$D$319,MATCH(14,'18℃'!$AA$5:$AA$319,0)))) -> 經典肉鬆飯糰 | C35: =IF(14>MAX('4℃飯'!$AA$5:$AA$319),"",HYPERLINK("#'4℃飯'!D"&(MATCH(14,'4℃飯'!$AA$5:$AA$319,0)+4),INDEX('4℃飯'!$D$5:$D$319,MATCH(14,'4℃飯'!$AA$5:$AA$319,0)))) -> 西班牙風味海鮮燉飯 | D35: =IF(14>MAX('4℃麵'!$AA$5:$AA$310),"",HYPERLINK("#'4℃麵'!D"&(MATCH(14,'4℃麵'!$AA$5:$AA$310,0)+4),INDEX('4℃麵'!$D$5:$D$310,MATCH(14,'4℃麵'!$AA$5:$AA$310,0)))) -> 東京豚骨風味拉麵 | E35: =IF(14>MAX('4℃其他'!$AA$5:$AA$322),"",HYPERLINK("#'4℃其他'!D"&(MATCH(14,'4℃其他'!$AA$5:$AA$322,0)+4),INDEX('4℃其他'!$D$5:$D$322,MATCH(14,'4℃其他'!$AA$5:$AA$322,0)))) | F35: =IF(14>MAX('冷凍品'!$AA$5:$AA$322),"",HYPERLINK("#'冷凍品'!D"&(MATCH(14,'冷凍品'!$AA$5:$AA$322,0)+4),INDEX('冷凍品'!$D$5:$D$322,MATCH(14,'冷凍品'!$AA$5:$AA$322,0))))
B36: =IF(15>MAX('18℃'!$AA$5:$AA$319),"",HYPERLINK("#'18℃'!D"&(MATCH(15,'18℃'!$AA$5:$AA$319,0)+4),INDEX('18℃'!$D$5:$D$319,MATCH(15,'18℃'!$AA$5:$AA$319,0)))) -> 蔬食鮪魚飯糰 | C36: =IF(15>MAX('4℃飯'!$AA$5:$AA$319),"",HYPERLINK("#'4℃飯'!D"&(MATCH(15,'4℃飯'!$AA$5:$AA$319,0)+4),INDEX('4℃飯'!$D$5:$D$319,MATCH(15,'4℃飯'!$AA$5:$AA$319,0)))) -> 里肌豬排可可咖哩歐姆蛋飯 | D36: =IF(15>MAX('4℃麵'!$AA$5:$AA$310),"",HYPERLINK("#'4℃麵'!D"&(MATCH(15,'4℃麵'!$AA$5:$AA$310,0)+4),INDEX('4℃麵'!$D$5:$D$310,MATCH(15,'4℃麵'!$AA$5:$AA$310,0)))) | E36: =IF(15>MAX('4℃其他'!$AA$5:$AA$322),"",HYPERLINK("#'4℃其他'!D"&(MATCH(15,'4℃其他'!$AA$5:$AA$322,0)+4),INDEX('4℃其他'!$D$5:$D$322,MATCH(15,'4℃其他'!$AA$5:$AA$322,0)))) | F36: =IF(15>MAX('冷凍品'!$AA$5:$AA$322),"",HYPERLINK("#'冷凍品'!D"&(MATCH(15,'冷凍品'!$AA$5:$AA$322,0)+4),INDEX('冷凍品'!$D$5:$D$322,MATCH(15,'冷凍品'!$AA$5:$AA$322,0))))
B37: =IF(16>MAX('18℃'!$AA$5:$AA$319),"",HYPERLINK("#'18℃'!D"&(MATCH(16,'18℃'!$AA$5:$AA$319,0)+4),INDEX('18℃'!$D$5:$D$319,MATCH(16,'18℃'!$AA$5:$AA$319,0)))) -> 贅沢鮭魚肚飯糰 | C37: =IF(16>MAX('4℃飯'!$AA$5:$AA$319),"",HYPERLINK("#'4℃飯'!D"&(MATCH(16,'4℃飯'!$AA$5:$AA$319,0)+4),INDEX('4℃飯'!$D$5:$D$319,MATCH(16,'4℃飯'!$AA$5:$AA$319,0)))) -> 香料烤魚青醬燉飯 | D37: =IF(16>MAX('4℃麵'!$AA$5:$AA$310),"",HYPERLINK("#'4℃麵'!D"&(MATCH(16,'4℃麵'!$AA$5:$AA$310,0)+4),INDEX('4℃麵'!$D$5:$D$310,MATCH(16,'4℃麵'!$AA$5:$AA$310,0)))) | E37: =IF(16>MAX('4℃其他'!$AA$5:$AA$322),"",HYPERLINK("#'4℃其他'!D"&(MATCH(16,'4℃其他'!$AA$5:$AA$322,0)+4),INDEX('4℃其他'!$D$5:$D$322,MATCH(16,'4℃其他'!$AA$5:$AA$322,0)))) | F37: =IF(16>MAX('冷凍品'!$AA$5:$AA$322),"",HYPERLINK("#'冷凍品'!D"&(MATCH(16,'冷凍品'!$AA$5:$AA$322,0)+4),INDEX('冷凍品'!$D$5:$D$322,MATCH(16,'冷凍品'!$AA$5:$AA$322,0))))
B38: =IF(17>MAX('18℃'!$AA$5:$AA$319),"",HYPERLINK("#'18℃'!D"&(MATCH(17,'18℃'!$AA$5:$AA$319,0)+4),INDEX('18℃'!$D$5:$D$319,MATCH(17,'18℃'!$AA$5:$AA$319,0)))) -> 雞肉飯飯糰 | C38: =IF(17>MAX('4℃飯'!$AA$5:$AA$319),"",HYPERLINK("#'4℃飯'!D"&(MATCH(17,'4℃飯'!$AA$5:$AA$319,0)+4),INDEX('4℃飯'!$D$5:$D$319,MATCH(17,'4℃飯'!$AA$5:$AA$319,0)))) -> 黃金雞排蘑菇白醬歐姆蛋飯 | D38: =IF(17>MAX('4℃麵'!$AA$5:$AA$310),"",HYPERLINK("#'4℃麵'!D"&(MATCH(17,'4℃麵'!$AA$5:$AA$310,0)+4),INDEX('4℃麵'!$D$5:$D$310,MATCH(17,'4℃麵'!$AA$5:$AA$310,0)))) | E38: =IF(17>MAX('4℃其他'!$AA$5:$AA$322),"",HYPERLINK("#'4℃其他'!D"&(MATCH(17,'4℃其他'!$AA$5:$AA$322,0)+4),INDEX('4℃其他'!$D$5:$D$322,MATCH(17,'4℃其他'!$AA$5:$AA$322,0)))) | F38: =IF(17>MAX('冷凍品'!$AA$5:$AA$322),"",HYPERLINK("#'冷凍品'!D"&(MATCH(17,'冷凍品'!$AA$5:$AA$322,0)+4),INDEX('冷凍品'!$D$5:$D$322,MATCH(17,'冷凍品'!$AA$5:$AA$322,0))))
B39: =IF(18>MAX('18℃'!$AA$5:$AA$319),"",HYPERLINK("#'18℃'!D"&(MATCH(18,'18℃'!$AA$5:$AA$319,0)+4),INDEX('18℃'!$D$5:$D$319,MATCH(18,'18℃'!$AA$5:$AA$319,0)))) -> 鮪魚飯糰 | C39: =IF(18>MAX('4℃飯'!$AA$5:$AA$319),"",HYPERLINK("#'4℃飯'!D"&(MATCH(18,'4℃飯'!$AA$5:$AA$319,0)+4),INDEX('4℃飯'!$D$5:$D$319,MATCH(18,'4℃飯'!$AA$5:$AA$319,0)))) -> 益活雞胸補力餐盒 | D39: =IF(18>MAX('4℃麵'!$AA$5:$AA$310),"",HYPERLINK("#'4℃麵'!D"&(MATCH(18,'4℃麵'!$AA$5:$AA$310,0)+4),INDEX('4℃麵'!$D$5:$D$310,MATCH(18,'4℃麵'!$AA$5:$AA$310,0)))) | E39: =IF(18>MAX('4℃其他'!$AA$5:$AA$322),"",HYPERLINK("#'4℃其他'!D"&(MATCH(18,'4℃其他'!$AA$5:$AA$322,0)+4),INDEX('4℃其他'!$D$5:$D$322,MATCH(18,'4℃其他'!$AA$5:$AA$322,0)))) | F39: =IF(18>MAX('冷凍品'!$AA$5:$AA$322),"",HYPERLINK("#'冷凍品'!D"&(MATCH(18,'冷凍品'!$AA$5:$AA$322,0)+4),INDEX('冷凍品'!$D$5:$D$322,MATCH(18,'冷凍品'!$AA$5:$AA$322,0))))
B40: =IF(19>MAX('18℃'!$AA$5:$AA$319),"",HYPERLINK("#'18℃'!D"&(MATCH(19,'18℃'!$AA$5:$AA$319,0)+4),INDEX('18℃'!$D$5:$D$319,MATCH(19,'18℃'!$AA$5:$AA$319,0)))) -> 鹽蔥燒肉飯糰 | C40: =IF(19>MAX('4℃飯'!$AA$5:$AA$319),"",HYPERLINK("#'4℃飯'!D"&(MATCH(19,'4℃飯'!$AA$5:$AA$319,0)+4),INDEX('4℃飯'!$D$5:$D$319,MATCH(19,'4℃飯'!$AA$5:$AA$319,0)))) -> 香烤鱈魚輕蔬餐盒 | D40: =IF(19>MAX('4℃麵'!$AA$5:$AA$310),"",HYPERLINK("#'4℃麵'!D"&(MATCH(19,'4℃麵'!$AA$5:$AA$310,0)+4),INDEX('4℃麵'!$D$5:$D$310,MATCH(19,'4℃麵'!$AA$5:$AA$310,0)))) | E40: =IF(19>MAX('4℃其他'!$AA$5:$AA$322),"",HYPERLINK("#'4℃其他'!D"&(MATCH(19,'4℃其他'!$AA$5:$AA$322,0)+4),INDEX('4℃其他'!$D$5:$D$322,MATCH(19,'4℃其他'!$AA$5:$AA$322,0)))) | F40: =IF(19>MAX('冷凍品'!$AA$5:$AA$322),"",HYPERLINK("#'冷凍品'!D"&(MATCH(19,'冷凍品'!$AA$5:$AA$322,0)+4),INDEX('冷凍品'!$D$5:$D$322,MATCH(19,'冷凍品'!$AA$5:$AA$322,0))))
B41: =IF(20>MAX('18℃'!$AA$5:$AA$319),"",HYPERLINK("#'18℃'!D"&(MATCH(20,'18℃'!$AA$5:$AA$319,0)+4),INDEX('18℃'!$D$5:$D$319,MATCH(20,'18℃'!$AA$5:$AA$319,0)))) -> 鮭魚毛豆炊飯飯糰 | C41: =IF(20>MAX('4℃飯'!$AA$5:$AA$319),"",HYPERLINK("#'4℃飯'!D"&(MATCH(20,'4℃飯'!$AA$5:$AA$319,0)+4),INDEX('4℃飯'!$D$5:$D$319,MATCH(20,'4℃飯'!$AA$5:$AA$319,0)))) -> 香濃明太子嫩雞飯卷 | D41: =IF(20>MAX('4℃麵'!$AA$5:$AA$310),"",HYPERLINK("#'4℃麵'!D"&(MATCH(20,'4℃麵'!$AA$5:$AA$310,0)+4),INDEX('4℃麵'!$D$5:$D$310,MATCH(20,'4℃麵'!$AA$5:$AA$310,0)))) | E41: =IF(20>MAX('4℃其他'!$AA$5:$AA$322),"",HYPERLINK("#'4℃其他'!D"&(MATCH(20,'4℃其他'!$AA$5:$AA$322,0)+4),INDEX('4℃其他'!$D$5:$D$322,MATCH(20,'4℃其他'!$AA$5:$AA$322,0)))) | F41: =IF(20>MAX('冷凍品'!$AA$5:$AA$322),"",HYPERLINK("#'冷凍品'!D"&(MATCH(20,'冷凍品'!$AA$5:$AA$322,0)+4),INDEX('冷凍品'!$D$5:$D$322,MATCH(20,'冷凍品'!$AA$5:$AA$322,0))))
B42: =IF(21>MAX('18℃'!$AA$5:$AA$319),"",HYPERLINK("#'18℃'!D"&(MATCH(21,'18℃'!$AA$5:$AA$319,0)+4),INDEX('18℃'!$D$5:$D$319,MATCH(21,'18℃'!$AA$5:$AA$319,0)))) -> 兩粒飯糰 (鮪魚.焦糖鮭魚) | C42: =IF(21>MAX('4℃飯'!$AA$5:$AA$319),"",HYPERLINK("#'4℃飯'!D"&(MATCH(21,'4℃飯'!$AA$5:$AA$319,0)+4),INDEX('4℃飯'!$D$5:$D$319,MATCH(21,'4℃飯'!$AA$5:$AA$319,0)))) -> 經典傳統飯糰 | D42: =IF(21>MAX('4℃麵'!$AA$5:$AA$310),"",HYPERLINK("#'4℃麵'!D"&(MATCH(21,'4℃麵'!$AA$5:$AA$310,0)+4),INDEX('4℃麵'!$D$5:$D$310,MATCH(21,'4℃麵'!$AA$5:$AA$310,0)))) | E42: =IF(21>MAX('4℃其他'!$AA$5:$AA$322),"",HYPERLINK("#'4℃其他'!D"&(MATCH(21,'4℃其他'!$AA$5:$AA$322,0)+4),INDEX('4℃其他'!$D$5:$D$322,MATCH(21,'4℃其他'!$AA$5:$AA$322,0)))) | F42: =IF(21>MAX('冷凍品'!$AA$5:$AA$322),"",HYPERLINK("#'冷凍品'!D"&(MATCH(21,'冷凍品'!$AA$5:$AA$322,0)+4),INDEX('冷凍品'!$D$5:$D$322,MATCH(21,'冷凍品'!$AA$5:$AA$322,0))))
B43: =IF(22>MAX('18℃'!$AA$5:$AA$319),"",HYPERLINK("#'18℃'!D"&(MATCH(22,'18℃'!$AA$5:$AA$319,0)+4),INDEX('18℃'!$D$5:$D$319,MATCH(22,'18℃'!$AA$5:$AA$319,0)))) -> 柚香雞胸五穀飯糰 | C43: =IF(22>MAX('4℃飯'!$AA$5:$AA$319),"",HYPERLINK("#'4℃飯'!D"&(MATCH(22,'4℃飯'!$AA$5:$AA$319,0)+4),INDEX('4℃飯'!$D$5:$D$319,MATCH(22,'4℃飯'!$AA$5:$AA$319,0)))) -> 里肌肉蛋紫米飯糰 | D43: =IF(22>MAX('4℃麵'!$AA$5:$AA$310),"",HYPERLINK("#'4℃麵'!D"&(MATCH(22,'4℃麵'!$AA$5:$AA$310,0)+4),INDEX('4℃麵'!$D$5:$D$310,MATCH(22,'4℃麵'!$AA$5:$AA$310,0)))) | E43: =IF(22>MAX('4℃其他'!$AA$5:$AA$322),"",HYPERLINK("#'4℃其他'!D"&(MATCH(22,'4℃其他'!$AA$5:$AA$322,0)+4),INDEX('4℃其他'!$D$5:$D$322,MATCH(22,'4℃其他'!$AA$5:$AA$322,0)))) | F43: =IF(22>MAX('冷凍品'!$AA$5:$AA$322),"",HYPERLINK("#'冷凍品'!D"&(MATCH(22,'冷凍品'!$AA$5:$AA$322,0)+4),INDEX('冷凍品'!$D$5:$D$322,MATCH(22,'冷凍品'!$AA$5:$AA$322,0))))
...

Sheet 填寫說明
B2: 商品半成品與調理設備應用展開一覽表｜填寫說明
B4: 目的 | C4: 盤點本廠商品之半成品組成，及各半成品應用之熱調理設備，據以掌握設備應用狀態（初步以「應用半成品數」衡量），並透過風險示警提前辨識設備依賴集中與資料缺漏。本檔為單一工廠使用，每廠一檔。
B6: 工作表結構 | C6: 「總覽」可點商品名稱跳至明細；五個溫層分頁填寫半成品與設備。「設備應用統計」自動彙總，僅藍字門檻可調整。
B7: 分頁歸類原則 | C7: 商品依販售溫層與品類歸入對應分頁；同一商品的所有半成品填在同一分頁。分頁內的「商品分類」欄可再填細分品類（如飯糰、壽司、便當、涼麵、甜點等）。
B9: 填寫規則 1 | C9: 填寫字體規範「微軟正黑體」，字體大小「10」號
B10: 填寫規則 2 | C10: 每一列代表「一個商品 × 一項半成品」。同一商品有 3 項半成品即填 3 列，且每列的工廠、商品名稱都要填（勿留空、勿合併儲存格），統計公式才能正確計算。
B11: 填寫規則 3 | C11: 有使用調理設備時，在該設備欄下拉選「V」。完全不經調理時，僅於「無使用調理設備」選「V」，不可同時勾選。
B12: 填寫規則 4 | C12: 單位用量分兩欄：「數值」填數字、「單位」下拉選公克或個。製程率直接填數字（如 92），系統自動顯示為 92%。尚未確認者可先留白，不影響設備統計。
B13: 填寫規則 5 | C13: 每列須填「建檔人員」，作為資料追溯窗口。「備註」請註記指示書編號與版本日期，依各分頁欄名填寫。
B14: 填寫規則 6 | C14: 最右側「系統用」隱藏欄自動計算商品目錄與品項數，請勿貼上數值或手動修改。
B16: 風險示警邏輯 | C16: 門檻可於「設備應用統計」C3:C5 藍字儲存格調整。檢核結果共五種狀態：
B17: ⚠ 資料缺漏（紅） | C17: 半成品已填名稱，但 11 個設備欄與「無使用調理設備」皆未勾選 → 須補填，或確認為免調理並勾選「無使用調理設備」。
B18: ⚠ 勾選矛盾（紅） | C18: 同時勾選「無使用調理設備」與任一設備欄 → 邏輯矛盾，請擇一修正。
... B25: 自動資料檢查 | C25: 以下以已填商品或半成品的資料列檢查。數量按明細列計，同一商品可有多列。
B26: 狀態未填（列） | C26: =SUM(COUNTIFS('18℃'!$D$5:$D$319,"<>",'18℃'!$A$5:$A$319,""),COUNTIFS('4℃飯'!$D$5:$D$319,"<>",'4℃飯'!$A$5:$A$319,""),COUNTIFS('4℃麵'!$D$5:$D$310,"<>",'4℃麵'!$A$5:$A$310,""),COUNTIFS('4℃其他'!$D$5:$D$322,"<>",'4℃其他'!$A$5:$A$322,""),COUNTIFS('冷凍品'!$D$5:$D$322,"<>",'冷凍品'!$B$5:$B$322,"")) -> 0
B27: 半成品名稱未填（列） | C27: =SUM(COUNTIFS('18℃'!$D$5:$D$319,"<>",'18℃'!$E$5:$E$319,""),COUNTIFS('4℃飯'!$D$5:$D$319,"<>",'4℃飯'!$E$5:$E$319,""),COUNTIFS('4℃麵'!$D$5:$D$310,"<>",'4℃麵'!$E$5:$E$310,""),COUNTIFS('4℃其他'!$D$5:$D$322,"<>",'4℃其他'!$E$5:$E$322,""),COUNTIFS('冷凍品'!$D$5:$D$322,"<>",'冷凍品'!$E$5:$E$322,"")) -> 0
B28: 設備未勾選（列） | C28: =SUM(COUNTIF('18℃'!$V$5:$V$319,"⚠ 資料缺漏"),COUNTIF('4℃飯'!$V$5:$V$319,"⚠ 資料缺漏"),COUNTIF('4℃麵'!$V$5:$V$310,"⚠ 資料缺漏"),COUNTIF('4℃其他'!$V$5:$V$322,"⚠ 資料缺漏"),COUNTIF('冷凍品'!$V$5:$V$322,"⚠ 資料缺漏")) -> 0
B29: 設備勾選矛盾（列） | C29: =SUM(COUNTIF('18℃'!$V$5:$V$319,"⚠ 勾選矛盾"),COUNTIF('4℃飯'!$V$5:$V$319,"⚠ 勾選矛盾"),COUNTIF('4℃麵'!$V$5:$V$310,"⚠ 勾選矛盾"),COUNTIF('4℃其他'!$V$5:$V$322,"⚠ 勾選矛盾"),COUNTIF('冷凍品'!$V$5:$V$322,"⚠ 勾選矛盾")) -> 0
B30: 建檔人員未填（列） | C30: =SUM(COUNTIFS('18℃'!$E$5:$E$319,"<>",'18℃'!$Y$5:$Y$319,""),COUNTIFS('4℃飯'!$E$5:$E$319,"<>",'4℃飯'!$Y$5:$Y$319,""),COUNTIFS('4℃麵'!$E$5:$E$310,"<>",'4℃麵'!$Y$5:$Y$310,""),COUNTIFS('4℃其他'!$E$5:$E$322,"<>",'4℃其他'!$Y$5:$Y$322,""),COUNTIFS('冷凍品'!$E$5:$E$322,"<>",'冷凍品'!$Y$5:$Y$322,"")) -> 299
B31: 工廠不符或未填（列） | C31: =SUM(COUNTIFS('18℃'!$E$5:$E$319,"<>",'18℃'!$B$5:$B$319,"<>大溪"),COUNTIFS('4℃飯'!$E$5:$E$319,"<>",'4℃飯'!$B$5:$B$319,"<>大溪"),COUNTIFS('4℃麵'!$E$5:$E$310,"<>",'4℃麵'!$B$5:$B$310,"<>大溪"),COUNTIFS('4℃其他'!$E$5:$E$322,"<>",'4℃其他'!$B$5:$B$322,"<>大溪"),COUNTIFS('冷凍品'!$E$5:$E$322,"<>",'冷凍品'!$A$5:$A$322,"<>大溪")) -> 0
B32: 用量有值但單位未填（列） | C32: =SUM(COUNTIFS('18℃'!$E$5:$E$319,"<>",'18℃'!$F$5:$F$319,"<>",'18℃'!$G$5:$G$319,""),COUNTIFS('4℃飯'!$E$5:$E$319,"<>",'4℃飯'!$F$5:$F$319,"<>",'4℃飯'!$G$5:$G$319,""),COUNTIFS('4℃麵'!$E$5:$E$310,"<>",'4℃麵'!$F$5:$F$310,"<>",'4℃麵'!$G$5:$G$310,""),COUNTIFS('4℃其他'!$E$5:$E$322,"<>",'4℃其他'!$F$5:$F$322,"<>",'4℃其他'!$G$5:$G$322,""),COUNTIFS('冷凍品'!$E$5:$E$322,"<>",'冷凍品'!$F$5:$F$322,"<>",'冷凍品'!$G$5:$G$322,"")) -> 0
B34: 狀態判定基準 | C34: 本次已確認狀態依2026/10/14訂單與逐項確認結果。未上市商品保留待上架。後續更新需先確認訂單日期。
B35: 篩選與色彩 | C35: 狀態欄可篩選架上、下架、待上架。橘色表示狀態漏填或同商品不一致；淡黃表示建檔人員或單位待補。
B36: 批次更新同一商品 | C36: 先用商品名稱篩選，選取該商品可見的狀態儲存格，按 Alt+; 僅選可見儲存格，輸入狀態後按 Ctrl+Enter。
B37: 新增商品或半成品 | C37: 請在現有表格範圍內插入整列，再複製相鄰整列的格式、公式與選單，清除輸入資料後填寫新內容。
B38: 保留未確認內容 | C38: 未有依據的建檔人員、用量與單位不代填。未設狀態欄的分頁不納入狀態漏填檢查，既有「-」保留待確認。

Sheet 18℃
A1: 商品半成品與調理設備應用展開一覽表｜18℃
A2: 商品資訊 | I2: 熱調理區（使用者填「V」；免調理者勾最右欄） | U2: 自動計算與風險檢核（勿手動修改） | X2: 建檔資訊（手填）
A3: 狀態 | B3: 工廠 | C3: 商品分類 (細分品類) | D3: 商品名稱 | E3: 半成品名稱 | F3: 單位用量 | H3: 製程率 (填數字) | I3: 炊飯 | J3: 煮麵 | K3: 烤箱 | L3: 炙燒 | M3: 蒸箱 | N3: 油炸機 | O3: 二重釜 | P3: 平釜 (日) | Q3: 平釜 (台) | R3: 蛋皮機 | S3: 壓力鍋 | T3: 無使用 調理設備 | U3: 使用 設備數 | V3: 檢核結果 | W3: 風險說明 | X3: 備註 (指示書編號/版本) | Y3: 建檔人員 | Z3: 系統用Y | AA3: 系統用Z
F4: 數值 | G4: 單位
A5: 下架 | B5: 大溪 | C5: 飯糰 | D5: 柚檸海灣貝飯糰 | E5: 煮一見鍾情飯 | F5: 95 | G5: 公克 | H5: 92.5 | I5: V | O5: V | U5: =IF($E5="","",COUNTIF($I5:$S5,"V")) -> 2 | V5: =IF($E5="","",IF(AND($T5="V",$U5>0),"⚠ 勾選矛盾",IF($T5="V","○ 免調理",IF($U5=0,"⚠ 資料缺漏",IF($U5=1,"▲ 單一設備依賴","OK"))))) -> OK | W5: =IF($E5="","",IF(AND($T5="V",$U5>0),"「無使用調理設備」不可與設備欄同時勾選，請擇一修正",IF($T5="V","免調理半成品（外購/僅切配等），不列入設備風險評估",IF($U5=0,"未勾選任何設備，請補填或勾選「無使用調理設備」",IF($U5=1,"僅依賴1台設備，須確認故障/排修時之備援製程","無異常"))))) -> 無異常 | X5: 大溪廠_2026.04.15_柚檸海灣貝飯糰_2026.07校正 | Z5: =IF($D5="",0,IF(COUNTIF($D$5:$D5,$D5)=1,1,0)) -> 1 | AA5: =IF(Z5=1,SUM($Z$5:$Z5),"") -> 1
A6: 下架 | B6: 大溪 | C6: 飯糰 | D6: 柚檸海灣貝飯糰 | E6: 煮柚檸醬油 | F6: 4 | G6: 公克 | H6: 57.8 | O6: V | U6: =IF($E6="","",COUNTIF($I6:$S6,"V")) -> 1 | V6: =IF($E6="","",IF(AND($T6="V",$U6>0),"⚠ 勾選矛盾",IF($T6="V","○ 免調理",IF($U6=0,"⚠ 資料缺漏",IF($U6=1,"▲ 單一設備依賴","OK"))))) -> ▲ 單一設備依賴 | W6: =IF($E6="","",IF(AND($T6="V",$U6>0),"「無使用調理設備」不可與設備欄同時勾選，請擇一修正",IF($T6="V","免調理半成品（外購/僅切配等），不列入設備風險評估",IF($U6=0,"未勾選任何設備，請補填或勾選「無使用調理設備」",IF($U6=1,"僅依賴1台設備，須確認故障/排修時之備援製程","無異常"))))) -> 僅依賴1台設備，須確認故障/排修時之備援製程 | X6: 大溪廠_2026.04.15_柚檸海灣貝飯糰_2026.07校正 | Z6: =IF($D6="",0,IF(COUNTIF($D$5:$D6,$D6)=1,1,0)) -> 0 | AA6: =IF(Z6=1,SUM($Z$5:$Z6),"")
A7: 下架 | B7: 大溪 | C7: 飯糰 | D7: 柚檸海灣貝飯糰 | E7: 調味扇貝柱-F | F7: 3 | G7: 個 | H7: 64.2 | T7: V | U7: =IF($E7="","",COUNTIF($I7:$S7,"V")) -> 0 | V7: =IF($E7="","",IF(AND($T7="V",$U7>0),"⚠ 勾選矛盾",IF($T7="V","○ 免調理",IF($U7=0,"⚠ 資料缺漏",IF($U7=1,"▲ 單一設備依賴","OK"))))) -> ○ 免調理 | W7: =IF($E7="","",IF(AND($T7="V",$U7>0),"「無使用調理設備」不可與設備欄同時勾選，請擇一修正",IF($T7="V","免調理半成品（外購/僅切配等），不列入設備風險評估",IF($U7=0,"未勾選任何設備，請補填或勾選「無使用調理設備」",IF($U7=1,"僅依賴1台設備，須確認故障/排修時之備援製程","無異常"))))) -> 免調理半成品（外購/僅切配等），不列入設備風險評估 | X7: 大溪廠_2026.04.15_柚檸海灣貝飯糰_2026.07校正 | Z7: =IF($D7="",0,IF(COUNTIF($D$5:$D7,$D7)=1,1,0)) -> 0 | AA7: =IF(Z7=1,SUM($Z$5:$Z7),"")
A8: 下架 | B8: 大溪 | C8: 飯糰 | D8: 柚檸海灣貝飯糰 | E8: 原味海苔(極選膠膜) | F8: 1 | G8: 個 | H8: 100 | T8: V | U8: =IF($E8="","",COUNTIF($I8:$S8,"V")) -> 0 | V8: =IF($E8="","",IF(AND($T8="V",$U8>0),"⚠ 勾選矛盾",IF($T8="V","○ 免調理",IF($U8=0,"⚠ 資料缺漏",IF($U8=1,"▲ 單一設備依賴","OK"))))) -> ○ 免調理 | W8: =IF($E8="","",IF(AND($T8="V",$U8>0),"「無使用調理設備」不可與設備欄同時勾選，請擇一修正",IF($T8="V","免調理半成品（外購/僅切配等），不列入設備風險評估",IF($U8=0,"未勾選任何設備，請補填或勾選「無使用調理設備」",IF($U8=1,"僅依賴1台設備，須確認故障/排修時之備援製程","無異常"))))) -> 免調理半成品（外購/僅切配等），不列入設備風險評估 | X8: 大溪廠_2026.04.15_柚檸海灣貝飯糰_2026.07校正 | Z8: =IF($D8="",0,IF(COUNTIF($D$5:$D8,$D8)=1,1,0)) -> 0 | AA8: =IF(Z8=1,SUM($Z$5:$Z8),"")
A9: 架上 | B9: 大溪 | C9: 飯糰 | D9: 筋子銀鮭飯糰 | E9: 煮一見鍾情飯 | F9: 95 | G9: 公克 | H9: 92 | I9: V | O9: V | U9: =IF($E9="","",COUNTIF($I9:$S9,"V")) -> 2 | V9: =IF($E9="","",IF(AND($T9="V",$U9>0),"⚠ 勾選矛盾",IF($T9="V","○ 免調理",IF($U9=0,"⚠ 資料缺漏",IF($U9=1,"▲ 單一設備依賴","OK"))))) -> OK | W9: =IF($E9="","",IF(AND($T9="V",$U9>0),"「無使用調理設備」不可與設備欄同時勾選，請擇一修正",IF($T9="V","免調理半成品（外購/僅切配等），不列入設備風險評估",IF($U9=0,"未勾選任何設備，請補填或勾選「無使用調理設備」",IF($U9=1,"僅依賴1台設備，須確認故障/排修時之備援製程","無異常"))))) -> 無異常 | X9: 1150715筋子銀鮭飯糰.確認版(1) | Z9: =IF($D9="",0,IF(COUNTIF($D$5:$D9,$D9)=1,1,0)) -> 1 | AA9: =IF(Z9=1,SUM($Z$5:$Z9),"") -> 2
A10: 架上 | B10: 大溪 | C10: 飯糰 | D10: 筋子銀鮭飯糰 | E10: 新冷凍銀鮭碎肉 | F10: 4 | G10: 公克 | H10: 100 | T10: V | U10: =IF($E10="","",COUNTIF($I10:$S10,"V")) -> 0 | V10: =IF($E10="","",IF(AND($T10="V",$U10>0),"⚠ 勾選矛盾",IF($T10="V","○ 免調理",IF($U10=0,"⚠ 資料缺漏",IF($U10=1,"▲ 單一設備依賴","OK"))))) -> ○ 免調理 | W10: =IF($E10="","",IF(AND($T10="V",$U10>0),"「無使用調理設備」不可與設備欄同時勾選，請擇一修正",IF($T10="V","免調理半成品（外購/僅切配等），不列入設備風險評估",IF($U10=0,"未勾選任何設備，請補填或勾選「無使用調理設備」",IF($U10=1,"僅依賴1台設備，須確認故障/排修時之備援製程","無異常"))))) -> 免調理半成品（外購/僅切配等），不列入設備風險評估 | X10: 1150715筋子銀鮭飯糰.確認版(1) | Z10: =IF($D10="",0,IF(COUNTIF($D$5:$D10,$D10)=1,1,0)) -> 0 | AA10: =IF(Z10=1,SUM($Z$5:$Z10),"")
A11: 架上 | B11: 大溪 | C11: 飯糰 | D11: 筋子銀鮭飯糰 | E11: 切筋子1cm | F11: 4 | G11: 公克 | H11: 85 | T11: V | U11: =IF($E11="","",COUNTIF($I11:$S11,"V")) -> 0 | V11: =IF($E11="","",IF(AND($T11="V",$U11>0),"⚠ 勾選矛盾",IF($T11="V","○ 免調理",IF($U11=0,"⚠ 資料缺漏",IF($U11=1,"▲ 單一設備依賴","OK"))))) -> ○ 免調理 | W11: =IF($E11="","",IF(AND($T11="V",$U11>0),"「無使用調理設備」不可與設備欄同時勾選，請擇一修正",IF($T11="V","免調理半成品（外購/僅切配等），不列入設備風險評估",IF($U11=0,"未勾選任何設備，請補填或勾選「無使用調理設備」",IF($U11=1,"僅依賴1台設備，須確認故障/排修時之備援製程","無異常"))))) -> 免調理半成品（外購/僅切配等），不列入設備風險評估 | X11: 1150715筋子銀鮭飯糰.確認版(1) | Z11: =IF($D11="",0,IF(COUNTIF($D$5:$D11,$D11)=1,1,0)) -> 0 | AA11: =IF(Z11=1,SUM($Z$5:$Z11),"")
A12: 架上 | B12: 大溪 | C12: 飯糰 | D12: 筋子銀鮭飯糰 | E12: 日式三角芥末海苔 | F12: 1 | G12: 個 | H12: 100 | T12: V | U12: =IF($E12="","",COUNTIF($I12:$S12,"V")) -> 0 | V12: =IF($E12="","",IF(AND($T12="V",$U12>0),"⚠ 勾選矛盾",IF($T12="V","○ 免調理",IF($U12=0,"⚠ 資料缺漏",IF($U12=1,"▲ 單一設備依賴","OK"))))) -> ○ 免調理 | W12: =IF($E12="","",IF(AND($T12="V",$U12>0),"「無使用調理設備」不可與設備欄同時勾選，請擇一修正",IF($T12="V","免調理半成品（外購/僅切配等），不列入設備風險評估",IF($U12=0,"未勾選任何設備，請補填或勾選「無使用調理設備」",IF($U12=1,"僅依賴1台設備，須確認故障/排修時之備援製程","無異常"))))) -> 免調理半成品（外購/僅切配等），不列入設備風險評估 | X12: 1150715筋子銀鮭飯糰.確認版(1) | Z12: =IF($D12="",0,IF(COUNTIF($D$5:$D12,$D12)=1,1,0)) -> 0 | AA12: =IF(Z12=1,SUM($Z$5:$Z12),"")
A13: 架上 | B13: 大溪 | C13: 飯糰 | D13: 鮭魚奶油醬油飯糰 | E13: 日式醬油飯 | F13: 95 | G13: 公克 | H13: 91.1 | I13: V | O13: V | U13: =IF($E13="","",COUNTIF($I13:$S13,"V")) -> 2 | V13: =IF($E13="","",IF(AND($T13="V",$U13>0),"⚠ 勾選矛盾",IF($T13="V","○ 免調理",IF($U13=0,"⚠ 資料缺漏",IF($U13=1,"▲ 單一設備依賴","OK"))))) -> OK | W13: =IF($E13="","",IF(AND($T13="V",$U13>0),"「無使用調理設備」不可與設備欄同時勾選，請擇一修正",IF($T13="V","免調理半成品（外購/僅切配等），不列入設備風險評估",IF($U13=0,"未勾選任何設備，請補填或勾選「無使用調理設備」",IF($U13=1,"僅依賴1台設備，須確認故障/排修時之備援製程","無異常"))))) -> 無異常 | X13: 大溪_2025.12.31_鮭魚奶油醬油飯糰_2026.07校正 | Z13: =IF($D13="",0,IF(COUNTIF($D$5:$D13,$D13)=1,1,0)) -> 1 | AA13: =IF(Z13=1,SUM($Z$5:$Z13),"") -> 3
A14: 架上 | B14: 大溪 | C14: 飯糰 | D14: 鮭魚奶油醬油飯糰 | E14: 拌鮭魚奶油醬 | F14: 10 | G14: 公克 | H14: 95 | O14: V | U14: =IF($E14="","",COUNTIF($I14:$S14,"V")) -> 1 | V14: =IF($E14="","",IF(AND($T14="V",$U14>0),"⚠ 勾選矛盾",IF($T14="V","○ 免調理",IF($U14=0,"⚠ 資料缺漏",IF($U14=1,"▲ 單一設備依賴","OK"))))) -> ▲ 單一設備依賴 | W14: =IF($E14="","",IF(AND($T14="V",$U14>0),"「無使用調理設備」不可與設備欄同時勾選，請擇一修正",IF($T14="V","免調理半成品（外購/僅切配等），不列入設備風險評估",IF($U14=0,"未勾選任何設備，請補填或勾選「無使用調理設備」",IF($U14=1,"僅依賴1台設備，須確認故障/排修時之備援製程","無異常"))))) -> 僅依賴1台設備，須確認故障/排修時之備援製程 | X14: 大溪_2025.12.31_鮭魚奶油醬油飯糰_2026.07校正 | Z14: =IF($D14="",0,IF(COUNTIF($D$5:$D14,$D14)=1,1,0)) -> 0 | AA14: =IF(Z14=1,SUM($Z$5:$Z14),"")
A15: 架上 | B15: 大溪 | C15: 飯糰 | D15: 鮭魚奶油醬油飯糰 | E15: 原味海苔(透明膠膜) | F15: 1 | G15: 個 | H15: 100 | T15: V | U15: =IF($E15="","",COUNTIF($I15:$S15,"V")) -> 0 | V15: =IF($E15="","",IF(AND($T15="V",$U15>0),"⚠ 勾選矛盾",IF($T15="V","○ 免調理",IF($U15=0,"⚠ 資料缺漏",IF($U15=1,"▲ 單一設備依賴","OK"))))) -> ○ 免調理 | W15: =IF($E15="","",IF(AND($T15="V",$U15>0),"「無使用調理設備」不可與設備欄同時勾選，請擇一修正",IF($T15="V","免調理半成品（外購/僅切配等），不列入設備風險評估",IF($U15=0,"未勾選任何設備，請補填或勾選「無使用調理設備」",IF($U15=1,"僅依賴1台設備，須確認故障/排修時之備援製程","無異常"))))) -> 免調理半成品（外購/僅切配等），不列入設備風險評估 | X15: 大溪_2025.12.31_鮭魚奶油醬油飯糰_2026.07校正 | Z15: =IF($D15="",0,IF(COUNTIF($D$5:$D15,$D15)=1,1,0)) -> 0 | AA15: =IF(Z15=1,SUM($Z$5:$Z15),"")
A16: 架上 | B16: 大溪 | C16: 飯糰 | D16: 黑胡椒洋蔥豬飯糰 | E16: 煮16+11湖鹽飯(109年) | F16: 95 | G16: 公克 | H16: 92.8 | I16: V | O16: V | U16: =IF($E16="","",COUNTIF($I16:$S16,"V")) -> 2 | V16: =IF($E16="","",IF(AND($T16="V",$U16>0),"⚠ 勾選矛盾",IF($T16="V","○ 免調理",IF($U16=0,"⚠ 資料缺漏",IF($U16=1,"▲ 單一設備依賴","OK"))))) -> OK | W16: =IF($E16="","",IF(AND($T16="V",$U16>0),"「無使用調理設備」不可與設備欄同時勾選，請擇一修正",IF($T16="V","免調理半成品（外購/僅切配等），不列入設備風險評估",IF($U16=0,"未勾選任何設備，請補填或勾選「無使用調理設備」",IF($U16=1,"僅依賴1台設備，須確認故障/排修時之備援製程","無異常"))))) -> 無異常 | X16: 大溪廠_2026.05.13_黑胡椒洋蔥豬飯糰_2026.07校正 | Z16: =IF($D16="",0,IF(COUNTIF($D$5:$D16,$D16)=1,1,0)) -> 1 | AA16: =IF(Z16=1,SUM($Z$5:$Z16),"") -> 4
A17: 架上 | B17: 大溪 | C17: 飯糰 | D17: 黑胡椒洋蔥豬飯糰 | E17: 煮洋蔥豬肉 | F17: 19 | G17: 公克 | H17: 55 | O17: V | U17: =IF($E17="","",COUNTIF($I17:$S17,"V")) -> 1 | V17: =IF($E17="","",IF(AND($T17="V",$U17>0),"⚠ 勾選矛盾",IF($T17="V","○ 免調理",IF($U17=0,"⚠ 資料缺漏",IF($U17=1,"▲ 單一設備依賴","OK"))))) -> ▲ 單一設備依賴 | W17: =IF($E17="","",IF(AND($T17="V",$U17>0),"「無使用調理設備」不可與設備欄同時勾選，請擇一修正",IF($T17="V","免調理半成品（外購/僅切配等），不列入設備風險評估",IF($U17=0,"未勾選任何設備，請補填或勾選「無使用調理設備」",IF($U17=1,"僅依賴1台設備，須確認故障/排修時之備援製程","無異常"))))) -> 僅依賴1台設備，須確認故障/排修時之備援製程 | X17: 大溪廠_2026.05.13_黑胡椒洋蔥豬飯糰_2026.07校正 | Z17: =IF($D17="",0,IF(COUNTIF($D$5:$D17,$D17)=1,1,0)) -> 0 | AA17: =IF(Z17=1,SUM($Z$5:$Z17),"")
A18: 架上 | B18: 大溪 | C18: 飯糰 | D18: 黑胡椒洋蔥豬飯糰 | E18: 原味海苔(透明膠膜) | F18: 1 | G18: 個 | H18: 100 | T18: V | U18: =IF($E18="","",COUNTIF($I18:$S18,"V")) -> 0 | V18: =IF($E18="","",IF(AND($T18="V",$U18>0),"⚠ 勾選矛盾",IF($T18="V","○ 免調理",IF($U18=0,"⚠ 資料缺漏",IF($U18=1,"▲ 單一設備依賴","OK"))))) -> ○ 免調理 | W18: =IF($E18="","",IF(AND($T18="V",$U18>0),"「無使用調理設備」不可與設備欄同時勾選，請擇一修正",IF($T18="V","免調理半成品（外購/僅切配等），不列入設備風險評估",IF($U18=0,"未勾選任何設備，請補填或勾選「無使用調理設備」",IF($U18=1,"僅依賴1台設備，須確認故障/排修時之備援製程","無異常"))))) -> 免調理半成品（外購/僅切配等），不列入設備風險評估 | X18: 大溪廠_2026.05.13_黑胡椒洋蔥豬飯糰_2026.07校正 | Z18: =IF($D18="",0,IF(COUNTIF($D$5:$D18,$D18)=1,1,0)) -> 0 | AA18: =IF(Z18=1,SUM($Z$5:$Z18),"")
A19: 架上 | B19: 大溪 | C19: 飯糰 | D19: 三杯醬爆菇菇飯糰 | E19: 煮16+11湖鹽飯(109年) | F19: 95 | G19: 公克 | H19: 92.8 | I19: V | O19: V | U19: =IF($E19="","",COUNTIF($I19:$S19,"V")) -> 2 | V19: =IF($E19="","",IF(AND($T19="V",$U19>0),"⚠ 勾選矛盾",IF($T19="V","○ 免調理",IF($U19=0,"⚠ 資料缺漏",IF($U19=1,"▲ 單一設備依賴","OK"))))) -> OK | W19: =IF($E19="","",IF(AND($T19="V",$U19>0),"「無使用調理設備」不可與設備欄同時勾選，請擇一修正",IF($T19="V","免調理半成品（外購/僅切配等），不列入設備風險評估",IF($U19=0,"未勾選任何設備，請補填或勾選「無使用調理設備」",IF($U19=1,"僅依賴1台設備，須確認故障/排修時之備援製程","無異常"))))) -> 無異常 | X19: 代工品 | Z19: =IF($D19="",0,IF(COUNTIF($D$5:$D19,$D19)=1,1,0)) -> 1 | AA19: =IF(Z19=1,SUM($Z$5:$Z19),"") -> 5
A20: 架上 | B20: 大溪 | C20: 飯糰 | D20: 三杯醬爆菇菇飯糰 | E20: 煮三杯料 | F20: 15 | G20: 公克 | O20: V | U20: =IF($E20="","",COUNTIF($I20:$S20,"V")) -> 1 | V20: =IF($E20="","",IF(AND($T20="V",$U20>0),"⚠ 勾選矛盾",IF($T20="V","○ 免調理",IF($U20=0,"⚠ 資料缺漏",IF($U20=1,"▲ 單一設備依賴","OK"))))) -> ▲ 單一設備依賴 | W20: =IF($E20="","",IF(AND($T20="V",$U20>0),"「無使用調理設備」不可與設備欄同時勾選，請擇一修正",IF($T20="V","免調理半成品（外購/僅切配等），不列入設備風險評估",IF($U20=0,"未勾選任何設備，請補填或勾選「無使用調理設備」",IF($U20=1,"僅依賴1台設備，須確認故障/排修時之備援製程","無異常"))))) -> 僅依賴1台設備，須確認故障/排修時之備援製程 | X20: 代工品 | Z20: =IF($D20="",0,IF(COUNTIF($D$5:$D20,$D20)=1,1,0)) -> 0 | AA20: =IF(Z20=1,SUM($Z$5:$Z20),"")
A21: 架上 | B21: 大溪 | C21: 飯糰 | D21: 三杯醬爆菇菇飯糰 | E21: 全家三角原味海苔(蔬食版) | F21: 1 | G21: 個 | H21: 100 | T21: V | U21: =IF($E21="","",COUNTIF($I21:$S21,"V")) -> 0 | V21: =IF($E21="","",IF(AND($T21="V",$U21>0),"⚠ 勾選矛盾",IF($T21="V","○ 免調理",IF($U21=0,"⚠ 資料缺漏",IF($U21=1,"▲ 單一設備依賴","OK"))))) -> ○ 免調理 | W21: =IF($E21="","",IF(AND($T21="V",$U21>0),"「無使用調理設備」不可與設備欄同時勾選，請擇一修正",IF($T21="V","免調理半成品（外購/僅切配等），不列入設備風險評估",IF($U21=0,"未勾選任何設備，請補填或勾選「無使用調理設備」",IF($U21=1,"僅依賴1台設備，須確認故障/排修時之備援製程","無異常"))))) -> 免調理半成品（外購/僅切配等），不列入設備風險評估 | X21: 代工品 | Z21: =IF($D21="",0,IF(COUNTIF($D$5:$D21,$D21)=1,1,0)) -> 0 | AA21: =IF(Z21=1,SUM($Z$5:$Z21),"")
A22: 下架 | B22: 大溪 | C22: 飯糰 | D22: 大飯糰乾燒風味鮮蝦 | E22: 煮16+11湖鹽飯(109年) | F22: 110 | G22: 公克 | H22: 92.8 | I22: V | O22: V | U22: =IF($E22="","",COUNTIF($I22:$S22,"V")) -> 2 | V22: =IF($E22="","",IF(AND($T22="V",$U22>0),"⚠ 勾選矛盾",IF($T22="V","○ 免調理",IF($U22=0,"⚠ 資料缺漏",IF($U22=1,"▲ 單一設備依賴","OK"))))) -> OK | W22: =IF($E22="","",IF(AND($T22="V",$U22>0),"「無使用調理設備」不可與設備欄同時勾選，請擇一修正",IF($T22="V","免調理半成品（外購/僅切配等），不列入設備風險評估",IF($U22=0,"未勾選任何設備，請補填或勾選「無使用調理設備」",IF($U22=1,"僅依賴1台設備，須確認故障/排修時之備援製程","無異常"))))) -> 無異常 | X22: 大溪_2026.04.07_大飯糰乾燒風味鮮蝦_2026.06校正 | Z22: =IF($D22="",0,IF(COUNTIF($D$5:$D22,$D22)=1,1,0)) -> 1 | AA22: =IF(Z22=1,SUM($Z$5:$Z22),"") -> 6
A23: 下架 | B23: 大溪 | C23: 飯糰 | D23: 大飯糰乾燒風味鮮蝦 | E23: 煮乾燒醬 | F23: 8 | G23: 公克 | H23: 56.5 | O23: V | U23: =IF($E23="","",COUNTIF($I23:$S23,"V")) -> 1 | V23: =IF($E23="","",IF(AND($T23="V",$U23>0),"⚠ 勾選矛盾",IF($T23="V","○ 免調理",IF($U23=0,"⚠ 資料缺漏",IF($U23=1,"▲ 單一設備依賴","OK"))))) -> ▲ 單一設備依賴 | W23: =IF($E23="","",IF(AND($T23="V",$U23>0),"「無使用調理設備」不可與設備欄同時勾選，請擇一修正",IF($T23="V","免調理半成品（外購/僅切配等），不列入設備風險評估",IF($U23=0,"未勾選任何設備，請補填或勾選「無使用調理設備」",IF($U23=1,"僅依賴1台設備，須確認故障/排修時之備援製程","無異常"))))) -> 僅依賴1台設備，須確認故障/排修時之備援製程 | X23: 大溪_2026.04.07_大飯糰乾燒風味鮮蝦_2026.06校正 | Z23: =IF($D23="",0,IF(COUNTIF($D$5:$D23,$D23)=1,1,0)) -> 0 | AA23: =IF(Z23=1,SUM($Z$5:$Z23),"")
A24: 下架 | B24: 大溪 | C24: 飯糰 | D24: 大飯糰乾燒風味鮮蝦 | E24: 炒蝦仁(9號)(大飯糰) | F24: 3 | G24: 個 | H24: 41 | O24: V | U24: =IF($E24="","",COUNTIF($I24:$S24,"V")) -> 1 | V24: =IF($E24="","",IF(AND($T24="V",$U24>0),"⚠ 勾選矛盾",IF($T24="V","○ 免調理",IF($U24=0,"⚠ 資料缺漏",IF($U24=1,"▲ 單一設備依賴","OK"))))) -> ▲ 單一設備依賴 | W24: =IF($E24="","",IF(AND($T24="V",$U24>0),"「無使用調理設備」不可與設備欄同時勾選，請擇一修正",IF($T24="V","免調理半成品（外購/僅切配等），不列入設備風險評估",IF($U24=0,"未勾選任何設備，請補填或勾選「無使用調理設備」",IF($U24=1,"僅依賴1台設備，須確認故障/排修時之備援製程","無異常"))))) -> 僅依賴1台設備，須確認故障/排修時之備援製程 | X24: 大溪_2026.04.07_大飯糰乾燒風味鮮蝦_2026.06校正 | Z24: =IF($D24="",0,IF(COUNTIF($D$5:$D24,$D24)=1,1,0)) -> 0 | AA24: =IF(Z24=1,SUM($Z$5:$Z24),"")
A25: 下架 | B25: 大溪 | C25: 飯糰 | D25: 大飯糰乾燒風味鮮蝦 | E25: 全家大三角海苔(新版) | F25: 1 | G25: 個 | H25: 100 | T25: V | U25: =IF($E25="","",COUNTIF($I25:$S25,"V")) -> 0 | V25: =IF($E25="","",IF(AND($T25="V",$U25>0),"⚠ 勾選矛盾",IF($T25="V","○ 免調理",IF($U25=0,"⚠ 資料缺漏",IF($U25=1,"▲ 單一設備依賴","OK"))))) -> ○ 免調理 | W25: =IF($E25="","",IF(AND($T25="V",$U25>0),"「無使用調理設備」不可與設備欄同時勾選，請擇一修正",IF($T25="V","免調理半成品（外購/僅切配等），不列入設備風險評估",IF($U25=0,"未勾選任何設備，請補填或勾選「無使用調理設備」",IF($U25=1,"僅依賴1台設備，須確認故障/排修時之備援製程","無異常"))))) -> 免調理半成品（外購/僅切配等），不列入設備風險評估 | X25: 大溪_2026.04.07_大飯糰乾燒風味鮮蝦_2026.06校正 | Z25: =IF($D25="",0,IF(COUNTIF($D$5:$D25,$D25)=1,1,0)) -> 0 | AA25: =IF(Z25=1,SUM($Z$5:$Z25),"")
A26: 下架 | B26: 大溪 | C26: 飯糰 | D26: 大飯糰泡菜鮪魚 | E26: 韓式辣醬飯 | F26: 120 | G26: 公克 | H26: 90.8 | I26: V | O26: V | U26: =IF($E26="","",COUNTIF($I26:$S26,"V")) -> 2 | V26: =IF($E26="","",IF(AND($T26="V",$U26>0),"⚠ 勾選矛盾",IF($T26="V","○ 免調理",IF($U26=0,"⚠ 資料缺漏",IF($U26=1,"▲ 單一設備依賴","OK"))))) -> OK | W26: =IF($E26="","",IF(AND($T26="V",$U26>0),"「無使用調理設備」不可與設備欄同時勾選，請擇一修正",IF($T26="V","免調理半成品（外購/僅切配等），不列入設備風險評估",IF($U26=0,"未勾選任何設備，請補填或勾選「無使用調理設備」",IF($U26=1,"僅依賴1台設備，須確認故障/排修時之備援製程","無異常"))))) -> 無異常 | X26: 大溪廠_2026.06.30_大飯糰泡菜鮪魚_2026.07校正 | Z26: =IF($D26="",0,IF(COUNTIF($D$5:$D26,$D26)=1,1,0)) -> 1 | AA26: =IF(Z26=1,SUM($Z$5:$Z26),"") -> 7
A27: 下架 | B27: 大溪 | C27: 飯糰 | D27: 大飯糰泡菜鮪魚 | E27: 炒韓式泡菜 | F27: 12 | G27: 公克 | H27: 59.9 | O27: V | U27: =IF($E27="","",COUNTIF($I27:$S27,"V")) -> 1 | V27: =IF($E27="","",IF(AND($T27="V",$U27>0),"⚠ 勾選矛盾",IF($T27="V","○ 免調理",IF($U27=0,"⚠ 資料缺漏",IF($U27=1,"▲ 單一設備依賴","OK"))))) -> ▲ 單一設備依賴 | W27: =IF($E27="","",IF(AND($T27="V",$U27>0),"「無使用調理設備」不可與設備欄同時勾選，請擇一修正",IF($T27="V","免調理半成品（外購/僅切配等），不列入設備風險評估",IF($U27=0,"未勾選任何設備，請補填或勾選「無使用調理設備」",IF($U27=1,"僅依賴1台設備，須確認故障/排修時之備援製程","無異常"))))) -> 僅依賴1台設備，須確認故障/排修時之備援製程 | X27: 大溪廠_2026.06.30_大飯糰泡菜鮪魚_2026.07校正 | Z27: =IF($D27="",0,IF(COUNTIF($D$5:$D27,$D27)=1,1,0)) -> 0 | AA27: =IF(Z27=1,SUM($Z$5:$Z27),"")
A28: 下架 | B28: 大溪 | C28: 飯糰 | D28: 大飯糰泡菜鮪魚 | E28: 拌韓式辣鮪魚 | F28: 20 | G28: 公克 | H28: 95 | O28: V | U28: =IF($E28="","",COUNTIF($I28:$S28,"V")) -> 1 | V28: =IF($E28="","",IF(AND($T28="V",$U28>0),"⚠ 勾選矛盾",IF($T28="V","○ 免調理",IF($U28=0,"⚠ 資料缺漏",IF($U28=1,"▲ 單一設備依賴","OK"))))) -> ▲ 單一設備依賴 | W28: =IF($E28="","",IF(AND($T28="V",$U28>0),"「無使用調理設備」不可與設備欄同時勾選，請擇一修正",IF($T28="V","免調理半成品（外購/僅切配等），不列入設備風險評估",IF($U28=0,"未勾選任何設備，請補填或勾選「無使用調理設備」",IF($U28=1,"僅依賴1台設備，須確認故障/排修時之備援製程","無異常"))))) -> 僅依賴1台設備，須確認故障/排修時之備援製程 | X28: 大溪廠_2026.06.30_大飯糰泡菜鮪魚_2026.07校正 | Z28: =IF($D28="",0,IF(COUNTIF($D$5:$D28,$D28)=1,1,0)) -> 0 | AA28: =IF(Z28=1,SUM($Z$5:$Z28),"")
A29: 下架 | B29: 大溪 | C29: 飯糰 | D29: 大飯糰泡菜鮪魚 | E29: 原味大海苔-(112膠膜) | F29: 1 | G29: 個 | H29: 100 | T29: V | U29: =IF($E29="","",COUNTIF($I29:$S29,"V")) -> 0 | V29: =IF($E29="","",IF(AND($T29="V",$U29>0),"⚠ 勾選矛盾",IF($T29="V","○ 免調理",IF($U29=0,"⚠ 資料缺漏",IF($U29=1,"▲ 單一設備依賴","OK"))))) -> ○ 免調理 | W29: =IF($E29="","",IF(AND($T29="V",$U29>0),"「無使用調理設備」不可與設備欄同時勾選，請擇一修正",IF($T29="V","免調理半成品（外購/僅切配等），不列入設備風險評估",IF($U29=0,"未勾選任何設備，請補填或勾選「無使用調理設備」",IF($U29=1,"僅依賴1台設備，須確認故障/排修時之備援製程","無異常"))))) -> 免調理半成品（外購/僅切配等），不列入設備風險評估 | X29: 大溪廠_2026.06.30_大飯糰泡菜鮪魚_2026.07校正 | Z29: =IF($D29="",0,IF(COUNTIF($D$5:$D29,$D29)=1,1,0)) -> 0 | AA29: =IF(Z29=1,SUM($Z$5:$Z29),"")
A30: 架上 | B30: 大溪 | C30: 飯糰 | D30: 大飯糰韓式蒜烤豬五花 | E30: 煮16+11湖鹽飯(109年) | F30: 120 | G30: 公克 | H30: 92.8 | I30: V | O30: V | U30: =IF($E30="","",COUNTIF($I30:$S30,"V")) -> 2 | V30: =IF($E30="","",IF(AND($T30="V",$U30>0),"⚠ 勾選矛盾",IF($T30="V","○ 免調理",IF($U30=0,"⚠ 資料缺漏",IF($U30=1,"▲ 單一設備依賴","OK"))))) -> OK | W30: =IF($E30="","",IF(AND($T30="V",$U30>0),"「無使用調理設備」不可與設備欄同時勾選，請擇一修正",IF($T30="V","免調理半成品（外購/僅切配等），不列入設備風險評估",IF($U30=0,"未勾選任何設備，請補填或勾選「無使用調理設備」",IF($U30=1,"僅依賴1台設備，須確認故障/排修時之備援製程","無異常"))))) -> 無異常 | X30: 大溪_2025.11.25_大飯糰韓式蒜烤豬五花_2026.07校正 | Z30: =IF($D30="",0,IF(COUNTIF($D$5:$D30,$D30)=1,1,0)) -> 1 | AA30: =IF(Z30=1,SUM($Z$5:$Z30),"") -> 8
A31: 架上 | B31: 大溪 | C31: 飯糰 | D31: 大飯糰韓式蒜烤豬五花 | E31: 拌蒜香五花肉 | F31: 17 | G31: 公克 | H31: 95 | K31: V | L31: V | O31: V | U31: =IF($E31="","",COUNTIF($I31:$S31,"V")) -> 3 | V31: =IF($E31="","",IF(AND($T31="V",$U31>0),"⚠ 勾選矛盾",IF($T31="V","○ 免調理",IF($U31=0,"⚠ 資料缺漏",IF($U31=1,"▲ 單一設備依賴","OK"))))) -> OK | W31: =IF($E31="","",IF(AND($T31="V",$U31>0),"「無使用調理設備」不可與設備欄同時勾選，請擇一修正",IF($T31="V","免調理半成品（外購/僅切配等），不列入設備風險評估",IF($U31=0,"未勾選任何設備，請補填或勾選「無使用調理設備」",IF($U31=1,"僅依賴1台設備，須確認故障/排修時之備援製程","無異常"))))) -> 無異常 | X31: 大溪_2025.11.25_大飯糰韓式蒜烤豬五花_2026.07校正 | Z31: =IF($D31="",0,IF(COUNTIF($D$5:$D31,$D31)=1,1,0)) -> 0 | AA31: =IF(Z31=1,SUM($Z$5:$Z31),"")
A32: 架上 | B32: 大溪 | C32: 飯糰 | D32: 大飯糰韓式蒜烤豬五花 | E32: 原味大海苔-(112膠膜) | F32: 1 | G32: 個 | H32: 100 | T32: V | U32: =IF($E32="","",COUNTIF($I32:$S32,"V")) -> 0 | V32: =IF($E32="","",IF(AND($T32="V",$U32>0),"⚠ 勾選矛盾",IF($T32="V","○ 免調理",IF($U32=0,"⚠ 資料缺漏",IF($U32=1,"▲ 單一設備依賴","OK"))))) -> ○ 免調理 | W32: =IF($E32="","",IF(AND($T32="V",$U32>0),"「無使用調理設備」不可與設備欄同時勾選，請擇一修正",IF($T32="V","免調理半成品（外購/僅切配等），不列入設備風險評估",IF($U32=0,"未勾選任何設備，請補填或勾選「無使用調理設備」",IF($U32=1,"僅依賴1台設備，須確認故障/排修時之備援製程","無異常"))))) -> 免調理半成品（外購/僅切配等），不列入設備風險評估 | X32: 大溪_2025.11.25_大飯糰韓式蒜烤豬五花_2026.07校正 | Z32: =IF($D32="",0,IF(COUNTIF($D$5:$D32,$D32)=1,1,0)) -> 0 | AA32: =IF(Z32=1,SUM($Z$5:$Z32),"")
A33: 架上 | B33: 大溪 | C33: 飯糰 | D33: 芝麻香鬆飯糰 | E33: 16+11湖鹽飯(肉鬆) | F33: 95 | G33: 公克 | H33: 92.9 | I33: V | O33: V | U33: =IF($E33="","",COUNTIF($I33:$S33,"V")) -> 2 | V33: =IF($E33="","",IF(AND($T33="V",$U33>0),"⚠ 勾選矛盾",IF($T33="V","○ 免調理",IF($U33=0,"⚠ 資料缺漏",IF($U33=1,"▲ 單一設備依賴","OK"))))) -> OK | W33: =IF($E33="","",IF(AND($T33="V",$U33>0),"「無使用調理設備」不可與設備欄同時勾選，請擇一修正",IF($T33="V","免調理半成品（外購/僅切配等），不列入設備風險評估",IF($U33=0,"未勾選任何設備，請補填或勾選「無使用調理設備」",IF($U33=1,"僅依賴1台設備，須確認故障/排修時之備援製程","無異常"))))) -> 無異常 | X33: 大溪_2025.04.30_芝麻香鬆飯糰_2026.07校正 | Z33: =IF($D33="",0,IF(COUNTIF($D$5:$D33,$D33)=1,1,0)) -> 1 | AA33: =IF(Z33=1,SUM($Z$5:$Z33),"") -> 9
A34: 架上 | B34: 大溪 | C34: 飯糰 | D34: 芝麻香鬆飯糰 | E34: (V)炒海苔香鬆 | F34: 14 | G34: 公克 | H34: 62 | O34: V | U34: =IF($E34="","",COUNTIF($I34:$S34,"V")) -> 1 | V34: =IF($E34="","",IF(AND($T34="V",$U34>0),"⚠ 勾選矛盾",IF($T34="V","○ 免調理",IF($U34=0,"⚠ 資料缺漏",IF($U34=1,"▲ 單一設備依賴","OK"))))) -> ▲ 單一設備依賴 | W34: =IF($E34="","",IF(AND($T34="V",$U34>0),"「無使用調理設備」不可與設備欄同時勾選，請擇一修正",IF($T34="V","免調理半成品（外購/僅切配等），不列入設備風險評估",IF($U34=0,"未勾選任何設備，請補填或勾選「無使用調理設備」",IF($U34=1,"僅依賴1台設備，須確認故障/排修時之備援製程","無異常"))))) -> 僅依賴1台設備，須確認故障/排修時之備援製程 | X34: 大溪_2025.04.30_芝麻香鬆飯糰_2026.07校正 | Z34: =IF($D34="",0,IF(COUNTIF($D$5:$D34,$D34)=1,1,0)) -> 0 | AA34: =IF(Z34=1,SUM($Z$5:$Z34),"")
A35: 架上 | B35: 大溪 | C35: 飯糰 | D35: 芝麻香鬆飯糰 | E35: 全家三角原味海苔(蔬食版) | F35: 1 | G35: 個 | H35: 100 | T35: V | U35: =IF($E35="","",COUNTIF($I35:$S35,"V")) -> 0 | V35: =IF($E35="","",IF(AND($T35="V",$U35>0),"⚠ 勾選矛盾",IF($T35="V","○ 免調理",IF($U35=0,"⚠ 資料缺漏",IF($U35=1,"▲ 單一設備依賴","OK"))))) -> ○ 免調理 | W35: =IF($E35="","",IF(AND($T35="V",$U35>0),"「無使用調理設備」不可與設備欄同時勾選，請擇一修正",IF($T35="V","免調理半成品（外購/僅切配等），不列入設備風險評估",IF($U35=0,"未勾選任何設備，請補填或勾選「無使用調理設備」",IF($U35=1,"僅依賴1台設備，須確認故障/排修時之備援製程","無異常"))))) -> 免調理半成品（外購/僅切配等），不列入設備風險評估 | X35: 大溪_2025.04.30_芝麻香鬆飯糰_2026.07校正 | Z35: =IF($D35="",0,IF(COUNTIF($D$5:$D35,$D35)=1,1,0)) -> 0 | AA35: =IF(Z35=1,SUM($Z$5:$Z35),"")
A36: 架上 | B36: 大溪 | C36: 飯糰 | D36: 北海道秋鮭親子飯糰 | E36: 煮一見鍾情飯 | F36: 95 | G36: 公克 | H36: 92.5 | I36: V | O36: V | U36: =IF($E36="","",COUNTIF($I36:$S36,"V")) -> 2 | V36: =IF($E36="","",IF(AND($T36="V",$U36>0),"⚠ 勾選矛盾",IF($T36="V","○ 免調理",IF($U36=0,"⚠ 資料缺漏",IF($U36=1,"▲ 單一設備依賴","OK"))))) -> OK | W36: =IF($E36="","",IF(AND($T36="V",$U36>0),"「無使用調理設備」不可與設備欄同時勾選，請擇一修正",IF($T36="V","免調理半成品（外購/僅切配等），不列入設備風險評估",IF($U36=0,"未勾選任何設備，請補填或勾選「無使用調理設備」",IF($U36=1,"僅依賴1台設備，須確認故障/排修時之備援製程","無異常"))))) -> 無異常 | X36: 大溪_2025.09.10_北海道秋鮭親子飯糰_2026.07校正 | Z36: =IF($D36="",0,IF(COUNTIF($D$5:$D36,$D36)=1,1,0)) -> 1 | AA36: =IF(Z36=1,SUM($Z$5:$Z36),"") -> 10
A37: 架上 | B37: 大溪 | C37: 飯糰 | D37: 北海道秋鮭親子飯糰 | E37: 拌鮭魚沙拉(114年) | F37: 13 | G37: 公克 | H37: 95 | O37: V | U37: =IF($E37="","",COUNTIF($I37:$S37,"V")) -> 1 | V37: =IF($E37="","",IF(AND($T37="V",$U37>0),"⚠ 勾選矛盾",IF($T37="V","○ 免調理",IF($U37=0,"⚠ 資料缺漏",IF($U37=1,"▲ 單一設備依賴","OK"))))) -> ▲ 單一設備依賴 | W37: =IF($E37="","",IF(AND($T37="V",$U37>0),"「無使用調理設備」不可與設備欄同時勾選，請擇一修正",IF($T37="V","免調理半成品（外購/僅切配等），不列入設備風險評估",IF($U37=0,"未勾選任何設備，請補填或勾選「無使用調理設備」",IF($U37=1,"僅依賴1台設備，須確認故障/排修時之備援製程","無異常"))))) -> 僅依賴1台設備，須確認故障/排修時之備援製程 | X37: 大溪_2025.09.10_北海道秋鮭親子飯糰_2026.07校正 | Z37: =IF($D37="",0,IF(COUNTIF($D$5:$D37,$D37)=1,1,0)) -> 0 | AA37: =IF(Z37=1,SUM($Z$5:$Z37),"")
A38: 架上 | B38: 大溪 | C38: 飯糰 | D38: 北海道秋鮭親子飯糰 | E38: 冷凍調味鱒鮭魚卵公克L10-3 | F38: 2 | G38: 公克 | H38: 97 | T38: V | U38: =IF($E38="","",COUNTIF($I38:$S38,"V")) -> 0 | V38: =IF($E38="","",IF(AND($T38="V",$U38>0),"⚠ 勾選矛盾",IF($T38="V","○ 免調理",IF($U38=0,"⚠ 資料缺漏",IF($U38=1,"▲ 單一設備依賴","OK"))))) -> ○ 免調理 | W38: =IF($E38="","",IF(AND($T38="V",$U38>0),"「無使用調理設備」不可與設備欄同時勾選，請擇一修正",IF($T38="V","免調理半成品（外購/僅切配等），不列入設備風險評估",IF($U38=0,"未勾選任何設備，請補填或勾選「無使用調理設備」",IF($U38=1,"僅依賴1台設備，須確認故障/排修時之備援製程","無異常"))))) -> 免調理半成品（外購/僅切配等），不列入設備風險評估 | X38: 大溪_2025.09.10_北海道秋鮭親子飯糰_2026.07校正 | Z38: =IF($D38="",0,IF(COUNTIF($D$5:$D38,$D38)=1,1,0)) -> 0 | AA38: =IF(Z38=1,SUM($Z$5:$Z38),"")
A39: 架上 | B39: 大溪 | C39: 飯糰 | D39: 北海道秋鮭親子飯糰 | E39: 原味海苔（極選系列） | F39: 1 | G39: 個 | H39: 100 | T39: V | U39: =IF($E39="","",COUNTIF($I39:$S39,"V")) -> 0 | V39: =IF($E39="","",IF(AND($T39="V",$U39>0),"⚠ 勾選矛盾",IF($T39="V","○ 免調理",IF($U39=0,"⚠ 資料缺漏",IF($U39=1,"▲ 單一設備依賴","OK"))))) -> ○ 免調理 | W39: =IF($E39="","",IF(AND($T39="V",$U39>0),"「無使用調理設備」不可與設備欄同時勾選，請擇一修正",IF($T39="V","免調理半成品（外購/僅切配等），不列入設備風險評估",IF($U39=0,"未勾選任何設備，請補填或勾選「無使用調理設備」",IF($U39=1,"僅依賴1台設備，須確認故障/排修時之備援製程","無異常"))))) -> 免調理半成品（外購/僅切配等），不列入設備風險評估 | X39: 大溪_2025.09.10_北海道秋鮭親子飯糰_2026.07校正 | Z39: =IF($D39="",0,IF(COUNTIF($D$5:$D39,$D39)=1,1,0)) -> 0 | AA39: =IF(Z39=1,SUM($Z$5:$Z39),"")
A40: 下架 | B40: 大溪 | C40: 飯糰 | D40: 壹號醬炙烤牛飯糰 | E40: 煮16+11湖鹽飯(109年) | F40: 95 | G40: 公克 | H40: 92.8 | I40: V | O40: V | U40: =IF($E40="","",COUNTIF($I40:$S40,"V")) -> 2 | V40: =IF($E40="","",IF(AND($T40="V",$U40>0),"⚠ 勾選矛盾",IF($T40="V","○ 免調理",IF($U40=0,"⚠ 資料缺漏",IF($U40=1,"▲ 單一設備依賴","OK"))))) -> OK | W40: =IF($E40="","",IF(AND($T40="V",$U40>0),"「無使用調理設備」不可與設備欄同時勾選，請擇一修正",IF($T40="V","免調理半成品（外購/僅切配等），不列入設備風險評估",IF($U40=0,"未勾選任何設備，請補填或勾選「無使用調理設備」",IF($U40=1,"僅依賴1台設備，須確認故障/排修時之備援製程","無異常"))))) -> 無異常 | X40: 大溪_2024.05.15_壹號醬炙烤牛飯糰_2026.06校正 | Z40: =IF($D40="",0,IF(COUNTIF($D$5:$D40,$D40)=1,1,0)) -> 1 | AA40: =IF(Z40=1,SUM($Z$5:$Z40),"") -> 11
...

Sheet 4℃飯
A1: 商品半成品與調理設備應用展開一覽表｜4℃飯
A2: 商品資訊 | I2: 熱調理區（使用者填「V」；免調理者勾最右欄） | U2: 自動計算與風險檢核（勿手動修改） | X2: 建檔資訊（手填）
A3: 狀態 | B3: 工廠 | C3: 商品分類 (細分品類) | D3: 商品名稱 | E3: 半成品名稱 | F3: 單位用量 | H3: 製程率 (填數字) | I3: 炊飯 | J3: 煮麵 | K3: 烤箱 | L3: 炙燒 | M3: 蒸箱 | N3: 油炸機 | O3: 二重釜 | P3: 平釜 (日) | Q3: 平釜 (台) | R3: 蛋皮機 | S3: 壓力鍋 | T3: 無使用 調理設備 | U3: 使用 設備數 | V3: 檢核結果 | W3: 風險說明 | X3: 備註 (指示書編號/版本) | Y3: 建檔人員 | Z3: 系統用Y | AA3: 系統用Z
F4: 數值 | G4: 單位
A5: 下架 | B5: 大溪 | C5: 主食 | D5: 日式鮭魚茶泡烤飯 | E5: 細切海苔(2mm*5cm) | F5: 0.3 | G5: 公克 | H5: 97 | T5: V | U5: =IF($E5="","",COUNTIF($I5:$S5,"V")) -> 0 | V5: =IF($E5="","",IF(AND($T5="V",$U5>0),"⚠ 勾選矛盾",IF($T5="V","○ 免調理",IF($U5=0,"⚠ 資料缺漏",IF($U5=1,"▲ 單一設備依賴","OK"))))) -> ○ 免調理 | W5: =IF($E5="","",IF(AND($T5="V",$U5>0),"「無使用調理設備」不可與設備欄同時勾選，請擇一修正",IF($T5="V","免調理半成品（外購/僅切配等），不列入設備風險評估",IF($U5=0,"未勾選任何設備，請補填或勾選「無使用調理設備」",IF($U5=1,"僅依賴1台設備，須確認故障/排修時之備援製程","無異常"))))) -> 免調理半成品（外購/僅切配等），不列入設備風險評估 | X5: 大溪_2026.07.08_日式鮭魚茶泡烤飯.2026.07校正 | Z5: =IF($D5="",0,IF(COUNTIF($D$5:$D5,$D5)=1,1,0)) -> 1 | AA5: =IF(Z5=1,SUM($Z$5:$Z5),"") -> 1
A6: 下架 | B6: 大溪 | C6: 主食 | D6: 日式鮭魚茶泡烤飯 | E6: 2019傳統芥末醬 | F6: 3 | G6: 公克 | H6: 97 | T6: V | U6: =IF($E6="","",COUNTIF($I6:$S6,"V")) -> 0 | V6: =IF($E6="","",IF(AND($T6="V",$U6>0),"⚠ 勾選矛盾",IF($T6="V","○ 免調理",IF($U6=0,"⚠ 資料缺漏",IF($U6=1,"▲ 單一設備依賴","OK"))))) -> ○ 免調理 | W6: =IF($E6="","",IF(AND($T6="V",$U6>0),"「無使用調理設備」不可與設備欄同時勾選，請擇一修正",IF($T6="V","免調理半成品（外購/僅切配等），不列入設備風險評估",IF($U6=0,"未勾選任何設備，請補填或勾選「無使用調理設備」",IF($U6=1,"僅依賴1台設備，須確認故障/排修時之備援製程","無異常"))))) -> 免調理半成品（外購/僅切配等），不列入設備風險評估 | X6: 大溪_2026.07.08_日式鮭魚茶泡烤飯.2026.07校正 | Z6: =IF($D6="",0,IF(COUNTIF($D$5:$D6,$D6)=1,1,0)) -> 0 | AA6: =IF(Z6=1,SUM($Z$5:$Z6),"")
A7: 下架 | B7: 大溪 | C7: 主食 | D7: 日式鮭魚茶泡烤飯 | E7: 調味鮭魚熟碎肉CL | F7: 18 | G7: 公克 | H7: 90 | T7: V | U7: =IF($E7="","",COUNTIF($I7:$S7,"V")) -> 0 | V7: =IF($E7="","",IF(AND($T7="V",$U7>0),"⚠ 勾選矛盾",IF($T7="V","○ 免調理",IF($U7=0,"⚠ 資料缺漏",IF($U7=1,"▲ 單一設備依賴","OK"))))) -> ○ 免調理 | W7: =IF($E7="","",IF(AND($T7="V",$U7>0),"「無使用調理設備」不可與設備欄同時勾選，請擇一修正",IF($T7="V","免調理半成品（外購/僅切配等），不列入設備風險評估",IF($U7=0,"未勾選任何設備，請補填或勾選「無使用調理設備」",IF($U7=1,"僅依賴1台設備，須確認故障/排修時之備援製程","無異常"))))) -> 免調理半成品（外購/僅切配等），不列入設備風險評估 | X7: 大溪_2026.07.08_日式鮭魚茶泡烤飯.2026.07校正 | Z7: =IF($D7="",0,IF(COUNTIF($D$5:$D7,$D7)=1,1,0)) -> 0 | AA7: =IF(Z7=1,SUM($Z$5:$Z7),"")
A8: 下架 | B8: 大溪 | C8: 主食 | D8: 日式鮭魚茶泡烤飯 | E8: 泡飯-柴魚湯凍(115年) | F8: 260 | G8: 公克 | H8: 53 | O8: V | U8: =IF($E8="","",COUNTIF($I8:$S8,"V")) -> 1 | V8: =IF($E8="","",IF(AND($T8="V",$U8>0),"⚠ 勾選矛盾",IF($T8="V","○ 免調理",IF($U8=0,"⚠ 資料缺漏",IF($U8=1,"▲ 單一設備依賴","OK"))))) -> ▲ 單一設備依賴 | W8: =IF($E8="","",IF(AND($T8="V",$U8>0),"「無使用調理設備」不可與設備欄同時勾選，請擇一修正",IF($T8="V","免調理半成品（外購/僅切配等），不列入設備風險評估",IF($U8=0,"未勾選任何設備，請補填或勾選「無使用調理設備」",IF($U8=1,"僅依賴1台設備，須確認故障/排修時之備援製程","無異常"))))) -> 僅依賴1台設備，須確認故障/排修時之備援製程 | X8: 大溪_2026.07.08_日式鮭魚茶泡烤飯.2026.07校正 | Z8: =IF($D8="",0,IF(COUNTIF($D$5:$D8,$D8)=1,1,0)) -> 0 | AA8: =IF(Z8=1,SUM($Z$5:$Z8),"")
A9: 下架 | B9: 大溪 | C9: 主食 | D9: 日式鮭魚茶泡烤飯 | E9: 烤大三角飯糰(115年) | F9: 1 | G9: 個 | H9: 100 | I9: V | K9: V | O9: V | U9: =IF($E9="","",COUNTIF($I9:$S9,"V")) -> 3 | V9: =IF($E9="","",IF(AND($T9="V",$U9>0),"⚠ 勾選矛盾",IF($T9="V","○ 免調理",IF($U9=0,"⚠ 資料缺漏",IF($U9=1,"▲ 單一設備依賴","OK"))))) -> OK | W9: =IF($E9="","",IF(AND($T9="V",$U9>0),"「無使用調理設備」不可與設備欄同時勾選，請擇一修正",IF($T9="V","免調理半成品（外購/僅切配等），不列入設備風險評估",IF($U9=0,"未勾選任何設備，請補填或勾選「無使用調理設備」",IF($U9=1,"僅依賴1台設備，須確認故障/排修時之備援製程","無異常"))))) -> 無異常 | X9: 大溪_2026.07.08_日式鮭魚茶泡烤飯.2026.07校正 | Z9: =IF($D9="",0,IF(COUNTIF($D$5:$D9,$D9)=1,1,0)) -> 0 | AA9: =IF(Z9=1,SUM($Z$5:$Z9),"")
A10: 下架 | B10: 大溪 | C10: 主食 | D10: 日式鮭魚茶泡烤飯 | E10: 泡飯用-炒蛋碎(115年) | F10: 16 | G10: 公克 | H10: 54 | O10: V | U10: =IF($E10="","",COUNTIF($I10:$S10,"V")) -> 1 | V10: =IF($E10="","",IF(AND($T10="V",$U10>0),"⚠ 勾選矛盾",IF($T10="V","○ 免調理",IF($U10=0,"⚠ 資料缺漏",IF($U10=1,"▲ 單一設備依賴","OK"))))) -> ▲ 單一設備依賴 | W10: =IF($E10="","",IF(AND($T10="V",$U10>0),"「無使用調理設備」不可與設備欄同時勾選，請擇一修正",IF($T10="V","免調理半成品（外購/僅切配等），不列入設備風險評估",IF($U10=0,"未勾選任何設備，請補填或勾選「無使用調理設備」",IF($U10=1,"僅依賴1台設備，須確認故障/排修時之備援製程","無異常"))))) -> 僅依賴1台設備，須確認故障/排修時之備援製程 | X10: 大溪_2026.07.08_日式鮭魚茶泡烤飯.2026.07校正 | Z10: =IF($D10="",0,IF(COUNTIF($D$5:$D10,$D10)=1,1,0)) -> 0 | AA10: =IF(Z10=1,SUM($Z$5:$Z10),"")
A11: 下架 | B11: 大溪 | C11: 主食 | D11: 日式鮭魚茶泡烤飯 | E11: 消毒蔥花 | F11: 2 | G11: 公克 | H11: 70 | T11: V | U11: =IF($E11="","",COUNTIF($I11:$S11,"V")) -> 0 | V11: =IF($E11="","",IF(AND($T11="V",$U11>0),"⚠ 勾選矛盾",IF($T11="V","○ 免調理",IF($U11=0,"⚠ 資料缺漏",IF($U11=1,"▲ 單一設備依賴","OK"))))) -> ○ 免調理 | W11: =IF($E11="","",IF(AND($T11="V",$U11>0),"「無使用調理設備」不可與設備欄同時勾選，請擇一修正",IF($T11="V","免調理半成品（外購/僅切配等），不列入設備風險評估",IF($U11=0,"未勾選任何設備，請補填或勾選「無使用調理設備」",IF($U11=1,"僅依賴1台設備，須確認故障/排修時之備援製程","無異常"))))) -> 免調理半成品（外購/僅切配等），不列入設備風險評估 | X11: 大溪_2026.07.08_日式鮭魚茶泡烤飯.2026.07校正 | Z11: =IF($D11="",0,IF(COUNTIF($D$5:$D11,$D11)=1,1,0)) -> 0 | AA11: =IF(Z11=1,SUM($Z$5:$Z11),"")
A12: 下架 | B12: 大溪 | C12: 主食 | D12: 日式鮭魚茶泡烤飯 | E12: 自製香鬆(115年) | F12: 2 | G12: 公克 | H12: 84 | T12: V | U12: =IF($E12="","",COUNTIF($I12:$S12,"V")) -> 0 | V12: =IF($E12="","",IF(AND($T12="V",$U12>0),"⚠ 勾選矛盾",IF($T12="V","○ 免調理",IF($U12=0,"⚠ 資料缺漏",IF($U12=1,"▲ 單一設備依賴","OK"))))) -> ○ 免調理 | W12: =IF($E12="","",IF(AND($T12="V",$U12>0),"「無使用調理設備」不可與設備欄同時勾選，請擇一修正",IF($T12="V","免調理半成品（外購/僅切配等），不列入設備風險評估",IF($U12=0,"未勾選任何設備，請補填或勾選「無使用調理設備」",IF($U12=1,"僅依賴1台設備，須確認故障/排修時之備援製程","無異常"))))) -> 免調理半成品（外購/僅切配等），不列入設備風險評估 | X12: 大溪_2026.07.08_日式鮭魚茶泡烤飯.2026.07校正 | Z12: =IF($D12="",0,IF(COUNTIF($D$5:$D12,$D12)=1,1,0)) -> 0 | AA12: =IF(Z12=1,SUM($Z$5:$Z12),"")
A13: 架上 | B13: 大溪 | C13: 主食 | D13: 糖燻野郎三十天熟成牛飯(115年) | E13: 冷藏便當飯(109年) | F13: 225 | G13: 公克 | H13: 94 | I13: V | U13: =IF($E13="","",COUNTIF($I13:$S13,"V")) -> 1 | V13: =IF($E13="","",IF(AND($T13="V",$U13>0),"⚠ 勾選矛盾",IF($T13="V","○ 免調理",IF($U13=0,"⚠ 資料缺漏",IF($U13=1,"▲ 單一設備依賴","OK"))))) -> ▲ 單一設備依賴 | W13: =IF($E13="","",IF(AND($T13="V",$U13>0),"「無使用調理設備」不可與設備欄同時勾選，請擇一修正",IF($T13="V","免調理半成品（外購/僅切配等），不列入設備風險評估",IF($U13=0,"未勾選任何設備，請補填或勾選「無使用調理設備」",IF($U13=1,"僅依賴1台設備，須確認故障/排修時之備援製程","無異常"))))) -> 僅依賴1台設備，須確認故障/排修時之備援製程 | X13: 大溪_2026.06.24_糖燻野郎三十天熟成牛飯_2026.07校正 | Z13: =IF($D13="",0,IF(COUNTIF($D$5:$D13,$D13)=1,1,0)) -> 1 | AA13: =IF(Z13=1,SUM($Z$5:$Z13),"") -> 2
A14: 架上 | B14: 大溪 | C14: 主食 | D14: 糖燻野郎三十天熟成牛飯(115年) | E14: 烤黑胡椒洋蔥絲 | F14: 21 | G14: 公克 | H14: 52 | K14: V | U14: =IF($E14="","",COUNTIF($I14:$S14,"V")) -> 1 | V14: =IF($E14="","",IF(AND($T14="V",$U14>0),"⚠ 勾選矛盾",IF($T14="V","○ 免調理",IF($U14=0,"⚠ 資料缺漏",IF($U14=1,"▲ 單一設備依賴","OK"))))) -> ▲ 單一設備依賴 | W14: =IF($E14="","",IF(AND($T14="V",$U14>0),"「無使用調理設備」不可與設備欄同時勾選，請擇一修正",IF($T14="V","免調理半成品（外購/僅切配等），不列入設備風險評估",IF($U14=0,"未勾選任何設備，請補填或勾選「無使用調理設備」",IF($U14=1,"僅依賴1台設備，須確認故障/排修時之備援製程","無異常"))))) -> 僅依賴1台設備，須確認故障/排修時之備援製程 | X14: 大溪_2026.06.24_糖燻野郎三十天熟成牛飯_2026.07校正 | Z14: =IF($D14="",0,IF(COUNTIF($D$5:$D14,$D14)=1,1,0)) -> 0 | AA14: =IF(Z14=1,SUM($Z$5:$Z14),"")
A15: 架上 | B15: 大溪 | C15: 主食 | D15: 糖燻野郎三十天熟成牛飯(115年) | E15: 切-烤牛五花(115年) | F15: 43 | G15: 公克 | H15: 92 | K15: V | L15: V | U15: =IF($E15="","",COUNTIF($I15:$S15,"V")) -> 2 | V15: =IF($E15="","",IF(AND($T15="V",$U15>0),"⚠ 勾選矛盾",IF($T15="V","○ 免調理",IF($U15=0,"⚠ 資料缺漏",IF($U15=1,"▲ 單一設備依賴","OK"))))) -> OK | W15: =IF($E15="","",IF(AND($T15="V",$U15>0),"「無使用調理設備」不可與設備欄同時勾選，請擇一修正",IF($T15="V","免調理半成品（外購/僅切配等），不列入設備風險評估",IF($U15=0,"未勾選任何設備，請補填或勾選「無使用調理設備」",IF($U15=1,"僅依賴1台設備，須確認故障/排修時之備援製程","無異常"))))) -> 無異常 | X15: 大溪_2026.06.24_糖燻野郎三十天熟成牛飯_2026.07校正 | Z15: =IF($D15="",0,IF(COUNTIF($D$5:$D15,$D15)=1,1,0)) -> 0 | AA15: =IF(Z15=1,SUM($Z$5:$Z15),"")
A16: 架上 | B16: 大溪 | C16: 主食 | D16: 糖燻野郎三十天熟成牛飯(115年) | E16: 野郎醬(112年) | F16: 45 | G16: 公克 | H16: 55 | O16: V | U16: =IF($E16="","",COUNTIF($I16:$S16,"V")) -> 1 | V16: =IF($E16="","",IF(AND($T16="V",$U16>0),"⚠ 勾選矛盾",IF($T16="V","○ 免調理",IF($U16=0,"⚠ 資料缺漏",IF($U16=1,"▲ 單一設備依賴","OK"))))) -> ▲ 單一設備依賴 | W16: =IF($E16="","",IF(AND($T16="V",$U16>0),"「無使用調理設備」不可與設備欄同時勾選，請擇一修正",IF($T16="V","免調理半成品（外購/僅切配等），不列入設備風險評估",IF($U16=0,"未勾選任何設備，請補填或勾選「無使用調理設備」",IF($U16=1,"僅依賴1台設備，須確認故障/排修時之備援製程","無異常"))))) -> 僅依賴1台設備，須確認故障/排修時之備援製程 | X16: 大溪_2026.06.24_糖燻野郎三十天熟成牛飯_2026.07校正 | Z16: =IF($D16="",0,IF(COUNTIF($D$5:$D16,$D16)=1,1,0)) -> 0 | AA16: =IF(Z16=1,SUM($Z$5:$Z16),"")
A17: 架上 | B17: 大溪 | C17: 主食 | D17: 糖燻野郎三十天熟成牛飯(115年) | E17: 辣炒酸菜碎 | F17: 7 | G17: 公克 | H17: 46 | O17: V | U17: =IF($E17="","",COUNTIF($I17:$S17,"V")) -> 1 | V17: =IF($E17="","",IF(AND($T17="V",$U17>0),"⚠ 勾選矛盾",IF($T17="V","○ 免調理",IF($U17=0,"⚠ 資料缺漏",IF($U17=1,"▲ 單一設備依賴","OK"))))) -> ▲ 單一設備依賴 | W17: =IF($E17="","",IF(AND($T17="V",$U17>0),"「無使用調理設備」不可與設備欄同時勾選，請擇一修正",IF($T17="V","免調理半成品（外購/僅切配等），不列入設備風險評估",IF($U17=0,"未勾選任何設備，請補填或勾選「無使用調理設備」",IF($U17=1,"僅依賴1台設備，須確認故障/排修時之備援製程","無異常"))))) -> 僅依賴1台設備，須確認故障/排修時之備援製程 | X17: 大溪_2026.06.24_糖燻野郎三十天熟成牛飯_2026.07校正 | Z17: =IF($D17="",0,IF(COUNTIF($D$5:$D17,$D17)=1,1,0)) -> 0 | AA17: =IF(Z17=1,SUM($Z$5:$Z17),"")
A18: 架上 | B18: 大溪 | C18: 主食 | D18: 糖燻野郎三十天熟成牛飯(115年) | E18: 消毒蔥花 | F18: 2 | G18: 公克 | H18: 70 | T18: V | U18: =IF($E18="","",COUNTIF($I18:$S18,"V")) -> 0 | V18: =IF($E18="","",IF(AND($T18="V",$U18>0),"⚠ 勾選矛盾",IF($T18="V","○ 免調理",IF($U18=0,"⚠ 資料缺漏",IF($U18=1,"▲ 單一設備依賴","OK"))))) -> ○ 免調理 | W18: =IF($E18="","",IF(AND($T18="V",$U18>0),"「無使用調理設備」不可與設備欄同時勾選，請擇一修正",IF($T18="V","免調理半成品（外購/僅切配等），不列入設備風險評估",IF($U18=0,"未勾選任何設備，請補填或勾選「無使用調理設備」",IF($U18=1,"僅依賴1台設備，須確認故障/排修時之備援製程","無異常"))))) -> 免調理半成品（外購/僅切配等），不列入設備風險評估 | X18: 大溪_2026.06.24_糖燻野郎三十天熟成牛飯_2026.07校正 | Z18: =IF($D18="",0,IF(COUNTIF($D$5:$D18,$D18)=1,1,0)) -> 0 | AA18: =IF(Z18=1,SUM($Z$5:$Z18),"")
A19: 架上 | B19: 大溪 | C19: 主食 | D19: 糖燻野郎三十天熟成牛飯(115年) | E19: 小磨坊殺菌七味唐辛子(B070 | F19: 0.3 | G19: 公克 | H19: 97 | T19: V | U19: =IF($E19="","",COUNTIF($I19:$S19,"V")) -> 0 | V19: =IF($E19="","",IF(AND($T19="V",$U19>0),"⚠ 勾選矛盾",IF($T19="V","○ 免調理",IF($U19=0,"⚠ 資料缺漏",IF($U19=1,"▲ 單一設備依賴","OK"))))) -> ○ 免調理 | W19: =IF($E19="","",IF(AND($T19="V",$U19>0),"「無使用調理設備」不可與設備欄同時勾選，請擇一修正",IF($T19="V","免調理半成品（外購/僅切配等），不列入設備風險評估",IF($U19=0,"未勾選任何設備，請補填或勾選「無使用調理設備」",IF($U19=1,"僅依賴1台設備，須確認故障/排修時之備援製程","無異常"))))) -> 免調理半成品（外購/僅切配等），不列入設備風險評估 | X19: 大溪_2026.06.24_糖燻野郎三十天熟成牛飯_2026.07校正 | Z19: =IF($D19="",0,IF(COUNTIF($D$5:$D19,$D19)=1,1,0)) -> 0 | AA19: =IF(Z19=1,SUM($Z$5:$Z19),"")
A20: 架上 | B20: 大溪 | C20: 便當 | D20: 健身G肉餐盒 | E20: 煮麥仁薑黃飯(113年) | F20: 212 | G20: 公克 | H20: 91 | I20: V | O20: V | U20: =IF($E20="","",COUNTIF($I20:$S20,"V")) -> 2 | V20: =IF($E20="","",IF(AND($T20="V",$U20>0),"⚠ 勾選矛盾",IF($T20="V","○ 免調理",IF($U20=0,"⚠ 資料缺漏",IF($U20=1,"▲ 單一設備依賴","OK"))))) -> OK | W20: =IF($E20="","",IF(AND($T20="V",$U20>0),"「無使用調理設備」不可與設備欄同時勾選，請擇一修正",IF($T20="V","免調理半成品（外購/僅切配等），不列入設備風險評估",IF($U20=0,"未勾選任何設備，請補填或勾選「無使用調理設備」",IF($U20=1,"僅依賴1台設備，須確認故障/排修時之備援製程","無異常"))))) -> 無異常 | X20: 大溪_2024.09.18_健身G肉餐盒_2026.07校正 | Z20: =IF($D20="",0,IF(COUNTIF($D$5:$D20,$D20)=1,1,0)) -> 1 | AA20: =IF(Z20=1,SUM($Z$5:$Z20),"") -> 3
A21: 架上 | B21: 大溪 | C21: 便當 | D21: 健身G肉餐盒 | E21: 烤12切家常豆腐 | F21: 3 | G21: 個 | H21: 1200 | K21: V | U21: =IF($E21="","",COUNTIF($I21:$S21,"V")) -> 1 | V21: =IF($E21="","",IF(AND($T21="V",$U21>0),"⚠ 勾選矛盾",IF($T21="V","○ 免調理",IF($U21=0,"⚠ 資料缺漏",IF($U21=1,"▲ 單一設備依賴","OK"))))) -> ▲ 單一設備依賴 | W21: =IF($E21="","",IF(AND($T21="V",$U21>0),"「無使用調理設備」不可與設備欄同時勾選，請擇一修正",IF($T21="V","免調理半成品（外購/僅切配等），不列入設備風險評估",IF($U21=0,"未勾選任何設備，請補填或勾選「無使用調理設備」",IF($U21=1,"僅依賴1台設備，須確認故障/排修時之備援製程","無異常"))))) -> 僅依賴1台設備，須確認故障/排修時之備援製程 | X21: 大溪_2024.09.18_健身G肉餐盒_2026.07校正 | Z21: =IF($D21="",0,IF(COUNTIF($D$5:$D21,$D21)=1,1,0)) -> 0 | AA21: =IF(Z21=1,SUM($Z$5:$Z21),"")
A22: 架上 | B22: 大溪 | C22: 便當 | D22: 健身G肉餐盒 | E22: (V)川燙小青花菜 | F22: 24 | G22: 公克 | H22: 66 | O22: V | U22: =IF($E22="","",COUNTIF($I22:$S22,"V")) -> 1 | V22: =IF($E22="","",IF(AND($T22="V",$U22>0),"⚠ 勾選矛盾",IF($T22="V","○ 免調理",IF($U22=0,"⚠ 資料缺漏",IF($U22=1,"▲ 單一設備依賴","OK"))))) -> ▲ 單一設備依賴 | W22: =IF($E22="","",IF(AND($T22="V",$U22>0),"「無使用調理設備」不可與設備欄同時勾選，請擇一修正",IF($T22="V","免調理半成品（外購/僅切配等），不列入設備風險評估",IF($U22=0,"未勾選任何設備，請補填或勾選「無使用調理設備」",IF($U22=1,"僅依賴1台設備，須確認故障/排修時之備援製程","無異常"))))) -> 僅依賴1台設備，須確認故障/排修時之備援製程 | X22: 大溪_2024.09.18_健身G肉餐盒_2026.07校正 | Z22: =IF($D22="",0,IF(COUNTIF($D$5:$D22,$D22)=1,1,0)) -> 0 | AA22: =IF(Z22=1,SUM($Z$5:$Z22),"")
A23: 架上 | B23: 大溪 | C23: 便當 | D23: 健身G肉餐盒 | E23: 煮紅蘿蔔塊(VN101) | F23: 18 | G23: 公克 | H23: 58.4 | O23: V | U23: =IF($E23="","",COUNTIF($I23:$S23,"V")) -> 1 | V23: =IF($E23="","",IF(AND($T23="V",$U23>0),"⚠ 勾選矛盾",IF($T23="V","○ 免調理",IF($U23=0,"⚠ 資料缺漏",IF($U23=1,"▲ 單一設備依賴","OK"))))) -> ▲ 單一設備依賴 | W23: =IF($E23="","",IF(AND($T23="V",$U23>0),"「無使用調理設備」不可與設備欄同時勾選，請擇一修正",IF($T23="V","免調理半成品（外購/僅切配等），不列入設備風險評估",IF($U23=0,"未勾選任何設備，請補填或勾選「無使用調理設備」",IF($U23=1,"僅依賴1台設備，須確認故障/排修時之備援製程","無異常"))))) -> 僅依賴1台設備，須確認故障/排修時之備援製程 | X23: 大溪_2024.09.18_健身G肉餐盒_2026.07校正 | Z23: =IF($D23="",0,IF(COUNTIF($D$5:$D23,$D23)=1,1,0)) -> 0 | AA23: =IF(Z23=1,SUM($Z$5:$Z23),"")
