Workbook

Sheet 總覽
B1: 商品半成品與調理設備應用盤點｜總覽目錄
B3: 盤點基本資訊（黃底請填寫） | E3: 本廠總體統計（自動計算）
B4: 盤點工廠 | C4: 新豐 | E4: 生產總品項數 | F4: =SUM(MAX('18℃'!$Z$5:$Z$304),MAX('4℃飯'!$AA$5:$AA$302),MAX('4℃麵'!$AA$5:$AA$305),MAX('4℃其他'!$AA$5:$AA$302),MAX(冷凍品!$Z$5:$Z$304)) -> 79
B5: 盤點日期 | C5: 46220 | E5: 半成品總筆數 | F5: =COUNTA('18℃'!$D$5:$D$304)+COUNTA('4℃飯'!$E$5:$E$302)+COUNTA('4℃麵'!$E$5:$E$305)+COUNTA('4℃其他'!$E$5:$E$302)+COUNTA(冷凍品!$D$5:$D$304) -> 422
B6: 盤點負責人 | C6: 王安淇 | E6: 資料缺漏/矛盾筆數 | F6: =COUNTIF('18℃'!$U$5:$U$304,"⚠*")+COUNTIF('4℃飯'!$V$5:$V$302,"⚠*")+COUNTIF('4℃麵'!$V$5:$V$305,"⚠*")+COUNTIF('4℃其他'!$V$5:$V$302,"⚠*")+COUNTIF(冷凍品!$U$5:$U$304,"⚠*") -> 0
E7: 單一設備依賴筆數 | F7: =COUNTIF('18℃'!$U$5:$U$304,"▲ 單一設備依賴")+COUNTIF('4℃飯'!$V$5:$V$302,"▲ 單一設備依賴")+COUNTIF('4℃麵'!$V$5:$V$305,"▲ 單一設備依賴")+COUNTIF('4℃其他'!$V$5:$V$302,"▲ 單一設備依賴")+COUNTIF(冷凍品!$U$5:$U$304,"▲ 單一設備依賴") -> 198
E8: 免調理半成品筆數 | F8: =COUNTIF('18℃'!$U$5:$U$304,"○ 免調理")+COUNTIF('4℃飯'!$V$5:$V$302,"○ 免調理")+COUNTIF('4℃麵'!$V$5:$V$305,"○ 免調理")+COUNTIF('4℃其他'!$V$5:$V$302,"○ 免調理")+COUNTIF(冷凍品!$U$5:$U$304,"○ 免調理") -> 209
B10: 商品分類分布
B11: 分類 | C11: 品項數 | D11: 品項佔比 | E11: 半成品筆數 | F11: 半成品佔比
B12: 18℃ | C12: =MAX('18℃'!$Z$5:$Z$304) -> 0 | D12: =IF($F$4=0,0,C12/$F$4) -> 0 | E12: =COUNTA('18℃'!$D$5:$D$304) -> 0 | F12: =IF($F$5=0,0,E12/$F$5) -> 0
B13: 4℃飯 | C13: =MAX('4℃飯'!$AA$5:$AA$302) -> 28 | D13: =IF($F$4=0,0,C13/$F$4) -> 0.35443038 | E13: =COUNTA('4℃飯'!$E$5:$E$302) -> 164 | F13: =IF($F$5=0,0,E13/$F$5) -> 0.38862559
B14: 4℃麵 | C14: =MAX('4℃麵'!$AA$5:$AA$305) -> 4 | D14: =IF($F$4=0,0,C14/$F$4) -> 0.050632911 | E14: =COUNTA('4℃麵'!$E$5:$E$305) -> 23 | F14: =IF($F$5=0,0,E14/$F$5) -> 0.05450237
B15: 4℃其他 | C15: =MAX('4℃其他'!$AA$5:$AA$302) -> 47 | D15: =IF($F$4=0,0,C15/$F$4) -> 0.59493671 | E15: =COUNTA('4℃其他'!$E$5:$E$302) -> 235 | F15: =IF($F$5=0,0,E15/$F$5) -> 0.55687204
B16: 冷凍品 | C16: =MAX(冷凍品!$Z$5:$Z$304) -> 0 | D16: =IF($F$4=0,0,C16/$F$4) -> 0 | E16: =COUNTA(冷凍品!$D$5:$D$304) -> 0 | F16: =IF($F$5=0,0,E16/$F$5) -> 0
B17: 合計 | C17: =SUM(C12:C16) -> 79 | E17: =SUM(E12:E16) -> 422
B19: 商品目錄（自動列出各分頁不重複品項，勿手動修改）
B20: 18℃ | C20: 4℃飯 | D20: 4℃麵 | E20: 4℃其他 | F20: 冷凍品
B21: ="品項數："&MAX('18℃'!$Z$5:$Z$304) -> 品項數：0 | C21: ="品項數："&MAX('4℃飯'!$AA$5:$AA$302) -> 品項數：28 | D21: ="品項數："&MAX('4℃麵'!$AA$5:$AA$305) -> 品項數：4 | E21: ="品項數："&MAX('4℃其他'!$AA$5:$AA$302) -> 品項數：47 | F21: ="品項數："&MAX(冷凍品!$Z$5:$Z$304) -> 品項數：0
B22: =IF(1>MAX('18℃'!$Z$5:$Z$304),"",HYPERLINK("#'18℃'!C"&(MATCH(1,'18℃'!$Z$5:$Z$304,0)+4),INDEX('18℃'!$C$5:$C$304,MATCH(1,'18℃'!$Z$5:$Z$304,0)))) | C22: =IF(1>MAX('4℃飯'!$AA$5:$AA$302),"",HYPERLINK("#'4℃飯'!D"&(MATCH(1,'4℃飯'!$AA$5:$AA$302,0)+4),INDEX('4℃飯'!$D$5:$D$302,MATCH(1,'4℃飯'!$AA$5:$AA$302,0)))) -> 鐵板滑蛋炸豬排丼 | D22: =IF(1>MAX('4℃麵'!$AA$5:$AA$305),"",HYPERLINK("#'4℃麵'!D"&(MATCH(1,'4℃麵'!$AA$5:$AA$305,0)+4),INDEX('4℃麵'!$D$5:$D$305,MATCH(1,'4℃麵'!$AA$5:$AA$305,0)))) -> 台式麻醬涼麵 | E22: =IF(1>MAX('4℃其他'!$AA$5:$AA$302),"",HYPERLINK("#'4℃其他'!D"&(MATCH(1,'4℃其他'!$AA$5:$AA$302,0)+4),INDEX('4℃其他'!$D$5:$D$302,MATCH(1,'4℃其他'!$AA$5:$AA$302,0)))) -> 厚蛋時蔬握沙拉 | F22: =IF(1>MAX(冷凍品!$Z$5:$Z$304),"",HYPERLINK("#'冷凍品'!C"&(MATCH(1,冷凍品!$Z$5:$Z$304,0)+4),INDEX(冷凍品!$C$5:$C$304,MATCH(1,冷凍品!$Z$5:$Z$304,0))))
B23: =IF(2>MAX('18℃'!$Z$5:$Z$304),"",HYPERLINK("#'18℃'!C"&(MATCH(2,'18℃'!$Z$5:$Z$304,0)+4),INDEX('18℃'!$C$5:$C$304,MATCH(2,'18℃'!$Z$5:$Z$304,0)))) | C23: =IF(2>MAX('4℃飯'!$AA$5:$AA$302),"",HYPERLINK("#'4℃飯'!D"&(MATCH(2,'4℃飯'!$AA$5:$AA$302,0)+4),INDEX('4℃飯'!$D$5:$D$302,MATCH(2,'4℃飯'!$AA$5:$AA$302,0)))) -> 炙烤醬香燒豚飯 | D23: =IF(2>MAX('4℃麵'!$AA$5:$AA$305),"",HYPERLINK("#'4℃麵'!D"&(MATCH(2,'4℃麵'!$AA$5:$AA$305,0)+4),INDEX('4℃麵'!$D$5:$D$305,MATCH(2,'4℃麵'!$AA$5:$AA$305,0)))) -> 鰹魚烏龍冷麵 | E23: =IF(2>MAX('4℃其他'!$AA$5:$AA$302),"",HYPERLINK("#'4℃其他'!D"&(MATCH(2,'4℃其他'!$AA$5:$AA$302,0)+4),INDEX('4℃其他'!$D$5:$D$302,MATCH(2,'4℃其他'!$AA$5:$AA$302,0)))) -> 莎莎烤雞麵沙拉 | F23: =IF(2>MAX(冷凍品!$Z$5:$Z$304),"",HYPERLINK("#'冷凍品'!C"&(MATCH(2,冷凍品!$Z$5:$Z$304,0)+4),INDEX(冷凍品!$C$5:$C$304,MATCH(2,冷凍品!$Z$5:$Z$304,0))))
B24: =IF(3>MAX('18℃'!$Z$5:$Z$304),"",HYPERLINK("#'18℃'!C"&(MATCH(3,'18℃'!$Z$5:$Z$304,0)+4),INDEX('18℃'!$C$5:$C$304,MATCH(3,'18℃'!$Z$5:$Z$304,0)))) | C24: =IF(3>MAX('4℃飯'!$AA$5:$AA$302),"",HYPERLINK("#'4℃飯'!D"&(MATCH(3,'4℃飯'!$AA$5:$AA$302,0)+4),INDEX('4℃飯'!$D$5:$D$302,MATCH(3,'4℃飯'!$AA$5:$AA$302,0)))) -> 壹號醬雞豚雙拼 | D24: =IF(3>MAX('4℃麵'!$AA$5:$AA$305),"",HYPERLINK("#'4℃麵'!D"&(MATCH(3,'4℃麵'!$AA$5:$AA$305,0)+4),INDEX('4℃麵'!$D$5:$D$305,MATCH(3,'4℃麵'!$AA$5:$AA$305,0)))) -> 泰式炒河粉 | E24: =IF(3>MAX('4℃其他'!$AA$5:$AA$302),"",HYPERLINK("#'4℃其他'!D"&(MATCH(3,'4℃其他'!$AA$5:$AA$302,0)+4),INDEX('4℃其他'!$D$5:$D$302,MATCH(3,'4℃其他'!$AA$5:$AA$302,0)))) -> 青檸烤雞握沙拉 | F24: =IF(3>MAX(冷凍品!$Z$5:$Z$304),"",HYPERLINK("#'冷凍品'!C"&(MATCH(3,冷凍品!$Z$5:$Z$304,0)+4),INDEX(冷凍品!$C$5:$C$304,MATCH(3,冷凍品!$Z$5:$Z$304,0))))
B25: =IF(4>MAX('18℃'!$Z$5:$Z$304),"",HYPERLINK("#'18℃'!C"&(MATCH(4,'18℃'!$Z$5:$Z$304,0)+4),INDEX('18℃'!$C$5:$C$304,MATCH(4,'18℃'!$Z$5:$Z$304,0)))) | C25: =IF(4>MAX('4℃飯'!$AA$5:$AA$302),"",HYPERLINK("#'4℃飯'!D"&(MATCH(4,'4℃飯'!$AA$5:$AA$302,0)+4),INDEX('4℃飯'!$D$5:$D$302,MATCH(4,'4℃飯'!$AA$5:$AA$302,0)))) -> 香辣醬蒜味香腸蛋炒飯 | D25: =IF(4>MAX('4℃麵'!$AA$5:$AA$305),"",HYPERLINK("#'4℃麵'!D"&(MATCH(4,'4℃麵'!$AA$5:$AA$305,0)+4),INDEX('4℃麵'!$D$5:$D$305,MATCH(4,'4℃麵'!$AA$5:$AA$305,0)))) -> 嫩烤魚排佐花椰菜義大利麵 | E25: =IF(4>MAX('4℃其他'!$AA$5:$AA$302),"",HYPERLINK("#'4℃其他'!D"&(MATCH(4,'4℃其他'!$AA$5:$AA$302,0)+4),INDEX('4℃其他'!$D$5:$D$302,MATCH(4,'4℃其他'!$AA$5:$AA$302,0)))) -> 青醬優格雞肉握沙拉 | F25: =IF(4>MAX(冷凍品!$Z$5:$Z$304),"",HYPERLINK("#'冷凍品'!C"&(MATCH(4,冷凍品!$Z$5:$Z$304,0)+4),INDEX(冷凍品!$C$5:$C$304,MATCH(4,冷凍品!$Z$5:$Z$304,0))))
B26: =IF(5>MAX('18℃'!$Z$5:$Z$304),"",HYPERLINK("#'18℃'!C"&(MATCH(5,'18℃'!$Z$5:$Z$304,0)+4),INDEX('18℃'!$C$5:$C$304,MATCH(5,'18℃'!$Z$5:$Z$304,0)))) | C26: =IF(5>MAX('4℃飯'!$AA$5:$AA$302),"",HYPERLINK("#'4℃飯'!D"&(MATCH(5,'4℃飯'!$AA$5:$AA$302,0)+4),INDEX('4℃飯'!$D$5:$D$302,MATCH(5,'4℃飯'!$AA$5:$AA$302,0)))) -> 藤椒雞丁炒飯 | D26: =IF(5>MAX('4℃麵'!$AA$5:$AA$305),"",HYPERLINK("#'4℃麵'!D"&(MATCH(5,'4℃麵'!$AA$5:$AA$305,0)+4),INDEX('4℃麵'!$D$5:$D$305,MATCH(5,'4℃麵'!$AA$5:$AA$305,0)))) | E26: =IF(5>MAX('4℃其他'!$AA$5:$AA$302),"",HYPERLINK("#'4℃其他'!D"&(MATCH(5,'4℃其他'!$AA$5:$AA$302,0)+4),INDEX('4℃其他'!$D$5:$D$302,MATCH(5,'4℃其他'!$AA$5:$AA$302,0)))) -> 蔥鹽雞肉麵沙拉 | F26: =IF(5>MAX(冷凍品!$Z$5:$Z$304),"",HYPERLINK("#'冷凍品'!C"&(MATCH(5,冷凍品!$Z$5:$Z$304,0)+4),INDEX(冷凍品!$C$5:$C$304,MATCH(5,冷凍品!$Z$5:$Z$304,0))))
B27: =IF(6>MAX('18℃'!$Z$5:$Z$304),"",HYPERLINK("#'18℃'!C"&(MATCH(6,'18℃'!$Z$5:$Z$304,0)+4),INDEX('18℃'!$C$5:$C$304,MATCH(6,'18℃'!$Z$5:$Z$304,0)))) | C27: =IF(6>MAX('4℃飯'!$AA$5:$AA$302),"",HYPERLINK("#'4℃飯'!D"&(MATCH(6,'4℃飯'!$AA$5:$AA$302,0)+4),INDEX('4℃飯'!$D$5:$D$302,MATCH(6,'4℃飯'!$AA$5:$AA$302,0)))) -> 川味麻婆燒豆腐燴飯 | D27: =IF(6>MAX('4℃麵'!$AA$5:$AA$305),"",HYPERLINK("#'4℃麵'!D"&(MATCH(6,'4℃麵'!$AA$5:$AA$305,0)+4),INDEX('4℃麵'!$D$5:$D$305,MATCH(6,'4℃麵'!$AA$5:$AA$305,0)))) | E27: =IF(6>MAX('4℃其他'!$AA$5:$AA$302),"",HYPERLINK("#'4℃其他'!D"&(MATCH(6,'4℃其他'!$AA$5:$AA$302,0)+4),INDEX('4℃其他'!$D$5:$D$302,MATCH(6,'4℃其他'!$AA$5:$AA$302,0)))) -> 地瓜瓜握沙拉 | F27: =IF(6>MAX(冷凍品!$Z$5:$Z$304),"",HYPERLINK("#'冷凍品'!C"&(MATCH(6,冷凍品!$Z$5:$Z$304,0)+4),INDEX(冷凍品!$C$5:$C$304,MATCH(6,冷凍品!$Z$5:$Z$304,0))))
B28: =IF(7>MAX('18℃'!$Z$5:$Z$304),"",HYPERLINK("#'18℃'!C"&(MATCH(7,'18℃'!$Z$5:$Z$304,0)+4),INDEX('18℃'!$C$5:$C$304,MATCH(7,'18℃'!$Z$5:$Z$304,0)))) | C28: =IF(7>MAX('4℃飯'!$AA$5:$AA$302),"",HYPERLINK("#'4℃飯'!D"&(MATCH(7,'4℃飯'!$AA$5:$AA$302,0)+4),INDEX('4℃飯'!$D$5:$D$302,MATCH(7,'4℃飯'!$AA$5:$AA$302,0)))) -> 金咖哩濃厚辛口咖哩飯 | D28: =IF(7>MAX('4℃麵'!$AA$5:$AA$305),"",HYPERLINK("#'4℃麵'!D"&(MATCH(7,'4℃麵'!$AA$5:$AA$305,0)+4),INDEX('4℃麵'!$D$5:$D$305,MATCH(7,'4℃麵'!$AA$5:$AA$305,0)))) | E28: =IF(7>MAX('4℃其他'!$AA$5:$AA$302),"",HYPERLINK("#'4℃其他'!D"&(MATCH(7,'4℃其他'!$AA$5:$AA$302,0)+4),INDEX('4℃其他'!$D$5:$D$302,MATCH(7,'4℃其他'!$AA$5:$AA$302,0)))) -> 香雞蛋堡 | F28: =IF(7>MAX(冷凍品!$Z$5:$Z$304),"",HYPERLINK("#'冷凍品'!C"&(MATCH(7,冷凍品!$Z$5:$Z$304,0)+4),INDEX(冷凍品!$C$5:$C$304,MATCH(7,冷凍品!$Z$5:$Z$304,0))))
B29: =IF(8>MAX('18℃'!$Z$5:$Z$304),"",HYPERLINK("#'18℃'!C"&(MATCH(8,'18℃'!$Z$5:$Z$304,0)+4),INDEX('18℃'!$C$5:$C$304,MATCH(8,'18℃'!$Z$5:$Z$304,0)))) | C29: =IF(8>MAX('4℃飯'!$AA$5:$AA$302),"",HYPERLINK("#'4℃飯'!D"&(MATCH(8,'4℃飯'!$AA$5:$AA$302,0)+4),INDEX('4℃飯'!$D$5:$D$302,MATCH(8,'4℃飯'!$AA$5:$AA$302,0)))) -> 金咖哩果香甘口咖哩飯 | D29: =IF(8>MAX('4℃麵'!$AA$5:$AA$305),"",HYPERLINK("#'4℃麵'!D"&(MATCH(8,'4℃麵'!$AA$5:$AA$305,0)+4),INDEX('4℃麵'!$D$5:$D$305,MATCH(8,'4℃麵'!$AA$5:$AA$305,0)))) | E29: =IF(8>MAX('4℃其他'!$AA$5:$AA$302),"",HYPERLINK("#'4℃其他'!D"&(MATCH(8,'4℃其他'!$AA$5:$AA$302,0)+4),INDEX('4℃其他'!$D$5:$D$302,MATCH(8,'4℃其他'!$AA$5:$AA$302,0)))) -> 經典雙牛起司堡 | F29: =IF(8>MAX(冷凍品!$Z$5:$Z$304),"",HYPERLINK("#'冷凍品'!C"&(MATCH(8,冷凍品!$Z$5:$Z$304,0)+4),INDEX(冷凍品!$C$5:$C$304,MATCH(8,冷凍品!$Z$5:$Z$304,0))))
B30: =IF(9>MAX('18℃'!$Z$5:$Z$304),"",HYPERLINK("#'18℃'!C"&(MATCH(9,'18℃'!$Z$5:$Z$304,0)+4),INDEX('18℃'!$C$5:$C$304,MATCH(9,'18℃'!$Z$5:$Z$304,0)))) | C30: =IF(9>MAX('4℃飯'!$AA$5:$AA$302),"",HYPERLINK("#'4℃飯'!D"&(MATCH(9,'4℃飯'!$AA$5:$AA$302,0)+4),INDEX('4℃飯'!$D$5:$D$302,MATCH(9,'4℃飯'!$AA$5:$AA$302,0)))) -> 港式香滑嫩蛋牛肉燴飯 | D30: =IF(9>MAX('4℃麵'!$AA$5:$AA$305),"",HYPERLINK("#'4℃麵'!D"&(MATCH(9,'4℃麵'!$AA$5:$AA$305,0)+4),INDEX('4℃麵'!$D$5:$D$305,MATCH(9,'4℃麵'!$AA$5:$AA$305,0)))) | E30: =IF(9>MAX('4℃其他'!$AA$5:$AA$302),"",HYPERLINK("#'4℃其他'!D"&(MATCH(9,'4℃其他'!$AA$5:$AA$302,0)+4),INDEX('4℃其他'!$D$5:$D$302,MATCH(9,'4℃其他'!$AA$5:$AA$302,0)))) -> 豬肉起司堡 | F30: =IF(9>MAX(冷凍品!$Z$5:$Z$304),"",HYPERLINK("#'冷凍品'!C"&(MATCH(9,冷凍品!$Z$5:$Z$304,0)+4),INDEX(冷凍品!$C$5:$C$304,MATCH(9,冷凍品!$Z$5:$Z$304,0))))
B31: =IF(10>MAX('18℃'!$Z$5:$Z$304),"",HYPERLINK("#'18℃'!C"&(MATCH(10,'18℃'!$Z$5:$Z$304,0)+4),INDEX('18℃'!$C$5:$C$304,MATCH(10,'18℃'!$Z$5:$Z$304,0)))) | C31: =IF(10>MAX('4℃飯'!$AA$5:$AA$302),"",HYPERLINK("#'4℃飯'!D"&(MATCH(10,'4℃飯'!$AA$5:$AA$302,0)+4),INDEX('4℃飯'!$D$5:$D$302,MATCH(10,'4℃飯'!$AA$5:$AA$302,0)))) -> 泰式綠咖哩雞 | D31: =IF(10>MAX('4℃麵'!$AA$5:$AA$305),"",HYPERLINK("#'4℃麵'!D"&(MATCH(10,'4℃麵'!$AA$5:$AA$305,0)+4),INDEX('4℃麵'!$D$5:$D$305,MATCH(10,'4℃麵'!$AA$5:$AA$305,0)))) | E31: =IF(10>MAX('4℃其他'!$AA$5:$AA$302),"",HYPERLINK("#'4℃其他'!D"&(MATCH(10,'4℃其他'!$AA$5:$AA$302,0)+4),INDEX('4℃其他'!$D$5:$D$302,MATCH(10,'4℃其他'!$AA$5:$AA$302,0)))) -> 豬肉起司蛋堡 | F31: =IF(10>MAX(冷凍品!$Z$5:$Z$304),"",HYPERLINK("#'冷凍品'!C"&(MATCH(10,冷凍品!$Z$5:$Z$304,0)+4),INDEX(冷凍品!$C$5:$C$304,MATCH(10,冷凍品!$Z$5:$Z$304,0))))
B32: =IF(11>MAX('18℃'!$Z$5:$Z$304),"",HYPERLINK("#'18℃'!C"&(MATCH(11,'18℃'!$Z$5:$Z$304,0)+4),INDEX('18℃'!$C$5:$C$304,MATCH(11,'18℃'!$Z$5:$Z$304,0)))) | C32: =IF(11>MAX('4℃飯'!$AA$5:$AA$302),"",HYPERLINK("#'4℃飯'!D"&(MATCH(11,'4℃飯'!$AA$5:$AA$302,0)+4),INDEX('4℃飯'!$D$5:$D$302,MATCH(11,'4℃飯'!$AA$5:$AA$302,0)))) -> 打拋風味豬肉飯 | D32: =IF(11>MAX('4℃麵'!$AA$5:$AA$305),"",HYPERLINK("#'4℃麵'!D"&(MATCH(11,'4℃麵'!$AA$5:$AA$305,0)+4),INDEX('4℃麵'!$D$5:$D$305,MATCH(11,'4℃麵'!$AA$5:$AA$305,0)))) | E32: =IF(11>MAX('4℃其他'!$AA$5:$AA$302),"",HYPERLINK("#'4℃其他'!D"&(MATCH(11,'4℃其他'!$AA$5:$AA$302,0)+4),INDEX('4℃其他'!$D$5:$D$302,MATCH(11,'4℃其他'!$AA$5:$AA$302,0)))) -> 美式雞腿堡 | F32: =IF(11>MAX(冷凍品!$Z$5:$Z$304),"",HYPERLINK("#'冷凍品'!C"&(MATCH(11,冷凍品!$Z$5:$Z$304,0)+4),INDEX(冷凍品!$C$5:$C$304,MATCH(11,冷凍品!$Z$5:$Z$304,0))))
B33: =IF(12>MAX('18℃'!$Z$5:$Z$304),"",HYPERLINK("#'18℃'!C"&(MATCH(12,'18℃'!$Z$5:$Z$304,0)+4),INDEX('18℃'!$C$5:$C$304,MATCH(12,'18℃'!$Z$5:$Z$304,0)))) | C33: =IF(12>MAX('4℃飯'!$AA$5:$AA$302),"",HYPERLINK("#'4℃飯'!D"&(MATCH(12,'4℃飯'!$AA$5:$AA$302,0)+4),INDEX('4℃飯'!$D$5:$D$302,MATCH(12,'4℃飯'!$AA$5:$AA$302,0)))) -> 厚香料優格咖哩雞排飯 | D33: =IF(12>MAX('4℃麵'!$AA$5:$AA$305),"",HYPERLINK("#'4℃麵'!D"&(MATCH(12,'4℃麵'!$AA$5:$AA$305,0)+4),INDEX('4℃麵'!$D$5:$D$305,MATCH(12,'4℃麵'!$AA$5:$AA$305,0)))) | E33: =IF(12>MAX('4℃其他'!$AA$5:$AA$302),"",HYPERLINK("#'4℃其他'!D"&(MATCH(12,'4℃其他'!$AA$5:$AA$302,0)+4),INDEX('4℃其他'!$D$5:$D$302,MATCH(12,'4℃其他'!$AA$5:$AA$302,0)))) -> 厚豆腐蛋白蕈菇豬肉堡 | F33: =IF(12>MAX(冷凍品!$Z$5:$Z$304),"",HYPERLINK("#'冷凍品'!C"&(MATCH(12,冷凍品!$Z$5:$Z$304,0)+4),INDEX(冷凍品!$C$5:$C$304,MATCH(12,冷凍品!$Z$5:$Z$304,0))))
B34: =IF(13>MAX('18℃'!$Z$5:$Z$304),"",HYPERLINK("#'18℃'!C"&(MATCH(13,'18℃'!$Z$5:$Z$304,0)+4),INDEX('18℃'!$C$5:$C$304,MATCH(13,'18℃'!$Z$5:$Z$304,0)))) | C34: =IF(13>MAX('4℃飯'!$AA$5:$AA$302),"",HYPERLINK("#'4℃飯'!D"&(MATCH(13,'4℃飯'!$AA$5:$AA$302,0)+4),INDEX('4℃飯'!$D$5:$D$302,MATCH(13,'4℃飯'!$AA$5:$AA$302,0)))) -> 玉米濃湯焗烤飯 | D34: =IF(13>MAX('4℃麵'!$AA$5:$AA$305),"",HYPERLINK("#'4℃麵'!D"&(MATCH(13,'4℃麵'!$AA$5:$AA$305,0)+4),INDEX('4℃麵'!$D$5:$D$305,MATCH(13,'4℃麵'!$AA$5:$AA$305,0)))) | E34: =IF(13>MAX('4℃其他'!$AA$5:$AA$302),"",HYPERLINK("#'4℃其他'!D"&(MATCH(13,'4℃其他'!$AA$5:$AA$302,0)+4),INDEX('4℃其他'!$D$5:$D$302,MATCH(13,'4℃其他'!$AA$5:$AA$302,0)))) -> 黃金魚堡(114年) | F34: =IF(13>MAX(冷凍品!$Z$5:$Z$304),"",HYPERLINK("#'冷凍品'!C"&(MATCH(13,冷凍品!$Z$5:$Z$304,0)+4),INDEX(冷凍品!$C$5:$C$304,MATCH(13,冷凍品!$Z$5:$Z$304,0))))
B35: =IF(14>MAX('18℃'!$Z$5:$Z$304),"",HYPERLINK("#'18℃'!C"&(MATCH(14,'18℃'!$Z$5:$Z$304,0)+4),INDEX('18℃'!$C$5:$C$304,MATCH(14,'18℃'!$Z$5:$Z$304,0)))) | C35: =IF(14>MAX('4℃飯'!$AA$5:$AA$302),"",HYPERLINK("#'4℃飯'!D"&(MATCH(14,'4℃飯'!$AA$5:$AA$302,0)+4),INDEX('4℃飯'!$D$5:$D$302,MATCH(14,'4℃飯'!$AA$5:$AA$302,0)))) -> 美味蟹煲 | D35: =IF(14>MAX('4℃麵'!$AA$5:$AA$305),"",HYPERLINK("#'4℃麵'!D"&(MATCH(14,'4℃麵'!$AA$5:$AA$305,0)+4),INDEX('4℃麵'!$D$5:$D$305,MATCH(14,'4℃麵'!$AA$5:$AA$305,0)))) | E35: =IF(14>MAX('4℃其他'!$AA$5:$AA$302),"",HYPERLINK("#'4℃其他'!D"&(MATCH(14,'4℃其他'!$AA$5:$AA$302,0)+4),INDEX('4℃其他'!$D$5:$D$302,MATCH(14,'4℃其他'!$AA$5:$AA$302,0)))) -> 元氣起司鱈魚堡 | F35: =IF(14>MAX(冷凍品!$Z$5:$Z$304),"",HYPERLINK("#'冷凍品'!C"&(MATCH(14,冷凍品!$Z$5:$Z$304,0)+4),INDEX(冷凍品!$C$5:$C$304,MATCH(14,冷凍品!$Z$5:$Z$304,0))))
B36: =IF(15>MAX('18℃'!$Z$5:$Z$304),"",HYPERLINK("#'18℃'!C"&(MATCH(15,'18℃'!$Z$5:$Z$304,0)+4),INDEX('18℃'!$C$5:$C$304,MATCH(15,'18℃'!$Z$5:$Z$304,0)))) | C36: =IF(15>MAX('4℃飯'!$AA$5:$AA$302),"",HYPERLINK("#'4℃飯'!D"&(MATCH(15,'4℃飯'!$AA$5:$AA$302,0)+4),INDEX('4℃飯'!$D$5:$D$302,MATCH(15,'4℃飯'!$AA$5:$AA$302,0)))) -> 韓式泡菜豬肉豆腐丼飯 | D36: =IF(15>MAX('4℃麵'!$AA$5:$AA$305),"",HYPERLINK("#'4℃麵'!D"&(MATCH(15,'4℃麵'!$AA$5:$AA$305,0)+4),INDEX('4℃麵'!$D$5:$D$305,MATCH(15,'4℃麵'!$AA$5:$AA$305,0)))) | E36: =IF(15>MAX('4℃其他'!$AA$5:$AA$302),"",HYPERLINK("#'4℃其他'!D"&(MATCH(15,'4℃其他'!$AA$5:$AA$302,0)+4),INDEX('4℃其他'!$D$5:$D$302,MATCH(15,'4℃其他'!$AA$5:$AA$302,0)))) -> 剝皮辣椒雞湯 | F36: =IF(15>MAX(冷凍品!$Z$5:$Z$304),"",HYPERLINK("#'冷凍品'!C"&(MATCH(15,冷凍品!$Z$5:$Z$304,0)+4),INDEX(冷凍品!$C$5:$C$304,MATCH(15,冷凍品!$Z$5:$Z$304,0))))
B37: =IF(16>MAX('18℃'!$Z$5:$Z$304),"",HYPERLINK("#'18℃'!C"&(MATCH(16,'18℃'!$Z$5:$Z$304,0)+4),INDEX('18℃'!$C$5:$C$304,MATCH(16,'18℃'!$Z$5:$Z$304,0)))) | C37: =IF(16>MAX('4℃飯'!$AA$5:$AA$302),"",HYPERLINK("#'4℃飯'!D"&(MATCH(16,'4℃飯'!$AA$5:$AA$302,0)+4),INDEX('4℃飯'!$D$5:$D$302,MATCH(16,'4℃飯'!$AA$5:$AA$302,0)))) -> 日式炙烤親子丼 | D37: =IF(16>MAX('4℃麵'!$AA$5:$AA$305),"",HYPERLINK("#'4℃麵'!D"&(MATCH(16,'4℃麵'!$AA$5:$AA$305,0)+4),INDEX('4℃麵'!$D$5:$D$305,MATCH(16,'4℃麵'!$AA$5:$AA$305,0)))) | E37: =IF(16>MAX('4℃其他'!$AA$5:$AA$302),"",HYPERLINK("#'4℃其他'!D"&(MATCH(16,'4℃其他'!$AA$5:$AA$302,0)+4),INDEX('4℃其他'!$D$5:$D$302,MATCH(16,'4℃其他'!$AA$5:$AA$302,0)))) -> 香菇雞燉湯 | F37: =IF(16>MAX(冷凍品!$Z$5:$Z$304),"",HYPERLINK("#'冷凍品'!C"&(MATCH(16,冷凍品!$Z$5:$Z$304,0)+4),INDEX(冷凍品!$C$5:$C$304,MATCH(16,冷凍品!$Z$5:$Z$304,0))))
B38: =IF(17>MAX('18℃'!$Z$5:$Z$304),"",HYPERLINK("#'18℃'!C"&(MATCH(17,'18℃'!$Z$5:$Z$304,0)+4),INDEX('18℃'!$C$5:$C$304,MATCH(17,'18℃'!$Z$5:$Z$304,0)))) | C38: =IF(17>MAX('4℃飯'!$AA$5:$AA$302),"",HYPERLINK("#'4℃飯'!D"&(MATCH(17,'4℃飯'!$AA$5:$AA$302,0)+4),INDEX('4℃飯'!$D$5:$D$302,MATCH(17,'4℃飯'!$AA$5:$AA$302,0)))) -> 爆炒雞丁飯 | D38: =IF(17>MAX('4℃麵'!$AA$5:$AA$305),"",HYPERLINK("#'4℃麵'!D"&(MATCH(17,'4℃麵'!$AA$5:$AA$305,0)+4),INDEX('4℃麵'!$D$5:$D$305,MATCH(17,'4℃麵'!$AA$5:$AA$305,0)))) | E38: =IF(17>MAX('4℃其他'!$AA$5:$AA$302),"",HYPERLINK("#'4℃其他'!D"&(MATCH(17,'4℃其他'!$AA$5:$AA$302,0)+4),INDEX('4℃其他'!$D$5:$D$302,MATCH(17,'4℃其他'!$AA$5:$AA$302,0)))) -> 火腿起司蛋三明治 | F38: =IF(17>MAX(冷凍品!$Z$5:$Z$304),"",HYPERLINK("#'冷凍品'!C"&(MATCH(17,冷凍品!$Z$5:$Z$304,0)+4),INDEX(冷凍品!$C$5:$C$304,MATCH(17,冷凍品!$Z$5:$Z$304,0))))
B39: =IF(18>MAX('18℃'!$Z$5:$Z$304),"",HYPERLINK("#'18℃'!C"&(MATCH(18,'18℃'!$Z$5:$Z$304,0)+4),INDEX('18℃'!$C$5:$C$304,MATCH(18,'18℃'!$Z$5:$Z$304,0)))) | C39: =IF(18>MAX('4℃飯'!$AA$5:$AA$302),"",HYPERLINK("#'4℃飯'!D"&(MATCH(18,'4℃飯'!$AA$5:$AA$302,0)+4),INDEX('4℃飯'!$D$5:$D$302,MATCH(18,'4℃飯'!$AA$5:$AA$302,0)))) -> 泰式檸檬魚飯 | D39: =IF(18>MAX('4℃麵'!$AA$5:$AA$305),"",HYPERLINK("#'4℃麵'!D"&(MATCH(18,'4℃麵'!$AA$5:$AA$305,0)+4),INDEX('4℃麵'!$D$5:$D$305,MATCH(18,'4℃麵'!$AA$5:$AA$305,0)))) | E39: =IF(18>MAX('4℃其他'!$AA$5:$AA$302),"",HYPERLINK("#'4℃其他'!D"&(MATCH(18,'4℃其他'!$AA$5:$AA$302,0)+4),INDEX('4℃其他'!$D$5:$D$302,MATCH(18,'4℃其他'!$AA$5:$AA$302,0)))) -> 紐奧良風味烤雞鮮蔬三明治 | F39: =IF(18>MAX(冷凍品!$Z$5:$Z$304),"",HYPERLINK("#'冷凍品'!C"&(MATCH(18,冷凍品!$Z$5:$Z$304,0)+4),INDEX(冷凍品!$C$5:$C$304,MATCH(18,冷凍品!$Z$5:$Z$304,0))))
B40: =IF(19>MAX('18℃'!$Z$5:$Z$304),"",HYPERLINK("#'18℃'!C"&(MATCH(19,'18℃'!$Z$5:$Z$304,0)+4),INDEX('18℃'!$C$5:$C$304,MATCH(19,'18℃'!$Z$5:$Z$304,0)))) | C40: =IF(19>MAX('4℃飯'!$AA$5:$AA$302),"",HYPERLINK("#'4℃飯'!D"&(MATCH(19,'4℃飯'!$AA$5:$AA$302,0)+4),INDEX('4℃飯'!$D$5:$D$302,MATCH(19,'4℃飯'!$AA$5:$AA$302,0)))) -> 香菇雞粥 | D40: =IF(19>MAX('4℃麵'!$AA$5:$AA$305),"",HYPERLINK("#'4℃麵'!D"&(MATCH(19,'4℃麵'!$AA$5:$AA$305,0)+4),INDEX('4℃麵'!$D$5:$D$305,MATCH(19,'4℃麵'!$AA$5:$AA$305,0)))) | E40: =IF(19>MAX('4℃其他'!$AA$5:$AA$302),"",HYPERLINK("#'4℃其他'!D"&(MATCH(19,'4℃其他'!$AA$5:$AA$302,0)+4),INDEX('4℃其他'!$D$5:$D$302,MATCH(19,'4℃其他'!$AA$5:$AA$302,0)))) -> 經典火腿玉米蛋三明治 | F40: =IF(19>MAX(冷凍品!$Z$5:$Z$304),"",HYPERLINK("#'冷凍品'!C"&(MATCH(19,冷凍品!$Z$5:$Z$304,0)+4),INDEX(冷凍品!$C$5:$C$304,MATCH(19,冷凍品!$Z$5:$Z$304,0))))
B41: =IF(20>MAX('18℃'!$Z$5:$Z$304),"",HYPERLINK("#'18℃'!C"&(MATCH(20,'18℃'!$Z$5:$Z$304,0)+4),INDEX('18℃'!$C$5:$C$304,MATCH(20,'18℃'!$Z$5:$Z$304,0)))) | C41: =IF(20>MAX('4℃飯'!$AA$5:$AA$302),"",HYPERLINK("#'4℃飯'!D"&(MATCH(20,'4℃飯'!$AA$5:$AA$302,0)+4),INDEX('4℃飯'!$D$5:$D$302,MATCH(20,'4℃飯'!$AA$5:$AA$302,0)))) -> 柚見極炙烤牛 | D41: =IF(20>MAX('4℃麵'!$AA$5:$AA$305),"",HYPERLINK("#'4℃麵'!D"&(MATCH(20,'4℃麵'!$AA$5:$AA$305,0)+4),INDEX('4℃麵'!$D$5:$D$305,MATCH(20,'4℃麵'!$AA$5:$AA$305,0)))) | E41: =IF(20>MAX('4℃其他'!$AA$5:$AA$302),"",HYPERLINK("#'4℃其他'!D"&(MATCH(20,'4℃其他'!$AA$5:$AA$302,0)+4),INDEX('4℃其他'!$D$5:$D$302,MATCH(20,'4℃其他'!$AA$5:$AA$302,0)))) -> 雞蛋沙拉三明治 | F41: =IF(20>MAX(冷凍品!$Z$5:$Z$304),"",HYPERLINK("#'冷凍品'!C"&(MATCH(20,冷凍品!$Z$5:$Z$304,0)+4),INDEX(冷凍品!$C$5:$C$304,MATCH(20,冷凍品!$Z$5:$Z$304,0))))
B42: =IF(21>MAX('18℃'!$Z$5:$Z$304),"",HYPERLINK("#'18℃'!C"&(MATCH(21,'18℃'!$Z$5:$Z$304,0)+4),INDEX('18℃'!$C$5:$C$304,MATCH(21,'18℃'!$Z$5:$Z$304,0)))) | C42: =IF(21>MAX('4℃飯'!$AA$5:$AA$302),"",HYPERLINK("#'4℃飯'!D"&(MATCH(21,'4℃飯'!$AA$5:$AA$302,0)+4),INDEX('4℃飯'!$D$5:$D$302,MATCH(21,'4℃飯'!$AA$5:$AA$302,0)))) -> 叉燒蛋炒飯 | D42: =IF(21>MAX('4℃麵'!$AA$5:$AA$305),"",HYPERLINK("#'4℃麵'!D"&(MATCH(21,'4℃麵'!$AA$5:$AA$305,0)+4),INDEX('4℃麵'!$D$5:$D$305,MATCH(21,'4℃麵'!$AA$5:$AA$305,0)))) | E42: =IF(21>MAX('4℃其他'!$AA$5:$AA$302),"",HYPERLINK("#'4℃其他'!D"&(MATCH(21,'4℃其他'!$AA$5:$AA$302,0)+4),INDEX('4℃其他'!$D$5:$D$302,MATCH(21,'4℃其他'!$AA$5:$AA$302,0)))) -> 肉鬆火腿三明治(115年) | F42: =IF(21>MAX(冷凍品!$Z$5:$Z$304),"",HYPERLINK("#'冷凍品'!C"&(MATCH(21,冷凍品!$Z$5:$Z$304,0)+4),INDEX(冷凍品!$C$5:$C$304,MATCH(21,冷凍品!$Z$5:$Z$304,0))))
B43: =IF(22>MAX('18℃'!$Z$5:$Z$304),"",HYPERLINK("#'18℃'!C"&(MATCH(22,'18℃'!$Z$5:$Z$304,0)+4),INDEX('18℃'!$C$5:$C$304,MATCH(22,'18℃'!$Z$5:$Z$304,0)))) | C43: =IF(22>MAX('4℃飯'!$AA$5:$AA$302),"",HYPERLINK("#'4℃飯'!D"&(MATCH(22,'4℃飯'!$AA$5:$AA$302,0)+4),INDEX('4℃飯'!$D$5:$D$302,MATCH(22,'4℃飯'!$AA$5:$AA$302,0)))) -> 金沙醬牛豚雙饗飯 | D43: =IF(22>MAX('4℃麵'!$AA$5:$AA$305),"",HYPERLINK("#'4℃麵'!D"&(MATCH(22,'4℃麵'!$AA$5:$AA$305,0)+4),INDEX('4℃麵'!$D$5:$D$305,MATCH(22,'4℃麵'!$AA$5:$AA$305,0)))) | E43: =IF(22>MAX('4℃其他'!$AA$5:$AA$302),"",HYPERLINK("#'4℃其他'!D"&(MATCH(22,'4℃其他'!$AA$5:$AA$302,0)+4),INDEX('4℃其他'!$D$5:$D$302,MATCH(22,'4℃其他'!$AA$5:$AA$302,0)))) -> 醬燒烤雞三明治(115年) | F43: =IF(22>MAX(冷凍品!$Z$5:$Z$304),"",HYPERLINK("#'冷凍品'!C"&(MATCH(22,冷凍品!$Z$5:$Z$304,0)+4),INDEX(冷凍品!$C$5:$C$304,MATCH(22,冷凍品!$Z$5:$Z$304,0))))
...

Sheet 填寫說明
B2: 商品半成品與調理設備應用展開一覽表｜填寫說明
B4: 目的 | C4: 盤點本廠商品之半成品組成，及各半成品應用之熱調理設備，據以掌握設備應用狀態（初步以「應用半成品數」衡量），並透過風險示警提前辨識設備依賴集中與資料缺漏。本檔為單一工廠使用，每廠一檔。
B6: 工作表結構 | C6: 「總覽」可點商品名稱跳至明細；五個溫層分頁填寫半成品與設備。「設備應用統計」自動彙總，僅藍字門檻可調整。
B7: 分頁歸類原則 | C7: 商品依販售溫層與品類歸入對應分頁；同一商品的所有半成品填在同一分頁。分頁內的「商品分類」欄可再填細分品類（如飯糰、壽司、便當、涼麵、甜點等）。
B9: 填寫規則 1 | C9: 填寫字體規範「微軟正黑體」，字體大小「10」號
B10: 填寫規則 2 | C10: 每一列代表「一個商品 × 一項半成品」。同一商品有 3 項半成品即填 3 列，且每列的工廠、商品名稱都要填（勿留空、勿合併儲存格），統計公式才能正確計算。
B11: 填寫規則 3 | C11: 有使用調理設備時，在該設備欄下拉選「V」。完全不經調理時，僅於「無使用調理設備」選「V」，不可同時勾選。
B12: 填寫規則 4 | C12: 單位用量分兩欄：「數值」填數字、「單位」下拉選公克或個。製程率直接填數字（如 92），系統自動顯示為 92%。尚未確認者可先留白，不影響設備統計。
B13: 填寫規則 5 | C13: 每列須填「建檔人員」，作為資料追溯窗口。「備註」請註記指示書編號與版本日期，依各分頁欄名填寫。
B14: 填寫規則 6 | C14: 最右側「系統用」隱藏欄自動計算商品目錄與品項數，請勿貼上數值或手動修改。
B16: 風險示警邏輯 | C16: 門檻可於「設備應用統計」C3:C5 藍字儲存格調整。檢核結果共五種狀態：
B17: ⚠ 資料缺漏（紅） | C17: 半成品已填名稱，但 11 個設備欄與「無使用調理設備」皆未勾選 → 須補填，或確認為免調理並勾選「無使用調理設備」。
B18: ⚠ 勾選矛盾（紅） | C18: 同時勾選「無使用調理設備」與任一設備欄 → 邏輯矛盾，請擇一修正。
... B25: 自動資料檢查 | C25: 以下以已填商品或半成品的資料列檢查。數量按明細列計，同一商品可有多列。
B26: 狀態未填（列） | C26: =SUM(COUNTIFS('4℃飯'!$D$5:$D$302,"<>",'4℃飯'!$A$5:$A$302,""),COUNTIFS('4℃麵'!$D$5:$D$305,"<>",'4℃麵'!$A$5:$A$305,""),COUNTIFS('4℃其他'!$D$5:$D$302,"<>",'4℃其他'!$A$5:$A$302,"")) -> 0
B27: 半成品名稱未填（列） | C27: =SUM(COUNTIFS('18℃'!$C$5:$C$304,"<>",'18℃'!$D$5:$D$304,""),COUNTIFS('4℃飯'!$D$5:$D$302,"<>",'4℃飯'!$E$5:$E$302,""),COUNTIFS('4℃麵'!$D$5:$D$305,"<>",'4℃麵'!$E$5:$E$305,""),COUNTIFS('4℃其他'!$D$5:$D$302,"<>",'4℃其他'!$E$5:$E$302,""),COUNTIFS(冷凍品!$C$5:$C$304,"<>",冷凍品!$D$5:$D$304,"")) -> 0
B28: 設備未勾選（列） | C28: =SUM(COUNTIF('18℃'!$U$5:$U$304,"⚠ 資料缺漏"),COUNTIF('4℃飯'!$V$5:$V$302,"⚠ 資料缺漏"),COUNTIF('4℃麵'!$V$5:$V$305,"⚠ 資料缺漏"),COUNTIF('4℃其他'!$V$5:$V$302,"⚠ 資料缺漏"),COUNTIF(冷凍品!$U$5:$U$304,"⚠ 資料缺漏")) -> 0
B29: 設備勾選矛盾（列） | C29: =SUM(COUNTIF('18℃'!$U$5:$U$304,"⚠ 勾選矛盾"),COUNTIF('4℃飯'!$V$5:$V$302,"⚠ 勾選矛盾"),COUNTIF('4℃麵'!$V$5:$V$305,"⚠ 勾選矛盾"),COUNTIF('4℃其他'!$V$5:$V$302,"⚠ 勾選矛盾"),COUNTIF(冷凍品!$U$5:$U$304,"⚠ 勾選矛盾")) -> 0
B30: 建檔人員未填（列） | C30: =SUM(COUNTIFS('18℃'!$D$5:$D$304,"<>",'18℃'!$X$5:$X$304,""),COUNTIFS('4℃飯'!$E$5:$E$302,"<>",'4℃飯'!$Y$5:$Y$302,""),COUNTIFS('4℃麵'!$E$5:$E$305,"<>",'4℃麵'!$Y$5:$Y$305,""),COUNTIFS('4℃其他'!$E$5:$E$302,"<>",'4℃其他'!$Y$5:$Y$302,""),COUNTIFS(冷凍品!$D$5:$D$304,"<>",冷凍品!$X$5:$X$304,"")) -> 0
B31: 工廠不符或未填（列） | C31: =SUM(COUNTIFS('18℃'!$D$5:$D$304,"<>",'18℃'!$A$5:$A$304,"<>新豐"),COUNTIFS('4℃飯'!$E$5:$E$302,"<>",'4℃飯'!$B$5:$B$302,"<>新豐"),COUNTIFS('4℃麵'!$E$5:$E$305,"<>",'4℃麵'!$B$5:$B$305,"<>新豐"),COUNTIFS('4℃其他'!$E$5:$E$302,"<>",'4℃其他'!$B$5:$B$302,"<>新豐"),COUNTIFS(冷凍品!$D$5:$D$304,"<>",冷凍品!$A$5:$A$304,"<>新豐")) -> 0
B32: 用量有值但單位未填（列） | C32: =SUM(COUNTIFS('18℃'!$D$5:$D$304,"<>",'18℃'!$E$5:$E$304,"<>",'18℃'!$F$5:$F$304,""),COUNTIFS('4℃飯'!$E$5:$E$302,"<>",'4℃飯'!$F$5:$F$302,"<>",'4℃飯'!$G$5:$G$302,""),COUNTIFS('4℃麵'!$E$5:$E$305,"<>",'4℃麵'!$F$5:$F$305,"<>",'4℃麵'!$G$5:$G$305,""),COUNTIFS('4℃其他'!$E$5:$E$302,"<>",'4℃其他'!$F$5:$F$302,"<>",'4℃其他'!$G$5:$G$302,""),COUNTIFS(冷凍品!$D$5:$D$304,"<>",冷凍品!$E$5:$E$304,"<>",冷凍品!$F$5:$F$304,"")) -> 0
B34: 狀態判定基準 | C34: 本次已確認狀態依2026/10/14訂單與逐項確認結果。未上市商品保留待上架。後續更新需先確認訂單日期。
B35: 篩選與色彩 | C35: 狀態欄可篩選架上、下架、待上架。橘色表示狀態漏填或同商品不一致；淡黃表示建檔人員或單位待補。
B36: 批次更新同一商品 | C36: 先用商品名稱篩選，選取該商品可見的狀態儲存格，按 Alt+; 僅選可見儲存格，輸入狀態後按 Ctrl+Enter。
B37: 新增商品或半成品 | C37: 請在現有表格範圍內插入整列，再複製相鄰整列的格式、公式與選單，清除輸入資料後填寫新內容。
B38: 保留未確認內容 | C38: 未有依據的建檔人員、用量與單位不代填。未設狀態欄的分頁不納入狀態漏填檢查，既有「-」保留待確認。

Sheet 18℃
A1: 商品半成品與調理設備應用展開一覽表｜18℃
A2: 商品資訊 | H2: 熱調理區（使用者填「V」；免調理者勾最右欄） | T2: 自動計算與風險檢核（勿手動修改） | W2: 建檔資訊（手填）
A3: 工廠 | B3: 商品分類 (細分品類) | C3: 商品名稱 | D3: 半成品名稱 | E3: 單位用量 | G3: 製程率 (填數字) | H3: 炊飯 | I3: 煮麵 | J3: 烤箱 | K3: 炙燒 | L3: 蒸箱 | M3: 油炸機 | N3: 二重釜 | O3: 平釜 (日) | P3: 平釜 (台) | Q3: 蛋皮機 | R3: 壓力鍋 | S3: 無使用 調理設備 | T3: 使用 設備數 | U3: 檢核結果 | V3: 風險說明 | W3: 備註 (指示書編號/版本) | X3: 建檔人員 | Y3: 系統用Y | Z3: 系統用Z
E4: 數值 | F4: 單位
T5: =IF($D5="","",COUNTIF($H5:$R5,"V")) | U5: =IF($D5="","",IF(AND($S5="V",$T5>0),"⚠ 勾選矛盾",IF($S5="V","○ 免調理",IF($T5=0,"⚠ 資料缺漏",IF($T5=1,"▲ 單一設備依賴","OK"))))) | V5: =IF($D5="","",IF(AND($S5="V",$T5>0),"「無使用調理設備」不可與設備欄同時勾選，請擇一修正",IF($S5="V","免調理半成品（外購/僅切配等），不列入設備風險評估",IF($T5=0,"未勾選任何設備，請補填或勾選「無使用調理設備」",IF($T5=1,"僅依賴1台設備，須確認故障/排修時之備援製程","無異常"))))) | Y5: =IF($C5="",0,IF(COUNTIF($C$5:$C5,$C5)=1,1,0)) -> 0 | Z5: =IF(Y5=1,SUM($Y$5:$Y5),"")
T6: =IF($D6="","",COUNTIF($H6:$R6,"V")) | U6: =IF($D6="","",IF(AND($S6="V",$T6>0),"⚠ 勾選矛盾",IF($S6="V","○ 免調理",IF($T6=0,"⚠ 資料缺漏",IF($T6=1,"▲ 單一設備依賴","OK"))))) | V6: =IF($D6="","",IF(AND($S6="V",$T6>0),"「無使用調理設備」不可與設備欄同時勾選，請擇一修正",IF($S6="V","免調理半成品（外購/僅切配等），不列入設備風險評估",IF($T6=0,"未勾選任何設備，請補填或勾選「無使用調理設備」",IF($T6=1,"僅依賴1台設備，須確認故障/排修時之備援製程","無異常"))))) | Y6: =IF($C6="",0,IF(COUNTIF($C$5:$C6,$C6)=1,1,0)) -> 0 | Z6: =IF(Y6=1,SUM($Y$5:$Y6),"")
T7: =IF($D7="","",COUNTIF($H7:$R7,"V")) | U7: =IF($D7="","",IF(AND($S7="V",$T7>0),"⚠ 勾選矛盾",IF($S7="V","○ 免調理",IF($T7=0,"⚠ 資料缺漏",IF($T7=1,"▲ 單一設備依賴","OK"))))) | V7: =IF($D7="","",IF(AND($S7="V",$T7>0),"「無使用調理設備」不可與設備欄同時勾選，請擇一修正",IF($S7="V","免調理半成品（外購/僅切配等），不列入設備風險評估",IF($T7=0,"未勾選任何設備，請補填或勾選「無使用調理設備」",IF($T7=1,"僅依賴1台設備，須確認故障/排修時之備援製程","無異常"))))) | Y7: =IF($C7="",0,IF(COUNTIF($C$5:$C7,$C7)=1,1,0)) -> 0 | Z7: =IF(Y7=1,SUM($Y$5:$Y7),"")
T8: =IF($D8="","",COUNTIF($H8:$R8,"V")) | U8: =IF($D8="","",IF(AND($S8="V",$T8>0),"⚠ 勾選矛盾",IF($S8="V","○ 免調理",IF($T8=0,"⚠ 資料缺漏",IF($T8=1,"▲ 單一設備依賴","OK"))))) | V8: =IF($D8="","",IF(AND($S8="V",$T8>0),"「無使用調理設備」不可與設備欄同時勾選，請擇一修正",IF($S8="V","免調理半成品（外購/僅切配等），不列入設備風險評估",IF($T8=0,"未勾選任何設備，請補填或勾選「無使用調理設備」",IF($T8=1,"僅依賴1台設備，須確認故障/排修時之備援製程","無異常"))))) | Y8: =IF($C8="",0,IF(COUNTIF($C$5:$C8,$C8)=1,1,0)) -> 0 | Z8: =IF(Y8=1,SUM($Y$5:$Y8),"")
T9: =IF($D9="","",COUNTIF($H9:$R9,"V")) | U9: =IF($D9="","",IF(AND($S9="V",$T9>0),"⚠ 勾選矛盾",IF($S9="V","○ 免調理",IF($T9=0,"⚠ 資料缺漏",IF($T9=1,"▲ 單一設備依賴","OK"))))) | V9: =IF($D9="","",IF(AND($S9="V",$T9>0),"「無使用調理設備」不可與設備欄同時勾選，請擇一修正",IF($S9="V","免調理半成品（外購/僅切配等），不列入設備風險評估",IF($T9=0,"未勾選任何設備，請補填或勾選「無使用調理設備」",IF($T9=1,"僅依賴1台設備，須確認故障/排修時之備援製程","無異常"))))) | Y9: =IF($C9="",0,IF(COUNTIF($C$5:$C9,$C9)=1,1,0)) -> 0 | Z9: =IF(Y9=1,SUM($Y$5:$Y9),"")
T10: =IF($D10="","",COUNTIF($H10:$R10,"V")) | U10: =IF($D10="","",IF(AND($S10="V",$T10>0),"⚠ 勾選矛盾",IF($S10="V","○ 免調理",IF($T10=0,"⚠ 資料缺漏",IF($T10=1,"▲ 單一設備依賴","OK"))))) | V10: =IF($D10="","",IF(AND($S10="V",$T10>0),"「無使用調理設備」不可與設備欄同時勾選，請擇一修正",IF($S10="V","免調理半成品（外購/僅切配等），不列入設備風險評估",IF($T10=0,"未勾選任何設備，請補填或勾選「無使用調理設備」",IF($T10=1,"僅依賴1台設備，須確認故障/排修時之備援製程","無異常"))))) | Y10: =IF($C10="",0,IF(COUNTIF($C$5:$C10,$C10)=1,1,0)) -> 0 | Z10: =IF(Y10=1,SUM($Y$5:$Y10),"")
T11: =IF($D11="","",COUNTIF($H11:$R11,"V")) | U11: =IF($D11="","",IF(AND($S11="V",$T11>0),"⚠ 勾選矛盾",IF($S11="V","○ 免調理",IF($T11=0,"⚠ 資料缺漏",IF($T11=1,"▲ 單一設備依賴","OK"))))) | V11: =IF($D11="","",IF(AND($S11="V",$T11>0),"「無使用調理設備」不可與設備欄同時勾選，請擇一修正",IF($S11="V","免調理半成品（外購/僅切配等），不列入設備風險評估",IF($T11=0,"未勾選任何設備，請補填或勾選「無使用調理設備」",IF($T11=1,"僅依賴1台設備，須確認故障/排修時之備援製程","無異常"))))) | Y11: =IF($C11="",0,IF(COUNTIF($C$5:$C11,$C11)=1,1,0)) -> 0 | Z11: =IF(Y11=1,SUM($Y$5:$Y11),"")
T12: =IF($D12="","",COUNTIF($H12:$R12,"V")) | U12: =IF($D12="","",IF(AND($S12="V",$T12>0),"⚠ 勾選矛盾",IF($S12="V","○ 免調理",IF($T12=0,"⚠ 資料缺漏",IF($T12=1,"▲ 單一設備依賴","OK"))))) | V12: =IF($D12="","",IF(AND($S12="V",$T12>0),"「無使用調理設備」不可與設備欄同時勾選，請擇一修正",IF($S12="V","免調理半成品（外購/僅切配等），不列入設備風險評估",IF($T12=0,"未勾選任何設備，請補填或勾選「無使用調理設備」",IF($T12=1,"僅依賴1台設備，須確認故障/排修時之備援製程","無異常"))))) | Y12: =IF($C12="",0,IF(COUNTIF($C$5:$C12,$C12)=1,1,0)) -> 0 | Z12: =IF(Y12=1,SUM($Y$5:$Y12),"")
T13: =IF($D13="","",COUNTIF($H13:$R13,"V")) | U13: =IF($D13="","",IF(AND($S13="V",$T13>0),"⚠ 勾選矛盾",IF($S13="V","○ 免調理",IF($T13=0,"⚠ 資料缺漏",IF($T13=1,"▲ 單一設備依賴","OK"))))) | V13: =IF($D13="","",IF(AND($S13="V",$T13>0),"「無使用調理設備」不可與設備欄同時勾選，請擇一修正",IF($S13="V","免調理半成品（外購/僅切配等），不列入設備風險評估",IF($T13=0,"未勾選任何設備，請補填或勾選「無使用調理設備」",IF($T13=1,"僅依賴1台設備，須確認故障/排修時之備援製程","無異常"))))) | Y13: =IF($C13="",0,IF(COUNTIF($C$5:$C13,$C13)=1,1,0)) -> 0 | Z13: =IF(Y13=1,SUM($Y$5:$Y13),"")
T14: =IF($D14="","",COUNTIF($H14:$R14,"V")) | U14: =IF($D14="","",IF(AND($S14="V",$T14>0),"⚠ 勾選矛盾",IF($S14="V","○ 免調理",IF($T14=0,"⚠ 資料缺漏",IF($T14=1,"▲ 單一設備依賴","OK"))))) | V14: =IF($D14="","",IF(AND($S14="V",$T14>0),"「無使用調理設備」不可與設備欄同時勾選，請擇一修正",IF($S14="V","免調理半成品（外購/僅切配等），不列入設備風險評估",IF($T14=0,"未勾選任何設備，請補填或勾選「無使用調理設備」",IF($T14=1,"僅依賴1台設備，須確認故障/排修時之備援製程","無異常"))))) | Y14: =IF($C14="",0,IF(COUNTIF($C$5:$C14,$C14)=1,1,0)) -> 0 | Z14: =IF(Y14=1,SUM($Y$5:$Y14),"")
T15: =IF($D15="","",COUNTIF($H15:$R15,"V")) | U15: =IF($D15="","",IF(AND($S15="V",$T15>0),"⚠ 勾選矛盾",IF($S15="V","○ 免調理",IF($T15=0,"⚠ 資料缺漏",IF($T15=1,"▲ 單一設備依賴","OK"))))) | V15: =IF($D15="","",IF(AND($S15="V",$T15>0),"「無使用調理設備」不可與設備欄同時勾選，請擇一修正",IF($S15="V","免調理半成品（外購/僅切配等），不列入設備風險評估",IF($T15=0,"未勾選任何設備，請補填或勾選「無使用調理設備」",IF($T15=1,"僅依賴1台設備，須確認故障/排修時之備援製程","無異常"))))) | Y15: =IF($C15="",0,IF(COUNTIF($C$5:$C15,$C15)=1,1,0)) -> 0 | Z15: =IF(Y15=1,SUM($Y$5:$Y15),"")
T16: =IF($D16="","",COUNTIF($H16:$R16,"V")) | U16: =IF($D16="","",IF(AND($S16="V",$T16>0),"⚠ 勾選矛盾",IF($S16="V","○ 免調理",IF($T16=0,"⚠ 資料缺漏",IF($T16=1,"▲ 單一設備依賴","OK"))))) | V16: =IF($D16="","",IF(AND($S16="V",$T16>0),"「無使用調理設備」不可與設備欄同時勾選，請擇一修正",IF($S16="V","免調理半成品（外購/僅切配等），不列入設備風險評估",IF($T16=0,"未勾選任何設備，請補填或勾選「無使用調理設備」",IF($T16=1,"僅依賴1台設備，須確認故障/排修時之備援製程","無異常"))))) | Y16: =IF($C16="",0,IF(COUNTIF($C$5:$C16,$C16)=1,1,0)) -> 0 | Z16: =IF(Y16=1,SUM($Y$5:$Y16),"")
... T304: =IF($D304="","",COUNTIF($H304:$R304,"V")) | U304: =IF($D304="","",IF(AND($S304="V",$T304>0),"⚠ 勾選矛盾",IF($S304="V","○ 免調理",IF($T304=0,"⚠ 資料缺漏",IF($T304=1,"▲ 單一設備依賴","OK"))))) | V304: =IF($D304="","",IF(AND($S304="V",$T304>0),"「無使用調理設備」不可與設備欄同時勾選，請擇一修正",IF($S304="V","免調理半成品（外購/僅切配等），不列入設備風險評估",IF($T304=0,"未勾選任何設備，請補填或勾選「無使用調理設備」",IF($T304=1,"僅依賴1台設備，須確認故障/排修時之備援製程","無異常"))))) | Y304: =IF($C304="",0,IF(COUNTIF($C$5:$C304,$C304)=1,1,0)) -> 0 | Z304: =IF(Y304=1,SUM($Y$5:$Y304),"")

Sheet 4℃飯
B1: 商品半成品與調理設備應用展開一覽表｜4℃飯
A2: 商品資訊 | I2: 熱調理區（使用者填「V」；免調理者勾最右欄） | U2: 自動計算與風險檢核（勿手動修改） | X2: 建檔資訊（手填）
A3: 狀態 | B3: 工廠 | C3: 商品分類 (細分品類) | D3: 商品名稱 | E3: 半成品名稱 | F3: 單位用量 | H3: 製程率 (填數字) | I3: 炊飯 | J3: 煮麵 | K3: 烤箱 | L3: 炙燒 | M3: 蒸箱 | N3: 油炸機 | O3: 二重釜 | P3: 平釜 (日) | Q3: 平釜 (台) | R3: 蛋皮機 | S3: 壓力鍋 | T3: 無使用 調理設備 | U3: 使用 設備數 | V3: 檢核結果 | W3: 風險說明 | X3: 備註 (指示書編號/版本) | Y3: 建檔人員 | Z3: 系統用Y | AA3: 系統用Z
F4: 數值 | G4: 單位
A5: 架上 | B5: 新豐 | C5: 主食 | D5: 鐵板滑蛋炸豬排丼 | E5: 冷藏便當飯(109年) | F5: 246 | G5: 公克 | H5: 85 | I5: V | U5: =IF($E5="","",COUNTIF($I5:$S5,"V")) -> 1 | V5: =IF($E5="","",IF(AND($T5="V",$U5>0),"⚠ 勾選矛盾",IF($T5="V","○ 免調理",IF($U5=0,"⚠ 資料缺漏",IF($U5=1,"▲ 單一設備依賴","OK"))))) -> ▲ 單一設備依賴 | W5: =IF($E5="","",IF(AND($T5="V",$U5>0),"「無使用調理設備」不可與設備欄同時勾選，請擇一修正",IF($T5="V","免調理半成品（外購/僅切配等），不列入設備風險評估",IF($U5=0,"未勾選任何設備，請補填或勾選「無使用調理設備」",IF($U5=1,"僅依賴1台設備，須確認故障/排修時之備援製程","無異常"))))) -> 僅依賴1台設備，須確認故障/排修時之備援製程 | X5: 1120718鐵板滑蛋炸豬排丼.確認版(11)-G06-食研所製成率校正、封膜設計變更 | Y5: 王安淇 | Z5: =IF($D5="",0,IF(COUNTIF($D$5:$D5,$D5)=1,1,0)) -> 1 | AA5: =IF(Z5=1,SUM($Z$5:$Z5),"") -> 1
A6: 架上 | B6: 新豐 | C6: 主食 | D6: 鐵板滑蛋炸豬排丼 | E6: 丼飯-柴魚湯凍(111年) | F6: 65 | G6: 公克 | H6: 65 | O6: V | U6: =IF($E6="","",COUNTIF($I6:$S6,"V")) -> 1 | V6: =IF($E6="","",IF(AND($T6="V",$U6>0),"⚠ 勾選矛盾",IF($T6="V","○ 免調理",IF($U6=0,"⚠ 資料缺漏",IF($U6=1,"▲ 單一設備依賴","OK"))))) -> ▲ 單一設備依賴 | W6: =IF($E6="","",IF(AND($T6="V",$U6>0),"「無使用調理設備」不可與設備欄同時勾選，請擇一修正",IF($T6="V","免調理半成品（外購/僅切配等），不列入設備風險評估",IF($U6=0,"未勾選任何設備，請補填或勾選「無使用調理設備」",IF($U6=1,"僅依賴1台設備，須確認故障/排修時之備援製程","無異常"))))) -> 僅依賴1台設備，須確認故障/排修時之備援製程 | X6: 1120718鐵板滑蛋炸豬排丼.確認版(11)-G06-食研所製成率校正、封膜設計變更 | Y6: 王安淇 | Z6: =IF($D6="",0,IF(COUNTIF($D$5:$D6,$D6)=1,1,0)) -> 0 | AA6: =IF(Z6=1,SUM($Z$5:$Z6),"")
A7: 架上 | B7: 新豐 | C7: 主食 | D7: 鐵板滑蛋炸豬排丼 | E7: 烤日式豬排洋蔥蛋(112年) | F7: 1 | G7: 個 | H7: 100 | K7: V | N7: V | U7: =IF($E7="","",COUNTIF($I7:$S7,"V")) -> 2 | V7: =IF($E7="","",IF(AND($T7="V",$U7>0),"⚠ 勾選矛盾",IF($T7="V","○ 免調理",IF($U7=0,"⚠ 資料缺漏",IF($U7=1,"▲ 單一設備依賴","OK"))))) -> OK | W7: =IF($E7="","",IF(AND($T7="V",$U7>0),"「無使用調理設備」不可與設備欄同時勾選，請擇一修正",IF($T7="V","免調理半成品（外購/僅切配等），不列入設備風險評估",IF($U7=0,"未勾選任何設備，請補填或勾選「無使用調理設備」",IF($U7=1,"僅依賴1台設備，須確認故障/排修時之備援製程","無異常"))))) -> 無異常 | X7: 1120718鐵板滑蛋炸豬排丼.確認版(11)-G06-食研所製成率校正、封膜設計變更 | Y7: 王安淇 | Z7: =IF($D7="",0,IF(COUNTIF($D$5:$D7,$D7)=1,1,0)) -> 0 | AA7: =IF(Z7=1,SUM($Z$5:$Z7),"")
A8: 架上 | B8: 新豐 | C8: 主食 | D8: 鐵板滑蛋炸豬排丼 | E8: 丼飯-滑蛋(112年) | F8: 75 | G8: 公克 | H8: 60.2 | O8: V | U8: =IF($E8="","",COUNTIF($I8:$S8,"V")) -> 1 | V8: =IF($E8="","",IF(AND($T8="V",$U8>0),"⚠ 勾選矛盾",IF($T8="V","○ 免調理",IF($U8=0,"⚠ 資料缺漏",IF($U8=1,"▲ 單一設備依賴","OK"))))) -> ▲ 單一設備依賴 | W8: =IF($E8="","",IF(AND($T8="V",$U8>0),"「無使用調理設備」不可與設備欄同時勾選，請擇一修正",IF($T8="V","免調理半成品（外購/僅切配等），不列入設備風險評估",IF($U8=0,"未勾選任何設備，請補填或勾選「無使用調理設備」",IF($U8=1,"僅依賴1台設備，須確認故障/排修時之備援製程","無異常"))))) -> 僅依賴1台設備，須確認故障/排修時之備援製程 | X8: 1120718鐵板滑蛋炸豬排丼.確認版(11)-G06-食研所製成率校正、封膜設計變更 | Y8: 王安淇 | Z8: =IF($D8="",0,IF(COUNTIF($D$5:$D8,$D8)=1,1,0)) -> 0 | AA8: =IF(Z8=1,SUM($Z$5:$Z8),"")
A9: 架上 | B9: 新豐 | C9: 主食 | D9: 鐵板滑蛋炸豬排丼 | E9: 清洗蔥花 | F9: 2 | G9: 公克 | H9: 70 | T9: V | U9: =IF($E9="","",COUNTIF($I9:$S9,"V")) -> 0 | V9: =IF($E9="","",IF(AND($T9="V",$U9>0),"⚠ 勾選矛盾",IF($T9="V","○ 免調理",IF($U9=0,"⚠ 資料缺漏",IF($U9=1,"▲ 單一設備依賴","OK"))))) -> ○ 免調理 | W9: =IF($E9="","",IF(AND($T9="V",$U9>0),"「無使用調理設備」不可與設備欄同時勾選，請擇一修正",IF($T9="V","免調理半成品（外購/僅切配等），不列入設備風險評估",IF($U9=0,"未勾選任何設備，請補填或勾選「無使用調理設備」",IF($U9=1,"僅依賴1台設備，須確認故障/排修時之備援製程","無異常"))))) -> 免調理半成品（外購/僅切配等），不列入設備風險評估 | X9: 1120718鐵板滑蛋炸豬排丼.確認版(11)-G06-食研所製成率校正、封膜設計變更 | Y9: 王安淇 | Z9: =IF($D9="",0,IF(COUNTIF($D$5:$D9,$D9)=1,1,0)) -> 0 | AA9: =IF(Z9=1,SUM($Z$5:$Z9),"")
A10: 架上 | B10: 新豐 | C10: 主食 | D10: 鐵板滑蛋炸豬排丼 | E10: 殺菌七味唐辛子(B0702AW6161) | F10: 0.1 | G10: 公克 | H10: 100 | T10: V | U10: =IF($E10="","",COUNTIF($I10:$S10,"V")) -> 0 | V10: =IF($E10="","",IF(AND($T10="V",$U10>0),"⚠ 勾選矛盾",IF($T10="V","○ 免調理",IF($U10=0,"⚠ 資料缺漏",IF($U10=1,"▲ 單一設備依賴","OK"))))) -> ○ 免調理 | W10: =IF($E10="","",IF(AND($T10="V",$U10>0),"「無使用調理設備」不可與設備欄同時勾選，請擇一修正",IF($T10="V","免調理半成品（外購/僅切配等），不列入設備風險評估",IF($U10=0,"未勾選任何設備，請補填或勾選「無使用調理設備」",IF($U10=1,"僅依賴1台設備，須確認故障/排修時之備援製程","無異常"))))) -> 免調理半成品（外購/僅切配等），不列入設備風險評估 | X10: 1120718鐵板滑蛋炸豬排丼.確認版(11)-G06-食研所製成率校正、封膜設計變更 | Y10: 王安淇 | Z10: =IF($D10="",0,IF(COUNTIF($D$5:$D10,$D10)=1,1,0)) -> 0 | AA10: =IF(Z10=1,SUM($Z$5:$Z10),"")
A11: 架上 | B11: 新豐 | C11: 主食 | D11: 炙烤醬香燒豚飯 | E11: 新低溫飯 | F11: 240 | G11: 公克 | H11: 85 | I11: V | U11: =IF($E11="","",COUNTIF($I11:$S11,"V")) -> 1 | V11: =IF($E11="","",IF(AND($T11="V",$U11>0),"⚠ 勾選矛盾",IF($T11="V","○ 免調理",IF($U11=0,"⚠ 資料缺漏",IF($U11=1,"▲ 單一設備依賴","OK"))))) -> ▲ 單一設備依賴 | W11: =IF($E11="","",IF(AND($T11="V",$U11>0),"「無使用調理設備」不可與設備欄同時勾選，請擇一修正",IF($T11="V","免調理半成品（外購/僅切配等），不列入設備風險評估",IF($U11=0,"未勾選任何設備，請補填或勾選「無使用調理設備」",IF($U11=1,"僅依賴1台設備，須確認故障/排修時之備援製程","無異常"))))) -> 僅依賴1台設備，須確認故障/排修時之備援製程 | X11: 1150617炙烤醬香燒豚飯.確認版(1) | Y11: 王安淇 | Z11: =IF($D11="",0,IF(COUNTIF($D$5:$D11,$D11)=1,1,0)) -> 1 | AA11: =IF(Z11=1,SUM($Z$5:$Z11),"") -> 2
A12: 架上 | B12: 新豐 | C12: 主食 | D12: 炙烤醬香燒豚飯 | E12: 蒜味燒豚醬(115年) | F12: 12 | G12: 公克 | H12: 61.1 | O12: V | U12: =IF($E12="","",COUNTIF($I12:$S12,"V")) -> 1 | V12: =IF($E12="","",IF(AND($T12="V",$U12>0),"⚠ 勾選矛盾",IF($T12="V","○ 免調理",IF($U12=0,"⚠ 資料缺漏",IF($U12=1,"▲ 單一設備依賴","OK"))))) -> ▲ 單一設備依賴 | W12: =IF($E12="","",IF(AND($T12="V",$U12>0),"「無使用調理設備」不可與設備欄同時勾選，請擇一修正",IF($T12="V","免調理半成品（外購/僅切配等），不列入設備風險評估",IF($U12=0,"未勾選任何設備，請補填或勾選「無使用調理設備」",IF($U12=1,"僅依賴1台設備，須確認故障/排修時之備援製程","無異常"))))) -> 僅依賴1台設備，須確認故障/排修時之備援製程 | X12: 1150617炙烤醬香燒豚飯.確認版(1) | Y12: 王安淇 | Z12: =IF($D12="",0,IF(COUNTIF($D$5:$D12,$D12)=1,1,0)) -> 0 | AA12: =IF(Z12=1,SUM($Z$5:$Z12),"")
A13: 架上 | B13: 新豐 | C13: 主食 | D13: 炙烤醬香燒豚飯 | E13: 切-炙燒炭火燒肉片 | F13: 37 | G13: 公克 | H13: 95 | K13: V | L13: V | U13: =IF($E13="","",COUNTIF($I13:$S13,"V")) -> 2 | V13: =IF($E13="","",IF(AND($T13="V",$U13>0),"⚠ 勾選矛盾",IF($T13="V","○ 免調理",IF($U13=0,"⚠ 資料缺漏",IF($U13=1,"▲ 單一設備依賴","OK"))))) -> OK | W13: =IF($E13="","",IF(AND($T13="V",$U13>0),"「無使用調理設備」不可與設備欄同時勾選，請擇一修正",IF($T13="V","免調理半成品（外購/僅切配等），不列入設備風險評估",IF($U13=0,"未勾選任何設備，請補填或勾選「無使用調理設備」",IF($U13=1,"僅依賴1台設備，須確認故障/排修時之備援製程","無異常"))))) -> 無異常 | X13: 1150617炙烤醬香燒豚飯.確認版(1) | Y13: 王安淇 | Z13: =IF($D13="",0,IF(COUNTIF($D$5:$D13,$D13)=1,1,0)) -> 0 | AA13: =IF(Z13=1,SUM($Z$5:$Z13),"")
A14: 架上 | B14: 新豐 | C14: 主食 | D14: 炙烤醬香燒豚飯 | E14: 甘口燒肉醬 | F14: 30 | G14: 公克 | H14: 61.8 | O14: V | U14: =IF($E14="","",COUNTIF($I14:$S14,"V")) -> 1 | V14: =IF($E14="","",IF(AND($T14="V",$U14>0),"⚠ 勾選矛盾",IF($T14="V","○ 免調理",IF($U14=0,"⚠ 資料缺漏",IF($U14=1,"▲ 單一設備依賴","OK"))))) -> ▲ 單一設備依賴 | W14: =IF($E14="","",IF(AND($T14="V",$U14>0),"「無使用調理設備」不可與設備欄同時勾選，請擇一修正",IF($T14="V","免調理半成品（外購/僅切配等），不列入設備風險評估",IF($U14=0,"未勾選任何設備，請補填或勾選「無使用調理設備」",IF($U14=1,"僅依賴1台設備，須確認故障/排修時之備援製程","無異常"))))) -> 僅依賴1台設備，須確認故障/排修時之備援製程 | X14: 1150617炙烤醬香燒豚飯.確認版(1) | Y14: 王安淇 | Z14: =IF($D14="",0,IF(COUNTIF($D$5:$D14,$D14)=1,1,0)) -> 0 | AA14: =IF(Z14=1,SUM($Z$5:$Z14),"")
A15: 架上 | B15: 新豐 | C15: 主食 | D15: 炙烤醬香燒豚飯 | E15: 瀝汁-韓國首爾泡菜 | F15: 20 | G15: 公克 | H15: 80 | T15: V | U15: =IF($E15="","",COUNTIF($I15:$S15,"V")) -> 0 | V15: =IF($E15="","",IF(AND($T15="V",$U15>0),"⚠ 勾選矛盾",IF($T15="V","○ 免調理",IF($U15=0,"⚠ 資料缺漏",IF($U15=1,"▲ 單一設備依賴","OK"))))) -> ○ 免調理 | W15: =IF($E15="","",IF(AND($T15="V",$U15>0),"「無使用調理設備」不可與設備欄同時勾選，請擇一修正",IF($T15="V","免調理半成品（外購/僅切配等），不列入設備風險評估",IF($U15=0,"未勾選任何設備，請補填或勾選「無使用調理設備」",IF($U15=1,"僅依賴1台設備，須確認故障/排修時之備援製程","無異常"))))) -> 免調理半成品（外購/僅切配等），不列入設備風險評估 | X15: 1150617炙烤醬香燒豚飯.確認版(1) | Y15: 王安淇 | Z15: =IF($D15="",0,IF(COUNTIF($D$5:$D15,$D15)=1,1,0)) -> 0 | AA15: =IF(Z15=1,SUM($Z$5:$Z15),"")
A16: 架上 | B16: 新豐 | C16: 主食 | D16: 炙烤醬香燒豚飯 | E16: 蒜蒜醬 | F16: 5 | G16: 公克 | H16: 67.3 | O16: V | U16: =IF($E16="","",COUNTIF($I16:$S16,"V")) -> 1 | V16: =IF($E16="","",IF(AND($T16="V",$U16>0),"⚠ 勾選矛盾",IF($T16="V","○ 免調理",IF($U16=0,"⚠ 資料缺漏",IF($U16=1,"▲ 單一設備依賴","OK"))))) -> ▲ 單一設備依賴 | W16: =IF($E16="","",IF(AND($T16="V",$U16>0),"「無使用調理設備」不可與設備欄同時勾選，請擇一修正",IF($T16="V","免調理半成品（外購/僅切配等），不列入設備風險評估",IF($U16=0,"未勾選任何設備，請補填或勾選「無使用調理設備」",IF($U16=1,"僅依賴1台設備，須確認故障/排修時之備援製程","無異常"))))) -> 僅依賴1台設備，須確認故障/排修時之備援製程 | X16: 1150617炙烤醬香燒豚飯.確認版(1) | Y16: 王安淇 | Z16: =IF($D16="",0,IF(COUNTIF($D$5:$D16,$D16)=1,1,0)) -> 0 | AA16: =IF(Z16=1,SUM($Z$5:$Z16),"")
A17: 架上 | B17: 新豐 | C17: 主食 | D17: 炙烤醬香燒豚飯 | E17: 金香炒麻仁(熟) | F17: 0.3 | G17: 公克 | H17: 70 | T17: V | U17: =IF($E17="","",COUNTIF($I17:$S17,"V")) -> 0 | V17: =IF($E17="","",IF(AND($T17="V",$U17>0),"⚠ 勾選矛盾",IF($T17="V","○ 免調理",IF($U17=0,"⚠ 資料缺漏",IF($U17=1,"▲ 單一設備依賴","OK"))))) -> ○ 免調理 | W17: =IF($E17="","",IF(AND($T17="V",$U17>0),"「無使用調理設備」不可與設備欄同時勾選，請擇一修正",IF($T17="V","免調理半成品（外購/僅切配等），不列入設備風險評估",IF($U17=0,"未勾選任何設備，請補填或勾選「無使用調理設備」",IF($U17=1,"僅依賴1台設備，須確認故障/排修時之備援製程","無異常"))))) -> 免調理半成品（外購/僅切配等），不列入設備風險評估 | X17: 1150617炙烤醬香燒豚飯.確認版(1) | Y17: 王安淇 | Z17: =IF($D17="",0,IF(COUNTIF($D$5:$D17,$D17)=1,1,0)) -> 0 | AA17: =IF(Z17=1,SUM($Z$5:$Z17),"")
A18: 架上 | B18: 新豐 | C18: 主食 | D18: 炙烤醬香燒豚飯 | E18: 清洗蔥花 | F18: 2 | G18: 公克 | H18: 100 | T18: V | U18: =IF($E18="","",COUNTIF($I18:$S18,"V")) -> 0 | V18: =IF($E18="","",IF(AND($T18="V",$U18>0),"⚠ 勾選矛盾",IF($T18="V","○ 免調理",IF($U18=0,"⚠ 資料缺漏",IF($U18=1,"▲ 單一設備依賴","OK"))))) -> ○ 免調理 | W18: =IF($E18="","",IF(AND($T18="V",$U18>0),"「無使用調理設備」不可與設備欄同時勾選，請擇一修正",IF($T18="V","免調理半成品（外購/僅切配等），不列入設備風險評估",IF($U18=0,"未勾選任何設備，請補填或勾選「無使用調理設備」",IF($U18=1,"僅依賴1台設備，須確認故障/排修時之備援製程","無異常"))))) -> 免調理半成品（外購/僅切配等），不列入設備風險評估 | X18: 1150617炙烤醬香燒豚飯.確認版(1) | Y18: 王安淇 | Z18: =IF($D18="",0,IF(COUNTIF($D$5:$D18,$D18)=1,1,0)) -> 0 | AA18: =IF(Z18=1,SUM($Z$5:$Z18),"")
A19: 下架 | B19: 新豐 | C19: 主食 | D19: 壹號醬雞豚雙拼 | E19: 冷藏便當飯(109年) | F19: 190 | G19: 公克 | H19: 91 | I19: V | U19: =IF($E19="","",COUNTIF($I19:$S19,"V")) -> 1 | V19: =IF($E19="","",IF(AND($T19="V",$U19>0),"⚠ 勾選矛盾",IF($T19="V","○ 免調理",IF($U19=0,"⚠ 資料缺漏",IF($U19=1,"▲ 單一設備依賴","OK"))))) -> ▲ 單一設備依賴 | W19: =IF($E19="","",IF(AND($T19="V",$U19>0),"「無使用調理設備」不可與設備欄同時勾選，請擇一修正",IF($T19="V","免調理半成品（外購/僅切配等），不列入設備風險評估",IF($U19=0,"未勾選任何設備，請補填或勾選「無使用調理設備」",IF($U19=1,"僅依賴1台設備，須確認故障/排修時之備援製程","無異常"))))) -> 僅依賴1台設備，須確認故障/排修時之備援製程 | X19: 新豐_2025.08.13_壹號醬雞豚雙拼_2026.01校正.xlsx | Y19: 莊子儀 | Z19: =IF($D19="",0,IF(COUNTIF($D$5:$D19,$D19)=1,1,0)) -> 1 | AA19: =IF(Z19=1,SUM($Z$5:$Z19),"") -> 3
A20: 下架 | B20: 新豐 | C20: 主食 | D20: 壹號醬雞豚雙拼 | E20: 碳香燒肉醬 | F20: 20 | G20: 公克 | H20: 61 | O20: V | U20: =IF($E20="","",COUNTIF($I20:$S20,"V")) -> 1 | V20: =IF($E20="","",IF(AND($T20="V",$U20>0),"⚠ 勾選矛盾",IF($T20="V","○ 免調理",IF($U20=0,"⚠ 資料缺漏",IF($U20=1,"▲ 單一設備依賴","OK"))))) -> ▲ 單一設備依賴 | W20: =IF($E20="","",IF(AND($T20="V",$U20>0),"「無使用調理設備」不可與設備欄同時勾選，請擇一修正",IF($T20="V","免調理半成品（外購/僅切配等），不列入設備風險評估",IF($U20=0,"未勾選任何設備，請補填或勾選「無使用調理設備」",IF($U20=1,"僅依賴1台設備，須確認故障/排修時之備援製程","無異常"))))) -> 僅依賴1台設備，須確認故障/排修時之備援製程 | X20: 新豐_2025.08.13_壹號醬雞豚雙拼_2026.01校正.xlsx | Y20: 莊子儀 | Z20: =IF($D20="",0,IF(COUNTIF($D$5:$D20,$D20)=1,1,0)) -> 0 | AA20: =IF(Z20=1,SUM($Z$5:$Z20),"")
A21: 下架 | B21: 新豐 | C21: 主食 | D21: 壹號醬雞豚雙拼 | E21: 切-究極燒肉片 | F21: 18 | G21: 公克 | H21: 92.5 | K21: V | L21: V | U21: =IF($E21="","",COUNTIF($I21:$S21,"V")) -> 2 | V21: =IF($E21="","",IF(AND($T21="V",$U21>0),"⚠ 勾選矛盾",IF($T21="V","○ 免調理",IF($U21=0,"⚠ 資料缺漏",IF($U21=1,"▲ 單一設備依賴","OK"))))) -> OK | W21: =IF($E21="","",IF(AND($T21="V",$U21>0),"「無使用調理設備」不可與設備欄同時勾選，請擇一修正",IF($T21="V","免調理半成品（外購/僅切配等），不列入設備風險評估",IF($U21=0,"未勾選任何設備，請補填或勾選「無使用調理設備」",IF($U21=1,"僅依賴1台設備，須確認故障/排修時之備援製程","無異常"))))) -> 無異常 | X21: 新豐_2025.08.13_壹號醬雞豚雙拼_2026.01校正.xlsx | Y21: 莊子儀 | Z21: =IF($D21="",0,IF(COUNTIF($D$5:$D21,$D21)=1,1,0)) -> 0 | AA21: =IF(Z21=1,SUM($Z$5:$Z21),"")
A22: 下架 | B22: 新豐 | C22: 主食 | D22: 壹號醬雞豚雙拼 | E22: 4切-烤醃漬雞腿排50g | F22: 6 | G22: 個 | H22: 400 | K22: V | U22: =IF($E22="","",COUNTIF($I22:$S22,"V")) -> 1 | V22: =IF($E22="","",IF(AND($T22="V",$U22>0),"⚠ 勾選矛盾",IF($T22="V","○ 免調理",IF($U22=0,"⚠ 資料缺漏",IF($U22=1,"▲ 單一設備依賴","OK"))))) -> ▲ 單一設備依賴 | W22: =IF($E22="","",IF(AND($T22="V",$U22>0),"「無使用調理設備」不可與設備欄同時勾選，請擇一修正",IF($T22="V","免調理半成品（外購/僅切配等），不列入設備風險評估",IF($U22=0,"未勾選任何設備，請補填或勾選「無使用調理設備」",IF($U22=1,"僅依賴1台設備，須確認故障/排修時之備援製程","無異常"))))) -> 僅依賴1台設備，須確認故障/排修時之備援製程 | X22: 新豐_2025.08.13_壹號醬雞豚雙拼_2026.01校正.xlsx | Y22: 莊子儀 | Z22: =IF($D22="",0,IF(COUNTIF($D$5:$D22,$D22)=1,1,0)) -> 0 | AA22: =IF(Z22=1,SUM($Z$5:$Z22),"")
A23: 下架 | B23: 新豐 | C23: 主食 | D23: 壹號醬雞豚雙拼 | E23: 碳香燒肉醬 | F23: 18 | G23: 公克 | H23: 61 | O23: V | U23: =IF($E23="","",COUNTIF($I23:$S23,"V")) -> 1 | V23: =IF($E23="","",IF(AND($T23="V",$U23>0),"⚠ 勾選矛盾",IF($T23="V","○ 免調理",IF($U23=0,"⚠ 資料缺漏",IF($U23=1,"▲ 單一設備依賴","OK"))))) -> ▲ 單一設備依賴 | W23: =IF($E23="","",IF(AND($T23="V",$U23>0),"「無使用調理設備」不可與設備欄同時勾選，請擇一修正",IF($T23="V","免調理半成品（外購/僅切配等），不列入設備風險評估",IF($U23=0,"未勾選任何設備，請補填或勾選「無使用調理設備」",IF($U23=1,"僅依賴1台設備，須確認故障/排修時之備援製程","無異常"))))) -> 僅依賴1台設備，須確認故障/排修時之備援製程 | X23: 新豐_2025.08.13_壹號醬雞豚雙拼_2026.01校正.xlsx | Y23: 莊子儀 | Z23: =IF($D23="",0,IF(COUNTIF($D$5:$D23,$D23)=1,1,0)) -> 0 | AA23: =IF(Z23=1,SUM($Z$5:$Z23),"")
A24: 下架 | B24: 新豐 | C24: 主食 | D24: 壹號醬雞豚雙拼 | E24: 自製鹽蔥(114年) | F24: 8 | G24: 公克 | H24: 57 | O24: V | U24: =IF($E24="","",COUNTIF($I24:$S24,"V")) -> 1 | V24: =IF($E24="","",IF(AND($T24="V",$U24>0),"⚠ 勾選矛盾",IF($T24="V","○ 免調理",IF($U24=0,"⚠ 資料缺漏",IF($U24=1,"▲ 單一設備依賴","OK"))))) -> ▲ 單一設備依賴 | W24: =IF($E24="","",IF(AND($T24="V",$U24>0),"「無使用調理設備」不可與設備欄同時勾選，請擇一修正",IF($T24="V","免調理半成品（外購/僅切配等），不列入設備風險評估",IF($U24=0,"未勾選任何設備，請補填或勾選「無使用調理設備」",IF($U24=1,"僅依賴1台設備，須確認故障/排修時之備援製程","無異常"))))) -> 僅依賴1台設備，須確認故障/排修時之備援製程 | X24: 新豐_2025.08.13_壹號醬雞豚雙拼_2026.01校正.xlsx | Y24: 莊子儀 | Z24: =IF($D24="",0,IF(COUNTIF($D$5:$D24,$D24)=1,1,0)) -> 0 | AA24: =IF(Z24=1,SUM($Z$5:$Z24),"")
A25: 下架 | B25: 新豐 | C25: 主食 | D25: 壹號醬雞豚雙拼 | E25: 殺菌七味唐辛子(B0702AW6161) | F25: 0.2 | G25: 公克 | H25: 100 | T25: V | U25: =IF($E25="","",COUNTIF($I25:$S25,"V")) -> 0 | V25: =IF($E25="","",IF(AND($T25="V",$U25>0),"⚠ 勾選矛盾",IF($T25="V","○ 免調理",IF($U25=0,"⚠ 資料缺漏",IF($U25=1,"▲ 單一設備依賴","OK"))))) -> ○ 免調理 | W25: =IF($E25="","",IF(AND($T25="V",$U25>0),"「無使用調理設備」不可與設備欄同時勾選，請擇一修正",IF($T25="V","免調理半成品（外購/僅切配等），不列入設備風險評估",IF($U25=0,"未勾選任何設備，請補填或勾選「無使用調理設備」",IF($U25=1,"僅依賴1台設備，須確認故障/排修時之備援製程","無異常"))))) -> 免調理半成品（外購/僅切配等），不列入設備風險評估 | X25: 新豐_2025.08.13_壹號醬雞豚雙拼_2026.01校正.xlsx | Y25: 莊子儀
A26: 架上 | B26: 新豐 | C26: 主食 | D26: 香辣醬蒜味香腸蛋炒飯 | E26: 鼎泰豐-黃金蛋炒飯(112年) | F26: 280 | G26: 公克 | H26: 78 | I26: V | P26: V | U26: =IF($E26="","",COUNTIF($I26:$S26,"V")) -> 2 | V26: =IF($E26="","",IF(AND($T26="V",$U26>0),"⚠ 勾選矛盾",IF($T26="V","○ 免調理",IF($U26=0,"⚠ 資料缺漏",IF($U26=1,"▲ 單一設備依賴","OK"))))) -> OK | W26: =IF($E26="","",IF(AND($T26="V",$U26>0),"「無使用調理設備」不可與設備欄同時勾選，請擇一修正",IF($T26="V","免調理半成品（外購/僅切配等），不列入設備風險評估",IF($U26=0,"未勾選任何設備，請補填或勾選「無使用調理設備」",IF($U26=1,"僅依賴1台設備，須確認故障/排修時之備援製程","無異常"))))) -> 無異常 | X26: 1131120二配香辣醬蒜味香腸蛋炒飯.確認版(2)切換二配 | Y26: 王安淇 | Z26: =IF($D26="",0,IF(COUNTIF($D$5:$D26,$D26)=1,1,0)) -> 1 | AA26: =IF(Z26=1,SUM($Z$5:$Z26),"") -> 4
A27: 架上 | B27: 新豐 | C27: 主食 | D27: 香辣醬蒜味香腸蛋炒飯 | E27: 清洗蔥花 | F27: 3 | G27: 公克 | H27: 70 | T27: V | U27: =IF($E27="","",COUNTIF($I27:$S27,"V")) -> 0 | V27: =IF($E27="","",IF(AND($T27="V",$U27>0),"⚠ 勾選矛盾",IF($T27="V","○ 免調理",IF($U27=0,"⚠ 資料缺漏",IF($U27=1,"▲ 單一設備依賴","OK"))))) -> ○ 免調理 | W27: =IF($E27="","",IF(AND($T27="V",$U27>0),"「無使用調理設備」不可與設備欄同時勾選，請擇一修正",IF($T27="V","免調理半成品（外購/僅切配等），不列入設備風險評估",IF($U27=0,"未勾選任何設備，請補填或勾選「無使用調理設備」",IF($U27=1,"僅依賴1台設備，須確認故障/排修時之備援製程","無異常"))))) -> 免調理半成品（外購/僅切配等），不列入設備風險評估 | X27: 1131120二配香辣醬蒜味香腸蛋炒飯.確認版(2)切換二配 | Y27: 王安淇 | Z27: =IF($D27="",0,IF(COUNTIF($D$5:$D27,$D27)=1,1,0)) -> 0 | AA27: =IF(Z27=1,SUM($Z$5:$Z27),"")
A28: 架上 | B28: 新豐 | C28: 主食 | D28: 香辣醬蒜味香腸蛋炒飯 | E28: 油亮蒜味香腸片 | F28: 37 | G28: 公克 | H28: 100 | K28: V | U28: =IF($E28="","",COUNTIF($I28:$S28,"V")) -> 1 | V28: =IF($E28="","",IF(AND($T28="V",$U28>0),"⚠ 勾選矛盾",IF($T28="V","○ 免調理",IF($U28=0,"⚠ 資料缺漏",IF($U28=1,"▲ 單一設備依賴","OK"))))) -> ▲ 單一設備依賴 | W28: =IF($E28="","",IF(AND($T28="V",$U28>0),"「無使用調理設備」不可與設備欄同時勾選，請擇一修正",IF($T28="V","免調理半成品（外購/僅切配等），不列入設備風險評估",IF($U28=0,"未勾選任何設備，請補填或勾選「無使用調理設備」",IF($U28=1,"僅依賴1台設備，須確認故障/排修時之備援製程","無異常"))))) -> 僅依賴1台設備，須確認故障/排修時之備援製程 | X28: 1131120二配香辣醬蒜味香腸蛋炒飯.確認版(2)切換二配 | Y28: 王安淇 | Z28: =IF($D28="",0,IF(COUNTIF($D$5:$D28,$D28)=1,1,0)) -> 0 | AA28: =IF(Z28=1,SUM($Z$5:$Z28),"")
A29: 架上 | B29: 新豐 | C29: 主食 | D29: 香辣醬蒜味香腸蛋炒飯 | E29: 蒸鼎泰豐香辣醬 | F29: 11 | G29: 公克 | H29: 95 | M29: V | U29: =IF($E29="","",COUNTIF($I29:$S29,"V")) -> 1 | V29: =IF($E29="","",IF(AND($T29="V",$U29>0),"⚠ 勾選矛盾",IF($T29="V","○ 免調理",IF($U29=0,"⚠ 資料缺漏",IF($U29=1,"▲ 單一設備依賴","OK"))))) -> ▲ 單一設備依賴 | W29: =IF($E29="","",IF(AND($T29="V",$U29>0),"「無使用調理設備」不可與設備欄同時勾選，請擇一修正",IF($T29="V","免調理半成品（外購/僅切配等），不列入設備風險評估",IF($U29=0,"未勾選任何設備，請補填或勾選「無使用調理設備」",IF($U29=1,"僅依賴1台設備，須確認故障/排修時之備援製程","無異常"))))) -> 僅依賴1台設備，須確認故障/排修時之備援製程 | X29: 1131120二配香辣醬蒜味香腸蛋炒飯.確認版(2)切換二配 | Y29: 王安淇 | Z29: =IF($D29="",0,IF(COUNTIF($D$5:$D29,$D29)=1,1,0)) -> 0 | AA29: =IF(Z29=1,SUM($Z$5:$Z29),"")
A30: 下架 | B30: 新豐 | C30: 主食 | D30: 藤椒雞丁炒飯 | E30: 藤椒油炒飯 | F30: 250 | G30: 公克 | H30: 76 | I30: V | P30: V | U30: =IF($E30="","",COUNTIF($I30:$S30,"V")) -> 2 | V30: =IF($E30="","",IF(AND($T30="V",$U30>0),"⚠ 勾選矛盾",IF($T30="V","○ 免調理",IF($U30=0,"⚠ 資料缺漏",IF($U30=1,"▲ 單一設備依賴","OK"))))) -> OK | W30: =IF($E30="","",IF(AND($T30="V",$U30>0),"「無使用調理設備」不可與設備欄同時勾選，請擇一修正",IF($T30="V","免調理半成品（外購/僅切配等），不列入設備風險評估",IF($U30=0,"未勾選任何設備，請補填或勾選「無使用調理設備」",IF($U30=1,"僅依賴1台設備，須確認故障/排修時之備援製程","無異常"))))) -> 無異常 | X30: 1150609二配藤椒雞丁炒飯.確認版(2)新增雞丁大小良品規範 | Y30: 王安淇 | Z30: =IF($D30="",0,IF(COUNTIF($D$5:$D30,$D30)=1,1,0)) -> 1 | AA30: =IF(Z30=1,SUM($Z$5:$Z30),"") -> 5
A31: 下架 | B31: 新豐 | C31: 主食 | D31: 藤椒雞丁炒飯 | E31: 烤藤椒雞丁 | F31: 50 | G31: 公克 | H31: 49 | K31: V | U31: =IF($E31="","",COUNTIF($I31:$S31,"V")) -> 1 | V31: =IF($E31="","",IF(AND($T31="V",$U31>0),"⚠ 勾選矛盾",IF($T31="V","○ 免調理",IF($U31=0,"⚠ 資料缺漏",IF($U31=1,"▲ 單一設備依賴","OK"))))) -> ▲ 單一設備依賴 | W31: =IF($E31="","",IF(AND($T31="V",$U31>0),"「無使用調理設備」不可與設備欄同時勾選，請擇一修正",IF($T31="V","免調理半成品（外購/僅切配等），不列入設備風險評估",IF($U31=0,"未勾選任何設備，請補填或勾選「無使用調理設備」",IF($U31=1,"僅依賴1台設備，須確認故障/排修時之備援製程","無異常"))))) -> 僅依賴1台設備，須確認故障/排修時之備援製程 | X31: 1150609二配藤椒雞丁炒飯.確認版(2)新增雞丁大小良品規範 | Y31: 王安淇 | Z31: =IF($D31="",0,IF(COUNTIF($D$5:$D31,$D31)=1,1,0)) -> 0 | AA31: =IF(Z31=1,SUM($Z$5:$Z31),"")
A32: 下架 | B32: 新豐 | C32: 主食 | D32: 藤椒雞丁炒飯 | E32: ㄠ麻子藤椒油 | F32: 1 | G32: 公克 | H32: 100 | T32: V | U32: =IF($E32="","",COUNTIF($I32:$S32,"V")) -> 0 | V32: =IF($E32="","",IF(AND($T32="V",$U32>0),"⚠ 勾選矛盾",IF($T32="V","○ 免調理",IF($U32=0,"⚠ 資料缺漏",IF($U32=1,"▲ 單一設備依賴","OK"))))) -> ○ 免調理 | W32: =IF($E32="","",IF(AND($T32="V",$U32>0),"「無使用調理設備」不可與設備欄同時勾選，請擇一修正",IF($T32="V","免調理半成品（外購/僅切配等），不列入設備風險評估",IF($U32=0,"未勾選任何設備，請補填或勾選「無使用調理設備」",IF($U32=1,"僅依賴1台設備，須確認故障/排修時之備援製程","無異常"))))) -> 免調理半成品（外購/僅切配等），不列入設備風險評估 | X32: 1150609二配藤椒雞丁炒飯.確認版(2)新增雞丁大小良品規範 | Y32: 王安淇 | Z32: =IF($D32="",0,IF(COUNTIF($D$5:$D32,$D32)=1,1,0)) -> 0 | AA32: =IF(Z32=1,SUM($Z$5:$Z32),"")
A33: 架上 | B33: 新豐 | C33: 主食 | D33: 川味麻婆燒豆腐燴飯 | E33: 冷藏便當飯(109年) | F33: 245 | G33: 公克 | H33: 91 | I33: V | U33: =IF($E33="","",COUNTIF($I33:$S33,"V")) -> 1 | V33: =IF($E33="","",IF(AND($T33="V",$U33>0),"⚠ 勾選矛盾",IF($T33="V","○ 免調理",IF($U33=0,"⚠ 資料缺漏",IF($U33=1,"▲ 單一設備依賴","OK"))))) -> ▲ 單一設備依賴 | W33: =IF($E33="","",IF(AND($T33="V",$U33>0),"「無使用調理設備」不可與設備欄同時勾選，請擇一修正",IF($T33="V","免調理半成品（外購/僅切配等），不列入設備風險評估",IF($U33=0,"未勾選任何設備，請補填或勾選「無使用調理設備」",IF($U33=1,"僅依賴1台設備，須確認故障/排修時之備援製程","無異常"))))) -> 僅依賴1台設備，須確認故障/排修時之備援製程 | X33: 1130110二配川味麻婆燒豆腐燴飯.確認版(13)設計移除國產豬及蔥花 | Y33: 王安淇 | Z33: =IF($D33="",0,IF(COUNTIF($D$5:$D33,$D33)=1,1,0)) -> 1 | AA33: =IF(Z33=1,SUM($Z$5:$Z33),"") -> 6
A34: 架上 | B34: 新豐 | C34: 主食 | D34: 川味麻婆燒豆腐燴飯 | E34: 鼎泰豐-煮麻婆豆腐(113年) | F34: 156 | G34: 公克 | H34: 58 | O34: V | U34: =IF($E34="","",COUNTIF($I34:$S34,"V")) -> 1 | V34: =IF($E34="","",IF(AND($T34="V",$U34>0),"⚠ 勾選矛盾",IF($T34="V","○ 免調理",IF($U34=0,"⚠ 資料缺漏",IF($U34=1,"▲ 單一設備依賴","OK"))))) -> ▲ 單一設備依賴 | W34: =IF($E34="","",IF(AND($T34="V",$U34>0),"「無使用調理設備」不可與設備欄同時勾選，請擇一修正",IF($T34="V","免調理半成品（外購/僅切配等），不列入設備風險評估",IF($U34=0,"未勾選任何設備，請補填或勾選「無使用調理設備」",IF($U34=1,"僅依賴1台設備，須確認故障/排修時之備援製程","無異常"))))) -> 僅依賴1台設備，須確認故障/排修時之備援製程 | X34: 1130110二配川味麻婆燒豆腐燴飯.確認版(13)設計移除國產豬及蔥花 | Y34: 王安淇 | Z34: =IF($D34="",0,IF(COUNTIF($D$5:$D34,$D34)=1,1,0)) -> 0 | AA34: =IF(Z34=1,SUM($Z$5:$Z34),"")
A35: 架上 | B35: 新豐 | C35: 主食 | D35: 川味麻婆燒豆腐燴飯 | E35: 鼎泰豐-麻婆豆腐燴汁(113年) | F35: 50 | G35: 公克 | H35: 61 | O35: V | U35: =IF($E35="","",COUNTIF($I35:$S35,"V")) -> 1 | V35: =IF($E35="","",IF(AND($T35="V",$U35>0),"⚠ 勾選矛盾",IF($T35="V","○ 免調理",IF($U35=0,"⚠ 資料缺漏",IF($U35=1,"▲ 單一設備依賴","OK"))))) -> ▲ 單一設備依賴 | W35: =IF($E35="","",IF(AND($T35="V",$U35>0),"「無使用調理設備」不可與設備欄同時勾選，請擇一修正",IF($T35="V","免調理半成品（外購/僅切配等），不列入設備風險評估",IF($U35=0,"未勾選任何設備，請補填或勾選「無使用調理設備」",IF($U35=1,"僅依賴1台設備，須確認故障/排修時之備援製程","無異常"))))) -> 僅依賴1台設備，須確認故障/排修時之備援製程 | X35: 1130110二配川味麻婆燒豆腐燴飯.確認版(13)設計移除國產豬及蔥花 | Y35: 王安淇 | Z35: =IF($D35="",0,IF(COUNTIF($D$5:$D35,$D35)=1,1,0)) -> 0 | AA35: =IF(Z35=1,SUM($Z$5:$Z35),"")
A36: 架上 | B36: 新豐 | C36: 主食 | D36: 金咖哩濃厚辛口咖哩飯 | E36: 冷藏便當飯(109年) | F36: 260 | G36: 公克 | H36: 91 | I36: V | U36: =IF($E36="","",COUNTIF($I36:$S36,"V")) -> 1 | V36: =IF($E36="","",IF(AND($T36="V",$U36>0),"⚠ 勾選矛盾",IF($T36="V","○ 免調理",IF($U36=0,"⚠ 資料缺漏",IF($U36=1,"▲ 單一設備依賴","OK"))))) -> ▲ 單一設備依賴 | W36: =IF($E36="","",IF(AND($T36="V",$U36>0),"「無使用調理設備」不可與設備欄同時勾選，請擇一修正",IF($T36="V","免調理半成品（外購/僅切配等），不列入設備風險評估",IF($U36=0,"未勾選任何設備，請補填或勾選「無使用調理設備」",IF($U36=1,"僅依賴1台設備，須確認故障/排修時之備援製程","無異常"))))) -> 僅依賴1台設備，須確認故障/排修時之備援製程 | X36: 1141111二配金咖哩濃厚辛口咖哩飯.確認版(3)設計切換無國產豬 | Y36: 王安淇 | Z36: =IF($D36="",0,IF(COUNTIF($D$5:$D36,$D36)=1,1,0)) -> 1 | AA36: =IF(Z36=1,SUM($Z$5:$Z36),"") -> 7
A37: 架上 | B37: 新豐 | C37: 主食 | D37: 金咖哩濃厚辛口咖哩飯 | E37: 濃辛辣咖哩醬(114年) | F37: 180 | G37: 公克 | H37: 55 | O37: V | U37: =IF($E37="","",COUNTIF($I37:$S37,"V")) -> 1 | V37: =IF($E37="","",IF(AND($T37="V",$U37>0),"⚠ 勾選矛盾",IF($T37="V","○ 免調理",IF($U37=0,"⚠ 資料缺漏",IF($U37=1,"▲ 單一設備依賴","OK"))))) -> ▲ 單一設備依賴 | W37: =IF($E37="","",IF(AND($T37="V",$U37>0),"「無使用調理設備」不可與設備欄同時勾選，請擇一修正",IF($T37="V","免調理半成品（外購/僅切配等），不列入設備風險評估",IF($U37=0,"未勾選任何設備，請補填或勾選「無使用調理設備」",IF($U37=1,"僅依賴1台設備，須確認故障/排修時之備援製程","無異常"))))) -> 僅依賴1台設備，須確認故障/排修時之備援製程 | X37: 1141111二配金咖哩濃厚辛口咖哩飯.確認版(3)設計切換無國產豬 | Y37: 王安淇 | Z37: =IF($D37="",0,IF(COUNTIF($D$5:$D37,$D37)=1,1,0)) -> 0 | AA37: =IF(Z37=1,SUM($Z$5:$Z37),"")
A38: 架上 | B38: 新豐 | C38: 主食 | D38: 金咖哩濃厚辛口咖哩飯 | E38: 辛口咖哩豬肉(114年) | F38: 26 | G38: 公克 | H38: 60 | O38: V | U38: =IF($E38="","",COUNTIF($I38:$S38,"V")) -> 1 | V38: =IF($E38="","",IF(AND($T38="V",$U38>0),"⚠ 勾選矛盾",IF($T38="V","○ 免調理",IF($U38=0,"⚠ 資料缺漏",IF($U38=1,"▲ 單一設備依賴","OK"))))) -> ▲ 單一設備依賴 | W38: =IF($E38="","",IF(AND($T38="V",$U38>0),"「無使用調理設備」不可與設備欄同時勾選，請擇一修正",IF($T38="V","免調理半成品（外購/僅切配等），不列入設備風險評估",IF($U38=0,"未勾選任何設備，請補填或勾選「無使用調理設備」",IF($U38=1,"僅依賴1台設備，須確認故障/排修時之備援製程","無異常"))))) -> 僅依賴1台設備，須確認故障/排修時之備援製程 | X38: 1141111二配金咖哩濃厚辛口咖哩飯.確認版(3)設計切換無國產豬 | Y38: 王安淇 | Z38: =IF($D38="",0,IF(COUNTIF($D$5:$D38,$D38)=1,1,0)) -> 0 | AA38: =IF(Z38=1,SUM($Z$5:$Z38),"")
A39: 架上 | B39: 新豐 | C39: 主食 | D39: 金咖哩濃厚辛口咖哩飯 | E39: 煮咖哩紅蘿蔔丁 | F39: 20 | G39: 公克 | H39: 65 | O39: V | U39: =IF($E39="","",COUNTIF($I39:$S39,"V")) -> 1 | V39: =IF($E39="","",IF(AND($T39="V",$U39>0),"⚠ 勾選矛盾",IF($T39="V","○ 免調理",IF($U39=0,"⚠ 資料缺漏",IF($U39=1,"▲ 單一設備依賴","OK"))))) -> ▲ 單一設備依賴 | W39: =IF($E39="","",IF(AND($T39="V",$U39>0),"「無使用調理設備」不可與設備欄同時勾選，請擇一修正",IF($T39="V","免調理半成品（外購/僅切配等），不列入設備風險評估",IF($U39=0,"未勾選任何設備，請補填或勾選「無使用調理設備」",IF($U39=1,"僅依賴1台設備，須確認故障/排修時之備援製程","無異常"))))) -> 僅依賴1台設備，須確認故障/排修時之備援製程 | X39: 1141111二配金咖哩濃厚辛口咖哩飯.確認版(3)設計切換無國產豬 | Y39: 王安淇 | Z39: =IF($D39="",0,IF(COUNTIF($D$5:$D39,$D39)=1,1,0)) -> 0 | AA39: =IF(Z39=1,SUM($Z$5:$Z39),"")
A40: 架上 | B40: 新豐 | C40: 主食 | D40: 金咖哩濃厚辛口咖哩飯 | E40: 煮焦糖馬鈴薯丁 | F40: 30 | G40: 公克 | H40: 66 | O40: V | U40: =IF($E40="","",COUNTIF($I40:$S40,"V")) -> 1 | V40: =IF($E40="","",IF(AND($T40="V",$U40>0),"⚠ 勾選矛盾",IF($T40="V","○ 免調理",IF($U40=0,"⚠ 資料缺漏",IF($U40=1,"▲ 單一設備依賴","OK"))))) -> ▲ 單一設備依賴 | W40: =IF($E40="","",IF(AND($T40="V",$U40>0),"「無使用調理設備」不可與設備欄同時勾選，請擇一修正",IF($T40="V","免調理半成品（外購/僅切配等），不列入設備風險評估",IF($U40=0,"未勾選任何設備，請補填或勾選「無使用調理設備」",IF($U40=1,"僅依賴1台設備，須確認故障/排修時之備援製程","無異常"))))) -> 僅依賴1台設備，須確認故障/排修時之備援製程 | X40: 1141111二配金咖哩濃厚辛口咖哩飯.確認版(3)設計切換無國產豬 | Y40: 王安淇 | Z40: =IF($D40="",0,IF(COUNTIF($D$5:$D40,$D40)=1,1,0)) -> 0 | AA40: =IF(Z40=1,SUM($Z$5:$Z40),"")
...

Sheet 4℃麵
B1: 商品半成品與調理設備應用展開一覽表｜4℃麵
A2: 商品資訊 | B2: 商品資訊 | I2: 熱調理區（使用者填「V」；免調理者勾最右欄） | U2: 自動計算與風險檢核（勿手動修改） | X2: 建檔資訊（手填）
A3: 狀態 | B3: 工廠 | C3: 商品分類 (細分品類) | D3: 商品名稱 | E3: 半成品名稱 | F3: 單位用量 | H3: 製程率 (填數字) | I3: 炊飯 | J3: 煮麵 | K3: 烤箱 | L3: 炙燒 | M3: 蒸箱 | N3: 油炸機 | O3: 二重釜 | P3: 平釜 (日) | Q3: 平釜 (台) | R3: 蛋皮機 | S3: 壓力鍋 | T3: 無使用 調理設備 | U3: 使用 設備數 | V3: 檢核結果 | W3: 風險說明 | X3: 備註 (指示書編號/版本) | Y3: 建檔人員 | Z3: 系統用Y | AA3: 系統用Z
F4: 數值 | G4: 單位
A5: 架上 | B5: 新豐 | C5: 季節調理麵 | D5: 台式麻醬涼麵 | E5: 煮中華冷麵(111年) | F5: 210 | G5: 公克 | H5: 193 | J5: V | U5: =IF($E5="","",COUNTIF($I5:$S5,"V")) -> 1 | V5: =IF($E5="","",IF(AND($T5="V",$U5>0),"⚠ 勾選矛盾",IF($T5="V","○ 免調理",IF($U5=0,"⚠ 資料缺漏",IF($U5=1,"▲ 單一設備依賴","OK"))))) -> ▲ 單一設備依賴 | W5: =IF($E5="","",IF(AND($T5="V",$U5>0),"「無使用調理設備」不可與設備欄同時勾選，請擇一修正",IF($T5="V","免調理半成品（外購/僅切配等），不列入設備風險評估",IF($U5=0,"未勾選任何設備，請補填或勾選「無使用調理設備」",IF($U5=1,"僅依賴1台設備，須確認故障/排修時之備援製程","無異常"))))) -> 僅依賴1台設備，須確認故障/排修時之備援製程 | X5: 1150422台式麻醬涼麵.確認版(8)- F06 - 切回小黃瓜.xlsx | Y5: 王安淇 | Z5: =IF($D5="",0,IF(COUNTIF($D$5:$D5,$D5)=1,1,0)) -> 1 | AA5: =IF(Z5=1,SUM($Z$5:$Z5),"") -> 1
A6: 架上 | B6: 新豐 | C6: 季節調理麵 | D6: 台式麻醬涼麵 | E6: 清洗細切胡蘿蔔絲 | F6: 15 | G6: 公克 | H6: 75 | T6: V | U6: =IF($E6="","",COUNTIF($I6:$S6,"V")) -> 0 | V6: =IF($E6="","",IF(AND($T6="V",$U6>0),"⚠ 勾選矛盾",IF($T6="V","○ 免調理",IF($U6=0,"⚠ 資料缺漏",IF($U6=1,"▲ 單一設備依賴","OK"))))) -> ○ 免調理 | W6: =IF($E6="","",IF(AND($T6="V",$U6>0),"「無使用調理設備」不可與設備欄同時勾選，請擇一修正",IF($T6="V","免調理半成品（外購/僅切配等），不列入設備風險評估",IF($U6=0,"未勾選任何設備，請補填或勾選「無使用調理設備」",IF($U6=1,"僅依賴1台設備，須確認故障/排修時之備援製程","無異常"))))) -> 免調理半成品（外購/僅切配等），不列入設備風險評估 | X6: 1150422台式麻醬涼麵.確認版(8)- F06 - 切回小黃瓜.xlsx | Y6: 王安淇 | Z6: =IF($D6="",0,IF(COUNTIF($D$5:$D6,$D6)=1,1,0)) -> 0 | AA6: =IF(Z6=1,SUM($Z$5:$Z6),"")
A7: 架上 | B7: 新豐 | C7: 季節調理麵 | D7: 台式麻醬涼麵 | E7: 小黃瓜絲 | F7: 13 | G7: 公克 | H7: 75 | T7: V | U7: =IF($E7="","",COUNTIF($I7:$S7,"V")) -> 0 | V7: =IF($E7="","",IF(AND($T7="V",$U7>0),"⚠ 勾選矛盾",IF($T7="V","○ 免調理",IF($U7=0,"⚠ 資料缺漏",IF($U7=1,"▲ 單一設備依賴","OK"))))) -> ○ 免調理 | W7: =IF($E7="","",IF(AND($T7="V",$U7>0),"「無使用調理設備」不可與設備欄同時勾選，請擇一修正",IF($T7="V","免調理半成品（外購/僅切配等），不列入設備風險評估",IF($U7=0,"未勾選任何設備，請補填或勾選「無使用調理設備」",IF($U7=1,"僅依賴1台設備，須確認故障/排修時之備援製程","無異常"))))) -> 免調理半成品（外購/僅切配等），不列入設備風險評估 | X7: 1150422台式麻醬涼麵.確認版(8)- F06 - 切回小黃瓜.xlsx | Y7: 王安淇 | Z7: =IF($D7="",0,IF(COUNTIF($D$5:$D7,$D7)=1,1,0)) -> 0 | AA7: =IF(Z7=1,SUM($Z$5:$Z7),"")
A8: 架上 | B8: 新豐 | C8: 季節調理麵 | D8: 台式麻醬涼麵 | E8: 2024台式醬油包 | F8: 1 | G8: 個 | H8: 100 | T8: V | U8: =IF($E8="","",COUNTIF($I8:$S8,"V")) -> 0 | V8: =IF($E8="","",IF(AND($T8="V",$U8>0),"⚠ 勾選矛盾",IF($T8="V","○ 免調理",IF($U8=0,"⚠ 資料缺漏",IF($U8=1,"▲ 單一設備依賴","OK"))))) -> ○ 免調理 | W8: =IF($E8="","",IF(AND($T8="V",$U8>0),"「無使用調理設備」不可與設備欄同時勾選，請擇一修正",IF($T8="V","免調理半成品（外購/僅切配等），不列入設備風險評估",IF($U8=0,"未勾選任何設備，請補填或勾選「無使用調理設備」",IF($U8=1,"僅依賴1台設備，須確認故障/排修時之備援製程","無異常"))))) -> 免調理半成品（外購/僅切配等），不列入設備風險評估 | X8: 1150422台式麻醬涼麵.確認版(8)- F06 - 切回小黃瓜.xlsx | Y8: 王安淇 | Z8: =IF($D8="",0,IF(COUNTIF($D$5:$D8,$D8)=1,1,0)) -> 0 | AA8: =IF(Z8=1,SUM($Z$5:$Z8),"")
A9: 架上 | B9: 新豐 | C9: 季節調理麵 | D9: 台式麻醬涼麵 | E9: 2022台式麻醬包 | F9: 1 | G9: 個 | H9: 100 | T9: V | U9: =IF($E9="","",COUNTIF($I9:$S9,"V")) -> 0 | V9: =IF($E9="","",IF(AND($T9="V",$U9>0),"⚠ 勾選矛盾",IF($T9="V","○ 免調理",IF($U9=0,"⚠ 資料缺漏",IF($U9=1,"▲ 單一設備依賴","OK"))))) -> ○ 免調理 | W9: =IF($E9="","",IF(AND($T9="V",$U9>0),"「無使用調理設備」不可與設備欄同時勾選，請擇一修正",IF($T9="V","免調理半成品（外購/僅切配等），不列入設備風險評估",IF($U9=0,"未勾選任何設備，請補填或勾選「無使用調理設備」",IF($U9=1,"僅依賴1台設備，須確認故障/排修時之備援製程","無異常"))))) -> 免調理半成品（外購/僅切配等），不列入設備風險評估 | X9: 1150422台式麻醬涼麵.確認版(8)- F06 - 切回小黃瓜.xlsx | Y9: 王安淇
A10: 下架 | B10: 新豐 | C10: 季節調理麵 | D10: 鰹魚烏龍冷麵 | E10: 烏龍冷麵(113年) | F10: 190 | G10: 公克 | H10: 100.6 | J10: V | U10: =IF($E10="","",COUNTIF($I10:$S10,"V")) -> 1 | V10: =IF($E10="","",IF(AND($T10="V",$U10>0),"⚠ 勾選矛盾",IF($T10="V","○ 免調理",IF($U10=0,"⚠ 資料缺漏",IF($U10=1,"▲ 單一設備依賴","OK"))))) -> ▲ 單一設備依賴 | W10: =IF($E10="","",IF(AND($T10="V",$U10>0),"「無使用調理設備」不可與設備欄同時勾選，請擇一修正",IF($T10="V","免調理半成品（外購/僅切配等），不列入設備風險評估",IF($U10=0,"未勾選任何設備，請補填或勾選「無使用調理設備」",IF($U10=1,"僅依賴1台設備，須確認故障/排修時之備援製程","無異常"))))) -> 僅依賴1台設備，須確認故障/排修時之備援製程 | X10: 1150429鰹魚烏龍冷麵.確認版(1).xlsx | Y10: 莊子儀 | Z10: =IF($D10="",0,IF(COUNTIF($D$5:$D10,$D10)=1,1,0)) -> 1 | AA10: =IF(Z10=1,SUM($Z$5:$Z10),"") -> 2
A11: 下架 | B11: 新豐 | C11: 季節調理麵 | D11: 鰹魚烏龍冷麵 | E11: 解凍玉子蛋絲 | F11: 9 | G11: 公克 | H11: 100 | T11: V | U11: =IF($E11="","",COUNTIF($I11:$S11,"V")) -> 0 | V11: =IF($E11="","",IF(AND($T11="V",$U11>0),"⚠ 勾選矛盾",IF($T11="V","○ 免調理",IF($U11=0,"⚠ 資料缺漏",IF($U11=1,"▲ 單一設備依賴","OK"))))) -> ○ 免調理 | W11: =IF($E11="","",IF(AND($T11="V",$U11>0),"「無使用調理設備」不可與設備欄同時勾選，請擇一修正",IF($T11="V","免調理半成品（外購/僅切配等），不列入設備風險評估",IF($U11=0,"未勾選任何設備，請補填或勾選「無使用調理設備」",IF($U11=1,"僅依賴1台設備，須確認故障/排修時之備援製程","無異常"))))) -> 免調理半成品（外購/僅切配等），不列入設備風險評估 | X11: 1150429鰹魚烏龍冷麵.確認版(1).xlsx | Y11: 莊子儀 | Z11: =IF($D11="",0,IF(COUNTIF($D$5:$D11,$D11)=1,1,0)) -> 0 | AA11: =IF(Z11=1,SUM($Z$5:$Z11),"")
A12: 下架 | B12: 新豐 | C12: 季節調理麵 | D12: 鰹魚烏龍冷麵 | E12: 清洗小黃瓜絲 | F12: 10 | G12: 公克 | H12: 75 | T12: V | U12: =IF($E12="","",COUNTIF($I12:$S12,"V")) -> 0 | V12: =IF($E12="","",IF(AND($T12="V",$U12>0),"⚠ 勾選矛盾",IF($T12="V","○ 免調理",IF($U12=0,"⚠ 資料缺漏",IF($U12=1,"▲ 單一設備依賴","OK"))))) -> ○ 免調理 | W12: =IF($E12="","",IF(AND($T12="V",$U12>0),"「無使用調理設備」不可與設備欄同時勾選，請擇一修正",IF($T12="V","免調理半成品（外購/僅切配等），不列入設備風險評估",IF($U12=0,"未勾選任何設備，請補填或勾選「無使用調理設備」",IF($U12=1,"僅依賴1台設備，須確認故障/排修時之備援製程","無異常"))))) -> 免調理半成品（外購/僅切配等），不列入設備風險評估 | X12: 1150429鰹魚烏龍冷麵.確認版(1).xlsx | Y12: 莊子儀 | Z12: =IF($D12="",0,IF(COUNTIF($D$5:$D12,$D12)=1,1,0)) -> 0 | AA12: =IF(Z12=1,SUM($Z$5:$Z12),"")
A13: 下架 | B13: 新豐 | C13: 季節調理麵 | D13: 鰹魚烏龍冷麵 | E13: F-2026日式烏龍醬汁 | F13: 1 | G13: 個 | H13: 100 | T13: V | U13: =IF($E13="","",COUNTIF($I13:$S13,"V")) -> 0 | V13: =IF($E13="","",IF(AND($T13="V",$U13>0),"⚠ 勾選矛盾",IF($T13="V","○ 免調理",IF($U13=0,"⚠ 資料缺漏",IF($U13=1,"▲ 單一設備依賴","OK"))))) -> ○ 免調理 | W13: =IF($E13="","",IF(AND($T13="V",$U13>0),"「無使用調理設備」不可與設備欄同時勾選，請擇一修正",IF($T13="V","免調理半成品（外購/僅切配等），不列入設備風險評估",IF($U13=0,"未勾選任何設備，請補填或勾選「無使用調理設備」",IF($U13=1,"僅依賴1台設備，須確認故障/排修時之備援製程","無異常"))))) -> 免調理半成品（外購/僅切配等），不列入設備風險評估 | X13: 1150429鰹魚烏龍冷麵.確認版(1).xlsx | Y13: 莊子儀 | Z13: =IF($D13="",0,IF(COUNTIF($D$5:$D13,$D13)=1,1,0)) -> 0 | AA13: =IF(Z13=1,SUM($Z$5:$Z13),"")
