Workbook

Sheet 總覽
B1: 商品半成品與調理設備應用盤點｜總覽目錄
B3: 盤點基本資訊（黃底請填寫） | E3: 本廠總體統計（自動計算）
B4: 盤點工廠 | C4: 長家 | E4: 生產總品項數 | F4: =SUM(MAX('18℃'!$Z$5:$Z$304),MAX('4℃飯'!$Z$5:$Z$304),MAX('4℃麵'!$AA$5:$AA$292),MAX('4℃其他'!$AA$5:$AA$304),MAX(冷凍品!$AA$5:$AA$304)) -> 40
B5: 盤點日期 | C5: 2026.7.22 | E5: 半成品總筆數 | F5: =COUNTA('18℃'!$D$5:$D$304)+COUNTA('4℃飯'!$D$5:$D$304)+COUNTA('4℃麵'!$E$5:$E$292)+COUNTA('4℃其他'!$E$5:$E$304)+COUNTA(冷凍品!$E$5:$E$304) -> 198
B6: 盤點負責人 | C6: 朱笠揚 | E6: 資料缺漏/矛盾筆數 | F6: =COUNTIF('18℃'!$U$5:$U$304,"⚠*")+COUNTIF('4℃飯'!$U$5:$U$304,"⚠*")+COUNTIF('4℃麵'!$V$5:$V$292,"⚠*")+COUNTIF('4℃其他'!$V$5:$V$304,"⚠*")+COUNTIF(冷凍品!$V$5:$V$304,"⚠*") -> 0
E7: 單一設備依賴筆數 | F7: =COUNTIF('18℃'!$U$5:$U$304,"▲ 單一設備依賴")+COUNTIF('4℃飯'!$U$5:$U$304,"▲ 單一設備依賴")+COUNTIF('4℃麵'!$V$5:$V$292,"▲ 單一設備依賴")+COUNTIF('4℃其他'!$V$5:$V$304,"▲ 單一設備依賴")+COUNTIF(冷凍品!$V$5:$V$304,"▲ 單一設備依賴") -> 141
E8: 免調理半成品筆數 | F8: =COUNTIF('18℃'!$U$5:$U$304,"○ 免調理")+COUNTIF('4℃飯'!$U$5:$U$304,"○ 免調理")+COUNTIF('4℃麵'!$V$5:$V$292,"○ 免調理")+COUNTIF('4℃其他'!$V$5:$V$304,"○ 免調理")+COUNTIF(冷凍品!$V$5:$V$304,"○ 免調理") -> 51
B10: 商品分類分布
B11: 分類 | C11: 品項數 | D11: 品項佔比 | E11: 半成品筆數 | F11: 半成品佔比
B12: 18℃ | C12: =MAX('18℃'!$Z$5:$Z$304) -> 0 | D12: =IF($F$4=0,0,C12/$F$4) -> 0 | E12: =COUNTA('18℃'!$D$5:$D$304) -> 0 | F12: =IF($F$5=0,0,E12/$F$5) -> 0
B13: 4℃飯 | C13: =MAX('4℃飯'!$Z$5:$Z$304) -> 0 | D13: =IF($F$4=0,0,C13/$F$4) -> 0 | E13: =COUNTA('4℃飯'!$D$5:$D$304) -> 0 | F13: =IF($F$5=0,0,E13/$F$5) -> 0
B14: 4℃麵 | C14: =MAX('4℃麵'!$AA$5:$AA$292) -> 26 | D14: =IF($F$4=0,0,C14/$F$4) -> 0.65 | E14: =COUNTA('4℃麵'!$E$5:$E$292) -> 148 | F14: =IF($F$5=0,0,E14/$F$5) -> 0.74747475
B15: 4℃其他 | C15: =MAX('4℃其他'!$AA$5:$AA$304) -> 5 | D15: =IF($F$4=0,0,C15/$F$4) -> 0.125 | E15: =COUNTA('4℃其他'!$E$5:$E$304) -> 21 | F15: =IF($F$5=0,0,E15/$F$5) -> 0.10606061
B16: 冷凍品 | C16: =MAX(冷凍品!$AA$5:$AA$304) -> 9 | D16: =IF($F$4=0,0,C16/$F$4) -> 0.225 | E16: =COUNTA(冷凍品!$E$5:$E$304) -> 29 | F16: =IF($F$5=0,0,E16/$F$5) -> 0.14646465
B17: 合計 | C17: =SUM(C12:C16) -> 40 | E17: =SUM(E12:E16) -> 198
B19: 商品目錄（自動列出各分頁不重複品項，勿手動修改）
B20: 18℃ | C20: 4℃飯 | D20: 4℃麵 | E20: 4℃其他 | F20: 冷凍品
B21: ="品項數："&MAX('18℃'!$Z$5:$Z$304) -> 品項數：0 | C21: ="品項數："&MAX('4℃飯'!$Z$5:$Z$304) -> 品項數：0 | D21: ="品項數："&MAX('4℃麵'!$AA$5:$AA$292) -> 品項數：26 | E21: ="品項數："&MAX('4℃其他'!$AA$5:$AA$304) -> 品項數：5 | F21: ="品項數："&MAX(冷凍品!$AA$5:$AA$304) -> 品項數：9
B22: =IF(1>MAX('18℃'!$Z$5:$Z$304),"",HYPERLINK("#'18℃'!C"&(MATCH(1,'18℃'!$Z$5:$Z$304,0)+4),INDEX('18℃'!$C$5:$C$304,MATCH(1,'18℃'!$Z$5:$Z$304,0)))) | C22: =IF(1>MAX('4℃飯'!$Z$5:$Z$304),"",HYPERLINK("#'4℃飯'!C"&(MATCH(1,'4℃飯'!$Z$5:$Z$304,0)+4),INDEX('4℃飯'!$C$5:$C$304,MATCH(1,'4℃飯'!$Z$5:$Z$304,0)))) | D22: =IF(1>MAX('4℃麵'!$AA$5:$AA$292),"",HYPERLINK("#'4℃麵'!D"&(MATCH(1,'4℃麵'!$AA$5:$AA$292,0)+4),INDEX('4℃麵'!$D$5:$D$292,MATCH(1,'4℃麵'!$AA$5:$AA$292,0)))) -> 金沙豆腐義大利麵 | E22: =IF(1>MAX('4℃其他'!$AA$5:$AA$304),"",HYPERLINK("#'4℃其他'!D"&(MATCH(1,'4℃其他'!$AA$5:$AA$304,0)+4),INDEX('4℃其他'!$D$5:$D$304,MATCH(1,'4℃其他'!$AA$5:$AA$304,0)))) -> 韓式炒冬粉 | F22: =IF(1>MAX('冷凍品'!$AA$5:$AA$304),"",HYPERLINK("#'冷凍品'!D"&(MATCH(1,'冷凍品'!$AA$5:$AA$304,0)+4),INDEX('冷凍品'!$D$5:$D$304,MATCH(1,'冷凍品'!$AA$5:$AA$304,0)))) -> 奶油蘑菇培根義大利麵
B23: =IF(2>MAX('18℃'!$Z$5:$Z$304),"",HYPERLINK("#'18℃'!C"&(MATCH(2,'18℃'!$Z$5:$Z$304,0)+4),INDEX('18℃'!$C$5:$C$304,MATCH(2,'18℃'!$Z$5:$Z$304,0)))) | C23: =IF(2>MAX('4℃飯'!$Z$5:$Z$304),"",HYPERLINK("#'4℃飯'!C"&(MATCH(2,'4℃飯'!$Z$5:$Z$304,0)+4),INDEX('4℃飯'!$C$5:$C$304,MATCH(2,'4℃飯'!$Z$5:$Z$304,0)))) | D23: =IF(2>MAX('4℃麵'!$AA$5:$AA$292),"",HYPERLINK("#'4℃麵'!D"&(MATCH(2,'4℃麵'!$AA$5:$AA$292,0)+4),INDEX('4℃麵'!$D$5:$D$292,MATCH(2,'4℃麵'!$AA$5:$AA$292,0)))) -> 奶油培根義大利麵RN | E23: =IF(2>MAX('4℃其他'!$AA$5:$AA$304),"",HYPERLINK("#'4℃其他'!D"&(MATCH(2,'4℃其他'!$AA$5:$AA$304,0)+4),INDEX('4℃其他'!$D$5:$D$304,MATCH(2,'4℃其他'!$AA$5:$AA$304,0)))) -> 小滷青蔬 | F23: =IF(2>MAX('冷凍品'!$AA$5:$AA$304),"",HYPERLINK("#'冷凍品'!D"&(MATCH(2,'冷凍品'!$AA$5:$AA$304,0)+4),INDEX('冷凍品'!$D$5:$D$304,MATCH(2,'冷凍品'!$AA$5:$AA$304,0)))) -> 青醬蛤蜊義大利麵
B24: =IF(3>MAX('18℃'!$Z$5:$Z$304),"",HYPERLINK("#'18℃'!C"&(MATCH(3,'18℃'!$Z$5:$Z$304,0)+4),INDEX('18℃'!$C$5:$C$304,MATCH(3,'18℃'!$Z$5:$Z$304,0)))) | C24: =IF(3>MAX('4℃飯'!$Z$5:$Z$304),"",HYPERLINK("#'4℃飯'!C"&(MATCH(3,'4℃飯'!$Z$5:$Z$304,0)+4),INDEX('4℃飯'!$C$5:$C$304,MATCH(3,'4℃飯'!$Z$5:$Z$304,0)))) | D24: =IF(3>MAX('4℃麵'!$AA$5:$AA$292),"",HYPERLINK("#'4℃麵'!D"&(MATCH(3,'4℃麵'!$AA$5:$AA$292,0)+4),INDEX('4℃麵'!$D$5:$D$292,MATCH(3,'4℃麵'!$AA$5:$AA$292,0)))) -> 奶油鮮蝦明太子細扁麵 | E24: =IF(3>MAX('4℃其他'!$AA$5:$AA$304),"",HYPERLINK("#'4℃其他'!D"&(MATCH(3,'4℃其他'!$AA$5:$AA$304,0)+4),INDEX('4℃其他'!$D$5:$D$304,MATCH(3,'4℃其他'!$AA$5:$AA$304,0)))) -> 香濃起司馬鈴薯 | F24: =IF(3>MAX('冷凍品'!$AA$5:$AA$304),"",HYPERLINK("#'冷凍品'!D"&(MATCH(3,'冷凍品'!$AA$5:$AA$304,0)+4),INDEX('冷凍品'!$D$5:$D$304,MATCH(3,'冷凍品'!$AA$5:$AA$304,0)))) -> 剝皮辣椒細扁麵
B25: =IF(4>MAX('18℃'!$Z$5:$Z$304),"",HYPERLINK("#'18℃'!C"&(MATCH(4,'18℃'!$Z$5:$Z$304,0)+4),INDEX('18℃'!$C$5:$C$304,MATCH(4,'18℃'!$Z$5:$Z$304,0)))) | C25: =IF(4>MAX('4℃飯'!$Z$5:$Z$304),"",HYPERLINK("#'4℃飯'!C"&(MATCH(4,'4℃飯'!$Z$5:$Z$304,0)+4),INDEX('4℃飯'!$C$5:$C$304,MATCH(4,'4℃飯'!$Z$5:$Z$304,0)))) | D25: =IF(4>MAX('4℃麵'!$AA$5:$AA$292),"",HYPERLINK("#'4℃麵'!D"&(MATCH(4,'4℃麵'!$AA$5:$AA$292,0)+4),INDEX('4℃麵'!$D$5:$D$292,MATCH(4,'4℃麵'!$AA$5:$AA$292,0)))) -> 白酒清炒鮮蛤義大利麵 | E25: =IF(4>MAX('4℃其他'!$AA$5:$AA$304),"",HYPERLINK("#'4℃其他'!D"&(MATCH(4,'4℃其他'!$AA$5:$AA$304,0)+4),INDEX('4℃其他'!$D$5:$D$304,MATCH(4,'4℃其他'!$AA$5:$AA$304,0)))) -> 台式蒜味小寬粉 | F25: =IF(4>MAX('冷凍品'!$AA$5:$AA$304),"",HYPERLINK("#'冷凍品'!D"&(MATCH(4,'冷凍品'!$AA$5:$AA$304,0)+4),INDEX('冷凍品'!$D$5:$D$304,MATCH(4,'冷凍品'!$AA$5:$AA$304,0)))) -> 清炒蛤蜊義大利麵
B26: =IF(5>MAX('18℃'!$Z$5:$Z$304),"",HYPERLINK("#'18℃'!C"&(MATCH(5,'18℃'!$Z$5:$Z$304,0)+4),INDEX('18℃'!$C$5:$C$304,MATCH(5,'18℃'!$Z$5:$Z$304,0)))) | C26: =IF(5>MAX('4℃飯'!$Z$5:$Z$304),"",HYPERLINK("#'4℃飯'!C"&(MATCH(5,'4℃飯'!$Z$5:$Z$304,0)+4),INDEX('4℃飯'!$C$5:$C$304,MATCH(5,'4℃飯'!$Z$5:$Z$304,0)))) | D26: =IF(5>MAX('4℃麵'!$AA$5:$AA$292),"",HYPERLINK("#'4℃麵'!D"&(MATCH(5,'4℃麵'!$AA$5:$AA$292,0)+4),INDEX('4℃麵'!$D$5:$D$292,MATCH(5,'4℃麵'!$AA$5:$AA$292,0)))) -> 沙茶豬肉炒麵 | E26: =IF(5>MAX('4℃其他'!$AA$5:$AA$304),"",HYPERLINK("#'4℃其他'!D"&(MATCH(5,'4℃其他'!$AA$5:$AA$304,0)+4),INDEX('4℃其他'!$D$5:$D$304,MATCH(5,'4℃其他'!$AA$5:$AA$304,0)))) -> 麻辣雞心 | F26: =IF(5>MAX('冷凍品'!$AA$5:$AA$304),"",HYPERLINK("#'冷凍品'!D"&(MATCH(5,'冷凍品'!$AA$5:$AA$304,0)+4),INDEX('冷凍品'!$D$5:$D$304,MATCH(5,'冷凍品'!$AA$5:$AA$304,0)))) -> 經典肉醬義大利麵
B27: =IF(6>MAX('18℃'!$Z$5:$Z$304),"",HYPERLINK("#'18℃'!C"&(MATCH(6,'18℃'!$Z$5:$Z$304,0)+4),INDEX('18℃'!$C$5:$C$304,MATCH(6,'18℃'!$Z$5:$Z$304,0)))) | C27: =IF(6>MAX('4℃飯'!$Z$5:$Z$304),"",HYPERLINK("#'4℃飯'!C"&(MATCH(6,'4℃飯'!$Z$5:$Z$304,0)+4),INDEX('4℃飯'!$C$5:$C$304,MATCH(6,'4℃飯'!$Z$5:$Z$304,0)))) | D27: =IF(6>MAX('4℃麵'!$AA$5:$AA$292),"",HYPERLINK("#'4℃麵'!D"&(MATCH(6,'4℃麵'!$AA$5:$AA$292,0)+4),INDEX('4℃麵'!$D$5:$D$292,MATCH(6,'4℃麵'!$AA$5:$AA$292,0)))) -> 府城鹽水意麵 | E27: =IF(6>MAX('4℃其他'!$AA$5:$AA$304),"",HYPERLINK("#'4℃其他'!D"&(MATCH(6,'4℃其他'!$AA$5:$AA$304,0)+4),INDEX('4℃其他'!$D$5:$D$304,MATCH(6,'4℃其他'!$AA$5:$AA$304,0)))) | F27: =IF(6>MAX('冷凍品'!$AA$5:$AA$304),"",HYPERLINK("#'冷凍品'!D"&(MATCH(6,'冷凍品'!$AA$5:$AA$304,0)+4),INDEX('冷凍品'!$D$5:$D$304,MATCH(6,'冷凍品'!$AA$5:$AA$304,0)))) -> 辣蕃茄義大利麵
B28: =IF(7>MAX('18℃'!$Z$5:$Z$304),"",HYPERLINK("#'18℃'!C"&(MATCH(7,'18℃'!$Z$5:$Z$304,0)+4),INDEX('18℃'!$C$5:$C$304,MATCH(7,'18℃'!$Z$5:$Z$304,0)))) | C28: =IF(7>MAX('4℃飯'!$Z$5:$Z$304),"",HYPERLINK("#'4℃飯'!C"&(MATCH(7,'4℃飯'!$Z$5:$Z$304,0)+4),INDEX('4℃飯'!$C$5:$C$304,MATCH(7,'4℃飯'!$Z$5:$Z$304,0)))) | D28: =IF(7>MAX('4℃麵'!$AA$5:$AA$292),"",HYPERLINK("#'4℃麵'!D"&(MATCH(7,'4℃麵'!$AA$5:$AA$292,0)+4),INDEX('4℃麵'!$D$5:$D$292,MATCH(7,'4℃麵'!$AA$5:$AA$292,0)))) -> 青花椒麻雞肉拌麵 | E28: =IF(7>MAX('4℃其他'!$AA$5:$AA$304),"",HYPERLINK("#'4℃其他'!D"&(MATCH(7,'4℃其他'!$AA$5:$AA$304,0)+4),INDEX('4℃其他'!$D$5:$D$304,MATCH(7,'4℃其他'!$AA$5:$AA$304,0)))) | F28: =IF(7>MAX('冷凍品'!$AA$5:$AA$304),"",HYPERLINK("#'冷凍品'!D"&(MATCH(7,'冷凍品'!$AA$5:$AA$304,0)+4),INDEX('冷凍品'!$D$5:$D$304,MATCH(7,'冷凍品'!$AA$5:$AA$304,0)))) -> 濃郁牛肉肉醬義大利麵
B29: =IF(8>MAX('18℃'!$Z$5:$Z$304),"",HYPERLINK("#'18℃'!C"&(MATCH(8,'18℃'!$Z$5:$Z$304,0)+4),INDEX('18℃'!$C$5:$C$304,MATCH(8,'18℃'!$Z$5:$Z$304,0)))) | C29: =IF(8>MAX('4℃飯'!$Z$5:$Z$304),"",HYPERLINK("#'4℃飯'!C"&(MATCH(8,'4℃飯'!$Z$5:$Z$304,0)+4),INDEX('4℃飯'!$C$5:$C$304,MATCH(8,'4℃飯'!$Z$5:$Z$304,0)))) | D29: =IF(8>MAX('4℃麵'!$AA$5:$AA$292),"",HYPERLINK("#'4℃麵'!D"&(MATCH(8,'4℃麵'!$AA$5:$AA$292,0)+4),INDEX('4℃麵'!$D$5:$D$292,MATCH(8,'4℃麵'!$AA$5:$AA$292,0)))) -> 青醬蛤蜊義大利麵RN | E29: =IF(8>MAX('4℃其他'!$AA$5:$AA$304),"",HYPERLINK("#'4℃其他'!D"&(MATCH(8,'4℃其他'!$AA$5:$AA$304,0)+4),INDEX('4℃其他'!$D$5:$D$304,MATCH(8,'4℃其他'!$AA$5:$AA$304,0)))) | F29: =IF(8>MAX('冷凍品'!$AA$5:$AA$304),"",HYPERLINK("#'冷凍品'!D"&(MATCH(8,'冷凍品'!$AA$5:$AA$304,0)+4),INDEX('冷凍品'!$D$5:$D$304,MATCH(8,'冷凍品'!$AA$5:$AA$304,0)))) -> 韓式起司義大利麵
B30: =IF(9>MAX('18℃'!$Z$5:$Z$304),"",HYPERLINK("#'18℃'!C"&(MATCH(9,'18℃'!$Z$5:$Z$304,0)+4),INDEX('18℃'!$C$5:$C$304,MATCH(9,'18℃'!$Z$5:$Z$304,0)))) | C30: =IF(9>MAX('4℃飯'!$Z$5:$Z$304),"",HYPERLINK("#'4℃飯'!C"&(MATCH(9,'4℃飯'!$Z$5:$Z$304,0)+4),INDEX('4℃飯'!$C$5:$C$304,MATCH(9,'4℃飯'!$Z$5:$Z$304,0)))) | D30: =IF(9>MAX('4℃麵'!$AA$5:$AA$292),"",HYPERLINK("#'4℃麵'!D"&(MATCH(9,'4℃麵'!$AA$5:$AA$292,0)+4),INDEX('4℃麵'!$D$5:$D$292,MATCH(9,'4℃麵'!$AA$5:$AA$292,0)))) -> 香煎魚排佐檸檬奶油義大利麵 | E30: =IF(9>MAX('4℃其他'!$AA$5:$AA$304),"",HYPERLINK("#'4℃其他'!D"&(MATCH(9,'4℃其他'!$AA$5:$AA$304,0)+4),INDEX('4℃其他'!$D$5:$D$304,MATCH(9,'4℃其他'!$AA$5:$AA$304,0)))) | F30: =IF(9>MAX('冷凍品'!$AA$5:$AA$304),"",HYPERLINK("#'冷凍品'!D"&(MATCH(9,'冷凍品'!$AA$5:$AA$304,0)+4),INDEX('冷凍品'!$D$5:$D$304,MATCH(9,'冷凍品'!$AA$5:$AA$304,0)))) -> (冷凍)黑松露野菇義大利麵
B31: =IF(10>MAX('18℃'!$Z$5:$Z$304),"",HYPERLINK("#'18℃'!C"&(MATCH(10,'18℃'!$Z$5:$Z$304,0)+4),INDEX('18℃'!$C$5:$C$304,MATCH(10,'18℃'!$Z$5:$Z$304,0)))) | C31: =IF(10>MAX('4℃飯'!$Z$5:$Z$304),"",HYPERLINK("#'4℃飯'!C"&(MATCH(10,'4℃飯'!$Z$5:$Z$304,0)+4),INDEX('4℃飯'!$C$5:$C$304,MATCH(10,'4℃飯'!$Z$5:$Z$304,0)))) | D31: =IF(10>MAX('4℃麵'!$AA$5:$AA$292),"",HYPERLINK("#'4℃麵'!D"&(MATCH(10,'4℃麵'!$AA$5:$AA$292,0)+4),INDEX('4℃麵'!$D$5:$D$292,MATCH(10,'4℃麵'!$AA$5:$AA$292,0)))) -> 焗烤起司雙饗筆尖麵 | E31: =IF(10>MAX('4℃其他'!$AA$5:$AA$304),"",HYPERLINK("#'4℃其他'!D"&(MATCH(10,'4℃其他'!$AA$5:$AA$304,0)+4),INDEX('4℃其他'!$D$5:$D$304,MATCH(10,'4℃其他'!$AA$5:$AA$304,0)))) | F31: =IF(10>MAX('冷凍品'!$AA$5:$AA$304),"",HYPERLINK("#'冷凍品'!D"&(MATCH(10,'冷凍品'!$AA$5:$AA$304,0)+4),INDEX('冷凍品'!$D$5:$D$304,MATCH(10,'冷凍品'!$AA$5:$AA$304,0))))
B32: =IF(11>MAX('18℃'!$Z$5:$Z$304),"",HYPERLINK("#'18℃'!C"&(MATCH(11,'18℃'!$Z$5:$Z$304,0)+4),INDEX('18℃'!$C$5:$C$304,MATCH(11,'18℃'!$Z$5:$Z$304,0)))) | C32: =IF(11>MAX('4℃飯'!$Z$5:$Z$304),"",HYPERLINK("#'4℃飯'!C"&(MATCH(11,'4℃飯'!$Z$5:$Z$304,0)+4),INDEX('4℃飯'!$C$5:$C$304,MATCH(11,'4℃飯'!$Z$5:$Z$304,0)))) | D32: =IF(11>MAX('4℃麵'!$AA$5:$AA$292),"",HYPERLINK("#'4℃麵'!D"&(MATCH(11,'4℃麵'!$AA$5:$AA$292,0)+4),INDEX('4℃麵'!$D$5:$D$292,MATCH(11,'4℃麵'!$AA$5:$AA$292,0)))) -> 黑松露野菇義大利麵 | E32: =IF(11>MAX('4℃其他'!$AA$5:$AA$304),"",HYPERLINK("#'4℃其他'!D"&(MATCH(11,'4℃其他'!$AA$5:$AA$304,0)+4),INDEX('4℃其他'!$D$5:$D$304,MATCH(11,'4℃其他'!$AA$5:$AA$304,0)))) | F32: =IF(11>MAX('冷凍品'!$AA$5:$AA$304),"",HYPERLINK("#'冷凍品'!D"&(MATCH(11,'冷凍品'!$AA$5:$AA$304,0)+4),INDEX('冷凍品'!$D$5:$D$304,MATCH(11,'冷凍品'!$AA$5:$AA$304,0))))
B33: =IF(12>MAX('18℃'!$Z$5:$Z$304),"",HYPERLINK("#'18℃'!C"&(MATCH(12,'18℃'!$Z$5:$Z$304,0)+4),INDEX('18℃'!$C$5:$C$304,MATCH(12,'18℃'!$Z$5:$Z$304,0)))) | C33: =IF(12>MAX('4℃飯'!$Z$5:$Z$304),"",HYPERLINK("#'4℃飯'!C"&(MATCH(12,'4℃飯'!$Z$5:$Z$304,0)+4),INDEX('4℃飯'!$C$5:$C$304,MATCH(12,'4℃飯'!$Z$5:$Z$304,0)))) | D33: =IF(12>MAX('4℃麵'!$AA$5:$AA$292),"",HYPERLINK("#'4℃麵'!D"&(MATCH(12,'4℃麵'!$AA$5:$AA$292,0)+4),INDEX('4℃麵'!$D$5:$D$292,MATCH(12,'4℃麵'!$AA$5:$AA$292,0)))) -> 義式蛋蛋青醬鮪魚冷義大利麵 | E33: =IF(12>MAX('4℃其他'!$AA$5:$AA$304),"",HYPERLINK("#'4℃其他'!D"&(MATCH(12,'4℃其他'!$AA$5:$AA$304,0)+4),INDEX('4℃其他'!$D$5:$D$304,MATCH(12,'4℃其他'!$AA$5:$AA$304,0)))) | F33: =IF(12>MAX('冷凍品'!$AA$5:$AA$304),"",HYPERLINK("#'冷凍品'!D"&(MATCH(12,'冷凍品'!$AA$5:$AA$304,0)+4),INDEX('冷凍品'!$D$5:$D$304,MATCH(12,'冷凍品'!$AA$5:$AA$304,0))))
B34: =IF(13>MAX('18℃'!$Z$5:$Z$304),"",HYPERLINK("#'18℃'!C"&(MATCH(13,'18℃'!$Z$5:$Z$304,0)+4),INDEX('18℃'!$C$5:$C$304,MATCH(13,'18℃'!$Z$5:$Z$304,0)))) | C34: =IF(13>MAX('4℃飯'!$Z$5:$Z$304),"",HYPERLINK("#'4℃飯'!C"&(MATCH(13,'4℃飯'!$Z$5:$Z$304,0)+4),INDEX('4℃飯'!$C$5:$C$304,MATCH(13,'4℃飯'!$Z$5:$Z$304,0)))) | D34: =IF(13>MAX('4℃麵'!$AA$5:$AA$292),"",HYPERLINK("#'4℃麵'!D"&(MATCH(13,'4℃麵'!$AA$5:$AA$292,0)+4),INDEX('4℃麵'!$D$5:$D$292,MATCH(13,'4℃麵'!$AA$5:$AA$292,0)))) -> 義式蕃茄起司義大利麵 | E34: =IF(13>MAX('4℃其他'!$AA$5:$AA$304),"",HYPERLINK("#'4℃其他'!D"&(MATCH(13,'4℃其他'!$AA$5:$AA$304,0)+4),INDEX('4℃其他'!$D$5:$D$304,MATCH(13,'4℃其他'!$AA$5:$AA$304,0)))) | F34: =IF(13>MAX('冷凍品'!$AA$5:$AA$304),"",HYPERLINK("#'冷凍品'!D"&(MATCH(13,'冷凍品'!$AA$5:$AA$304,0)+4),INDEX('冷凍品'!$D$5:$D$304,MATCH(13,'冷凍品'!$AA$5:$AA$304,0))))
B35: =IF(14>MAX('18℃'!$Z$5:$Z$304),"",HYPERLINK("#'18℃'!C"&(MATCH(14,'18℃'!$Z$5:$Z$304,0)+4),INDEX('18℃'!$C$5:$C$304,MATCH(14,'18℃'!$Z$5:$Z$304,0)))) | C35: =IF(14>MAX('4℃飯'!$Z$5:$Z$304),"",HYPERLINK("#'4℃飯'!C"&(MATCH(14,'4℃飯'!$Z$5:$Z$304,0)+4),INDEX('4℃飯'!$C$5:$C$304,MATCH(14,'4℃飯'!$Z$5:$Z$304,0)))) | D35: =IF(14>MAX('4℃麵'!$AA$5:$AA$292),"",HYPERLINK("#'4℃麵'!D"&(MATCH(14,'4℃麵'!$AA$5:$AA$292,0)+4),INDEX('4℃麵'!$D$5:$D$292,MATCH(14,'4℃麵'!$AA$5:$AA$292,0)))) -> 蒜香奶油蝦蝦義大利麵 | E35: =IF(14>MAX('4℃其他'!$AA$5:$AA$304),"",HYPERLINK("#'4℃其他'!D"&(MATCH(14,'4℃其他'!$AA$5:$AA$304,0)+4),INDEX('4℃其他'!$D$5:$D$304,MATCH(14,'4℃其他'!$AA$5:$AA$304,0)))) | F35: =IF(14>MAX('冷凍品'!$AA$5:$AA$304),"",HYPERLINK("#'冷凍品'!D"&(MATCH(14,'冷凍品'!$AA$5:$AA$304,0)+4),INDEX('冷凍品'!$D$5:$D$304,MATCH(14,'冷凍品'!$AA$5:$AA$304,0))))
B36: =IF(15>MAX('18℃'!$Z$5:$Z$304),"",HYPERLINK("#'18℃'!C"&(MATCH(15,'18℃'!$Z$5:$Z$304,0)+4),INDEX('18℃'!$C$5:$C$304,MATCH(15,'18℃'!$Z$5:$Z$304,0)))) | C36: =IF(15>MAX('4℃飯'!$Z$5:$Z$304),"",HYPERLINK("#'4℃飯'!C"&(MATCH(15,'4℃飯'!$Z$5:$Z$304,0)+4),INDEX('4℃飯'!$C$5:$C$304,MATCH(15,'4℃飯'!$Z$5:$Z$304,0)))) | D36: =IF(15>MAX('4℃麵'!$AA$5:$AA$292),"",HYPERLINK("#'4℃麵'!D"&(MATCH(15,'4℃麵'!$AA$5:$AA$292,0)+4),INDEX('4℃麵'!$D$5:$D$292,MATCH(15,'4℃麵'!$AA$5:$AA$292,0)))) -> 蕃茄莎莎海鮮冷義大利麵 | E36: =IF(15>MAX('4℃其他'!$AA$5:$AA$304),"",HYPERLINK("#'4℃其他'!D"&(MATCH(15,'4℃其他'!$AA$5:$AA$304,0)+4),INDEX('4℃其他'!$D$5:$D$304,MATCH(15,'4℃其他'!$AA$5:$AA$304,0)))) | F36: =IF(15>MAX('冷凍品'!$AA$5:$AA$304),"",HYPERLINK("#'冷凍品'!D"&(MATCH(15,'冷凍品'!$AA$5:$AA$304,0)+4),INDEX('冷凍品'!$D$5:$D$304,MATCH(15,'冷凍品'!$AA$5:$AA$304,0))))
B37: =IF(16>MAX('18℃'!$Z$5:$Z$304),"",HYPERLINK("#'18℃'!C"&(MATCH(16,'18℃'!$Z$5:$Z$304,0)+4),INDEX('18℃'!$C$5:$C$304,MATCH(16,'18℃'!$Z$5:$Z$304,0)))) | C37: =IF(16>MAX('4℃飯'!$Z$5:$Z$304),"",HYPERLINK("#'4℃飯'!C"&(MATCH(16,'4℃飯'!$Z$5:$Z$304,0)+4),INDEX('4℃飯'!$C$5:$C$304,MATCH(16,'4℃飯'!$Z$5:$Z$304,0)))) | D37: =IF(16>MAX('4℃麵'!$AA$5:$AA$292),"",HYPERLINK("#'4℃麵'!D"&(MATCH(16,'4℃麵'!$AA$5:$AA$292,0)+4),INDEX('4℃麵'!$D$5:$D$292,MATCH(16,'4℃麵'!$AA$5:$AA$292,0)))) -> 羅馬黑胡椒起司義大利麵 | E37: =IF(16>MAX('4℃其他'!$AA$5:$AA$304),"",HYPERLINK("#'4℃其他'!D"&(MATCH(16,'4℃其他'!$AA$5:$AA$304,0)+4),INDEX('4℃其他'!$D$5:$D$304,MATCH(16,'4℃其他'!$AA$5:$AA$304,0)))) | F37: =IF(16>MAX('冷凍品'!$AA$5:$AA$304),"",HYPERLINK("#'冷凍品'!D"&(MATCH(16,'冷凍品'!$AA$5:$AA$304,0)+4),INDEX('冷凍品'!$D$5:$D$304,MATCH(16,'冷凍品'!$AA$5:$AA$304,0))))
B38: =IF(17>MAX('18℃'!$Z$5:$Z$304),"",HYPERLINK("#'18℃'!C"&(MATCH(17,'18℃'!$Z$5:$Z$304,0)+4),INDEX('18℃'!$C$5:$C$304,MATCH(17,'18℃'!$Z$5:$Z$304,0)))) | C38: =IF(17>MAX('4℃飯'!$Z$5:$Z$304),"",HYPERLINK("#'4℃飯'!C"&(MATCH(17,'4℃飯'!$Z$5:$Z$304,0)+4),INDEX('4℃飯'!$C$5:$C$304,MATCH(17,'4℃飯'!$Z$5:$Z$304,0)))) | D38: =IF(17>MAX('4℃麵'!$AA$5:$AA$292),"",HYPERLINK("#'4℃麵'!D"&(MATCH(17,'4℃麵'!$AA$5:$AA$292,0)+4),INDEX('4℃麵'!$D$5:$D$292,MATCH(17,'4℃麵'!$AA$5:$AA$292,0)))) -> 鱈魚佐粉紅青醬筆尖麵 | E38: =IF(17>MAX('4℃其他'!$AA$5:$AA$304),"",HYPERLINK("#'4℃其他'!D"&(MATCH(17,'4℃其他'!$AA$5:$AA$304,0)+4),INDEX('4℃其他'!$D$5:$D$304,MATCH(17,'4℃其他'!$AA$5:$AA$304,0)))) | F38: =IF(17>MAX('冷凍品'!$AA$5:$AA$304),"",HYPERLINK("#'冷凍品'!D"&(MATCH(17,'冷凍品'!$AA$5:$AA$304,0)+4),INDEX('冷凍品'!$D$5:$D$304,MATCH(17,'冷凍品'!$AA$5:$AA$304,0))))
B39: =IF(18>MAX('18℃'!$Z$5:$Z$304),"",HYPERLINK("#'18℃'!C"&(MATCH(18,'18℃'!$Z$5:$Z$304,0)+4),INDEX('18℃'!$C$5:$C$304,MATCH(18,'18℃'!$Z$5:$Z$304,0)))) | C39: =IF(18>MAX('4℃飯'!$Z$5:$Z$304),"",HYPERLINK("#'4℃飯'!C"&(MATCH(18,'4℃飯'!$Z$5:$Z$304,0)+4),INDEX('4℃飯'!$C$5:$C$304,MATCH(18,'4℃飯'!$Z$5:$Z$304,0)))) | D39: =IF(18>MAX('4℃麵'!$AA$5:$AA$292),"",HYPERLINK("#'4℃麵'!D"&(MATCH(18,'4℃麵'!$AA$5:$AA$292,0)+4),INDEX('4℃麵'!$D$5:$D$292,MATCH(18,'4℃麵'!$AA$5:$AA$292,0)))) -> 燻鴨佐白蘭地義大利麵 | E39: =IF(18>MAX('4℃其他'!$AA$5:$AA$304),"",HYPERLINK("#'4℃其他'!D"&(MATCH(18,'4℃其他'!$AA$5:$AA$304,0)+4),INDEX('4℃其他'!$D$5:$D$304,MATCH(18,'4℃其他'!$AA$5:$AA$304,0)))) | F39: =IF(18>MAX('冷凍品'!$AA$5:$AA$304),"",HYPERLINK("#'冷凍品'!D"&(MATCH(18,'冷凍品'!$AA$5:$AA$304,0)+4),INDEX('冷凍品'!$D$5:$D$304,MATCH(18,'冷凍品'!$AA$5:$AA$304,0))))
B40: =IF(19>MAX('18℃'!$Z$5:$Z$304),"",HYPERLINK("#'18℃'!C"&(MATCH(19,'18℃'!$Z$5:$Z$304,0)+4),INDEX('18℃'!$C$5:$C$304,MATCH(19,'18℃'!$Z$5:$Z$304,0)))) | C40: =IF(19>MAX('4℃飯'!$Z$5:$Z$304),"",HYPERLINK("#'4℃飯'!C"&(MATCH(19,'4℃飯'!$Z$5:$Z$304,0)+4),INDEX('4℃飯'!$C$5:$C$304,MATCH(19,'4℃飯'!$Z$5:$Z$304,0)))) | D40: =IF(19>MAX('4℃麵'!$AA$5:$AA$292),"",HYPERLINK("#'4℃麵'!D"&(MATCH(19,'4℃麵'!$AA$5:$AA$292,0)+4),INDEX('4℃麵'!$D$5:$D$292,MATCH(19,'4℃麵'!$AA$5:$AA$292,0)))) -> 拿坡里燻腸義大利麵 | E40: =IF(19>MAX('4℃其他'!$AA$5:$AA$304),"",HYPERLINK("#'4℃其他'!D"&(MATCH(19,'4℃其他'!$AA$5:$AA$304,0)+4),INDEX('4℃其他'!$D$5:$D$304,MATCH(19,'4℃其他'!$AA$5:$AA$304,0)))) | F40: =IF(19>MAX('冷凍品'!$AA$5:$AA$304),"",HYPERLINK("#'冷凍品'!D"&(MATCH(19,'冷凍品'!$AA$5:$AA$304,0)+4),INDEX('冷凍品'!$D$5:$D$304,MATCH(19,'冷凍品'!$AA$5:$AA$304,0))))
B41: =IF(20>MAX('18℃'!$Z$5:$Z$304),"",HYPERLINK("#'18℃'!C"&(MATCH(20,'18℃'!$Z$5:$Z$304,0)+4),INDEX('18℃'!$C$5:$C$304,MATCH(20,'18℃'!$Z$5:$Z$304,0)))) | C41: =IF(20>MAX('4℃飯'!$Z$5:$Z$304),"",HYPERLINK("#'4℃飯'!C"&(MATCH(20,'4℃飯'!$Z$5:$Z$304,0)+4),INDEX('4℃飯'!$C$5:$C$304,MATCH(20,'4℃飯'!$Z$5:$Z$304,0)))) | D41: =IF(20>MAX('4℃麵'!$AA$5:$AA$292),"",HYPERLINK("#'4℃麵'!D"&(MATCH(20,'4℃麵'!$AA$5:$AA$292,0)+4),INDEX('4℃麵'!$D$5:$D$292,MATCH(20,'4℃麵'!$AA$5:$AA$292,0)))) -> 卡波納拉義大利麵 | E41: =IF(20>MAX('4℃其他'!$AA$5:$AA$304),"",HYPERLINK("#'4℃其他'!D"&(MATCH(20,'4℃其他'!$AA$5:$AA$304,0)+4),INDEX('4℃其他'!$D$5:$D$304,MATCH(20,'4℃其他'!$AA$5:$AA$304,0)))) | F41: =IF(20>MAX('冷凍品'!$AA$5:$AA$304),"",HYPERLINK("#'冷凍品'!D"&(MATCH(20,'冷凍品'!$AA$5:$AA$304,0)+4),INDEX('冷凍品'!$D$5:$D$304,MATCH(20,'冷凍品'!$AA$5:$AA$304,0))))
B42: =IF(21>MAX('18℃'!$Z$5:$Z$304),"",HYPERLINK("#'18℃'!C"&(MATCH(21,'18℃'!$Z$5:$Z$304,0)+4),INDEX('18℃'!$C$5:$C$304,MATCH(21,'18℃'!$Z$5:$Z$304,0)))) | C42: =IF(21>MAX('4℃飯'!$Z$5:$Z$304),"",HYPERLINK("#'4℃飯'!C"&(MATCH(21,'4℃飯'!$Z$5:$Z$304,0)+4),INDEX('4℃飯'!$C$5:$C$304,MATCH(21,'4℃飯'!$Z$5:$Z$304,0)))) | D42: =IF(21>MAX('4℃麵'!$AA$5:$AA$292),"",HYPERLINK("#'4℃麵'!D"&(MATCH(21,'4℃麵'!$AA$5:$AA$292,0)+4),INDEX('4℃麵'!$D$5:$D$292,MATCH(21,'4℃麵'!$AA$5:$AA$292,0)))) -> 義式蒜香鮮蝦義大利麵 | E42: =IF(21>MAX('4℃其他'!$AA$5:$AA$304),"",HYPERLINK("#'4℃其他'!D"&(MATCH(21,'4℃其他'!$AA$5:$AA$304,0)+4),INDEX('4℃其他'!$D$5:$D$304,MATCH(21,'4℃其他'!$AA$5:$AA$304,0)))) | F42: =IF(21>MAX('冷凍品'!$AA$5:$AA$304),"",HYPERLINK("#'冷凍品'!D"&(MATCH(21,'冷凍品'!$AA$5:$AA$304,0)+4),INDEX('冷凍品'!$D$5:$D$304,MATCH(21,'冷凍品'!$AA$5:$AA$304,0))))
B43: =IF(22>MAX('18℃'!$Z$5:$Z$304),"",HYPERLINK("#'18℃'!C"&(MATCH(22,'18℃'!$Z$5:$Z$304,0)+4),INDEX('18℃'!$C$5:$C$304,MATCH(22,'18℃'!$Z$5:$Z$304,0)))) | C43: =IF(22>MAX('4℃飯'!$Z$5:$Z$304),"",HYPERLINK("#'4℃飯'!C"&(MATCH(22,'4℃飯'!$Z$5:$Z$304,0)+4),INDEX('4℃飯'!$C$5:$C$304,MATCH(22,'4℃飯'!$Z$5:$Z$304,0)))) | D43: =IF(22>MAX('4℃麵'!$AA$5:$AA$292),"",HYPERLINK("#'4℃麵'!D"&(MATCH(22,'4℃麵'!$AA$5:$AA$292,0)+4),INDEX('4℃麵'!$D$5:$D$292,MATCH(22,'4℃麵'!$AA$5:$AA$292,0)))) -> 蕃茄蘑菇義大利麵 | E43: =IF(22>MAX('4℃其他'!$AA$5:$AA$304),"",HYPERLINK("#'4℃其他'!D"&(MATCH(22,'4℃其他'!$AA$5:$AA$304,0)+4),INDEX('4℃其他'!$D$5:$D$304,MATCH(22,'4℃其他'!$AA$5:$AA$304,0)))) | F43: =IF(22>MAX('冷凍品'!$AA$5:$AA$304),"",HYPERLINK("#'冷凍品'!D"&(MATCH(22,'冷凍品'!$AA$5:$AA$304,0)+4),INDEX('冷凍品'!$D$5:$D$304,MATCH(22,'冷凍品'!$AA$5:$AA$304,0))))
...

Sheet 填寫說明
B2: 商品半成品與調理設備應用展開一覽表｜填寫說明
B4: 目的 | C4: 盤點本廠商品之半成品組成，及各半成品應用之熱調理設備，據以掌握設備應用狀態（初步以「應用半成品數」衡量），並透過風險示警提前辨識設備依賴集中與資料缺漏。本檔為單一工廠使用，每廠一檔。
B6: 工作表結構 | C6: 「總覽」可點商品名稱跳至明細；五個溫層分頁填寫半成品與設備。「設備應用統計」自動彙總，僅藍字門檻可調整。
B7: 分頁歸類原則 | C7: 商品依販售溫層與品類歸入對應分頁；同一商品的所有半成品填在同一分頁。分頁內的「商品分類」欄可再填細分品類（如飯糰、壽司、便當、涼麵、甜點等）。
B9: 填寫規則 1 | C9: 填寫字體規範「微軟正黑體」，字體大小「10」號
B10: 填寫規則 2 | C10: 每一列代表「一個商品 × 一項半成品」。同一商品有 3 項半成品即填 3 列，且每列的工廠、商品名稱都要填（勿留空、勿合併儲存格），統計公式才能正確計算。
B11: 填寫規則 3 | C11: 有使用調理設備時，在該設備欄下拉選「V」。完全不經調理時，僅於「無使用調理設備」選「V」，不可同時勾選。
B12: 填寫規則 4 | C12: 單位用量分兩欄：「數值」填數字、「單位」下拉選公克或個。製程率直接填數字（如 92），系統自動顯示為 92%。尚未確認者可先留白，不影響設備統計。
B13: 填寫規則 5 | C13: 每列須填「建檔人員」，作為資料追溯窗口。「備註」請註記指示書編號與版本日期，依各分頁欄名填寫。
B14: 填寫規則 6 | C14: 最右側「系統用」隱藏欄自動計算商品目錄與品項數，請勿貼上數值或手動修改。
B16: 風險示警邏輯 | C16: 門檻可於「設備應用統計」C3:C5 藍字儲存格調整。檢核結果共五種狀態：
B17: ⚠ 資料缺漏（紅） | C17: 半成品已填名稱，但 11 個設備欄與「無使用調理設備」皆未勾選 → 須補填，或確認為免調理並勾選「無使用調理設備」。
B18: ⚠ 勾選矛盾（紅） | C18: 同時勾選「無使用調理設備」與任一設備欄 → 邏輯矛盾，請擇一修正。
... B25: 自動資料檢查 | C25: 以下以已填商品或半成品的資料列檢查。數量按明細列計，同一商品可有多列。
B26: 狀態未填（列） | C26: =SUM(COUNTIFS('4℃麵'!$D$5:$D$292,"<>",'4℃麵'!$A$5:$A$292,""),COUNTIFS('4℃其他'!$D$5:$D$304,"<>",'4℃其他'!$A$5:$A$304,""),COUNTIFS('冷凍品'!$D$5:$D$304,"<>",'冷凍品'!$A$5:$A$304,"")) -> 0
B27: 半成品名稱未填（列） | C27: =SUM(COUNTIFS('18℃'!$C$5:$C$304,"<>",'18℃'!$D$5:$D$304,""),COUNTIFS('4℃飯'!$C$5:$C$304,"<>",'4℃飯'!$D$5:$D$304,""),COUNTIFS('4℃麵'!$D$5:$D$292,"<>",'4℃麵'!$E$5:$E$292,""),COUNTIFS('4℃其他'!$D$5:$D$304,"<>",'4℃其他'!$E$5:$E$304,""),COUNTIFS('冷凍品'!$D$5:$D$304,"<>",'冷凍品'!$E$5:$E$304,"")) -> 0
B28: 設備未勾選（列） | C28: =SUM(COUNTIF('18℃'!$U$5:$U$304,"⚠ 資料缺漏"),COUNTIF('4℃飯'!$U$5:$U$304,"⚠ 資料缺漏"),COUNTIF('4℃麵'!$V$5:$V$292,"⚠ 資料缺漏"),COUNTIF('4℃其他'!$V$5:$V$304,"⚠ 資料缺漏"),COUNTIF('冷凍品'!$V$5:$V$304,"⚠ 資料缺漏")) -> 0
B29: 設備勾選矛盾（列） | C29: =SUM(COUNTIF('18℃'!$U$5:$U$304,"⚠ 勾選矛盾"),COUNTIF('4℃飯'!$U$5:$U$304,"⚠ 勾選矛盾"),COUNTIF('4℃麵'!$V$5:$V$292,"⚠ 勾選矛盾"),COUNTIF('4℃其他'!$V$5:$V$304,"⚠ 勾選矛盾"),COUNTIF('冷凍品'!$V$5:$V$304,"⚠ 勾選矛盾")) -> 0
B30: 建檔人員未填（列） | C30: =SUM(COUNTIFS('18℃'!$D$5:$D$304,"<>",'18℃'!$X$5:$X$304,""),COUNTIFS('4℃飯'!$D$5:$D$304,"<>",'4℃飯'!$X$5:$X$304,""),COUNTIFS('4℃麵'!$E$5:$E$292,"<>",'4℃麵'!$Y$5:$Y$292,""),COUNTIFS('4℃其他'!$E$5:$E$304,"<>",'4℃其他'!$Y$5:$Y$304,""),COUNTIFS('冷凍品'!$E$5:$E$304,"<>",'冷凍品'!$Y$5:$Y$304,"")) -> 140
B31: 工廠不符或未填（列） | C31: =SUM(COUNTIFS('18℃'!$D$5:$D$304,"<>",'18℃'!$A$5:$A$304,"<>長家"),COUNTIFS('4℃飯'!$D$5:$D$304,"<>",'4℃飯'!$A$5:$A$304,"<>長家"),COUNTIFS('4℃麵'!$E$5:$E$292,"<>",'4℃麵'!$B$5:$B$292,"<>長家"),COUNTIFS('4℃其他'!$E$5:$E$304,"<>",'4℃其他'!$B$5:$B$304,"<>長家"),COUNTIFS('冷凍品'!$E$5:$E$304,"<>",'冷凍品'!$B$5:$B$304,"<>長家")) -> 0
B32: 用量有值但單位未填（列） | C32: =SUM(COUNTIFS('18℃'!$D$5:$D$304,"<>",'18℃'!$E$5:$E$304,"<>",'18℃'!$F$5:$F$304,""),COUNTIFS('4℃飯'!$D$5:$D$304,"<>",'4℃飯'!$E$5:$E$304,"<>",'4℃飯'!$F$5:$F$304,""),COUNTIFS('4℃麵'!$E$5:$E$292,"<>",'4℃麵'!$F$5:$F$292,"<>",'4℃麵'!$G$5:$G$292,""),COUNTIFS('4℃其他'!$E$5:$E$304,"<>",'4℃其他'!$F$5:$F$304,"<>",'4℃其他'!$G$5:$G$304,""),COUNTIFS('冷凍品'!$E$5:$E$304,"<>",'冷凍品'!$F$5:$F$304,"<>",'冷凍品'!$G$5:$G$304,"")) -> 0
B34: 狀態判定基準 | C34: 本次已確認狀態依2026/10/14訂單與逐項確認結果。未上市商品保留待上架。後續更新需先確認訂單日期。
B35: 篩選與色彩 | C35: 狀態欄可篩選架上、下架、待上架。橘色表示狀態漏填或同商品不一致；淡黃表示建檔人員或單位待補。
B36: 批次更新同一商品 | C36: 先用商品名稱篩選，選取該商品可見的狀態儲存格，按 Alt+; 僅選可見儲存格，輸入狀態後按 Ctrl+Enter。
B37: 新增商品或半成品 | C37: 請在現有表格範圍內插入整列，再複製相鄰整列的格式、公式與選單，清除輸入資料後填寫新內容。
B38: 保留未確認內容 | C38: 未有依據的建檔人員、用量與單位不代填。未設狀態欄的分頁不納入狀態漏填檢查，既有「-」保留待確認。

Sheet 18℃
A1: 商品半成品與調理設備應用展開一覽表｜18℃
A2: 商品資訊 | H2: 熱調理區（使用者填「V」；免調理者勾最右欄） | T2: 自動計算與風險檢核（勿手動修改） | W2: 建檔資訊（手填）
A3: 工廠 | B3: 商品分類 (細分品類) | C3: 商品名稱 | D3: 半成品名稱 | E3: 單位用量 | G3: 製程率 (填數字) | H3: 炊飯 | I3: 煮麵 | J3: 烤箱 | K3: 炙燒 | L3: 蒸箱 | M3: 油炸機 | N3: 二重釜 | O3: 平釜 (日) | P3: 平釜 (台) | Q3: 蛋皮機 | R3: 壓力鍋 | S3: 無使用 調理設備 | T3: 使用 設備數 | U3: 檢核結果 | V3: 風險說明 | W3: 備註 (指示書編號/版本) | X3: 建檔人員 | Y3: 系統用Y | Z3: 系統用Z
E4: 數值 | F4: 單位
T5: =IF($D5="","",COUNTIF($H5:$R5,"V")) | U5: =IF($D5="","",IF(AND($S5="V",$T5>0),"⚠ 勾選矛盾",IF($S5="V","○ 免調理",IF($T5=0,"⚠ 資料缺漏",IF($T5=1,"▲ 單一設備依賴","OK"))))) | V5: =IF($D5="","",IF(AND($S5="V",$T5>0),"「無使用調理設備」不可與設備欄同時勾選，請擇一修正",IF($S5="V","免調理半成品（外購/僅切配等），不列入設備風險評估",IF($T5=0,"未勾選任何設備，請補填或勾選「無使用調理設備」",IF($T5=1,"僅依賴1台設備，須確認故障/排修時之備援製程","無異常"))))) | W5: 1140514明太子龍蝦風味沙拉飯糰.確認版(7)E02切換gkk | X5: 例：王小美 | Y5: =IF($C5="",0,IF(COUNTIF($C$5:$C5,$C5)=1,1,0)) -> 0 | Z5: =IF(Y5=1,SUM($Y$5:$Y5),"")
T6: =IF($D6="","",COUNTIF($H6:$R6,"V")) | U6: =IF($D6="","",IF(AND($S6="V",$T6>0),"⚠ 勾選矛盾",IF($S6="V","○ 免調理",IF($T6=0,"⚠ 資料缺漏",IF($T6=1,"▲ 單一設備依賴","OK"))))) | V6: =IF($D6="","",IF(AND($S6="V",$T6>0),"「無使用調理設備」不可與設備欄同時勾選，請擇一修正",IF($S6="V","免調理半成品（外購/僅切配等），不列入設備風險評估",IF($T6=0,"未勾選任何設備，請補填或勾選「無使用調理設備」",IF($T6=1,"僅依賴1台設備，須確認故障/排修時之備援製程","無異常"))))) | W6: 1140514明太子龍蝦風味沙拉飯糰.確認版(7)E02切換gkk | X6: 例：王小美 | Y6: =IF($C6="",0,IF(COUNTIF($C$5:$C6,$C6)=1,1,0)) -> 0 | Z6: =IF(Y6=1,SUM($Y$5:$Y6),"")
T7: =IF($D7="","",COUNTIF($H7:$R7,"V")) | U7: =IF($D7="","",IF(AND($S7="V",$T7>0),"⚠ 勾選矛盾",IF($S7="V","○ 免調理",IF($T7=0,"⚠ 資料缺漏",IF($T7=1,"▲ 單一設備依賴","OK"))))) | V7: =IF($D7="","",IF(AND($S7="V",$T7>0),"「無使用調理設備」不可與設備欄同時勾選，請擇一修正",IF($S7="V","免調理半成品（外購/僅切配等），不列入設備風險評估",IF($T7=0,"未勾選任何設備，請補填或勾選「無使用調理設備」",IF($T7=1,"僅依賴1台設備，須確認故障/排修時之備援製程","無異常"))))) | Y7: =IF($C7="",0,IF(COUNTIF($C$5:$C7,$C7)=1,1,0)) -> 0 | Z7: =IF(Y7=1,SUM($Y$5:$Y7),"")
T8: =IF($D8="","",COUNTIF($H8:$R8,"V")) | U8: =IF($D8="","",IF(AND($S8="V",$T8>0),"⚠ 勾選矛盾",IF($S8="V","○ 免調理",IF($T8=0,"⚠ 資料缺漏",IF($T8=1,"▲ 單一設備依賴","OK"))))) | V8: =IF($D8="","",IF(AND($S8="V",$T8>0),"「無使用調理設備」不可與設備欄同時勾選，請擇一修正",IF($S8="V","免調理半成品（外購/僅切配等），不列入設備風險評估",IF($T8=0,"未勾選任何設備，請補填或勾選「無使用調理設備」",IF($T8=1,"僅依賴1台設備，須確認故障/排修時之備援製程","無異常"))))) | Y8: =IF($C8="",0,IF(COUNTIF($C$5:$C8,$C8)=1,1,0)) -> 0 | Z8: =IF(Y8=1,SUM($Y$5:$Y8),"")
T9: =IF($D9="","",COUNTIF($H9:$R9,"V")) | U9: =IF($D9="","",IF(AND($S9="V",$T9>0),"⚠ 勾選矛盾",IF($S9="V","○ 免調理",IF($T9=0,"⚠ 資料缺漏",IF($T9=1,"▲ 單一設備依賴","OK"))))) | V9: =IF($D9="","",IF(AND($S9="V",$T9>0),"「無使用調理設備」不可與設備欄同時勾選，請擇一修正",IF($S9="V","免調理半成品（外購/僅切配等），不列入設備風險評估",IF($T9=0,"未勾選任何設備，請補填或勾選「無使用調理設備」",IF($T9=1,"僅依賴1台設備，須確認故障/排修時之備援製程","無異常"))))) | Y9: =IF($C9="",0,IF(COUNTIF($C$5:$C9,$C9)=1,1,0)) -> 0 | Z9: =IF(Y9=1,SUM($Y$5:$Y9),"")
T10: =IF($D10="","",COUNTIF($H10:$R10,"V")) | U10: =IF($D10="","",IF(AND($S10="V",$T10>0),"⚠ 勾選矛盾",IF($S10="V","○ 免調理",IF($T10=0,"⚠ 資料缺漏",IF($T10=1,"▲ 單一設備依賴","OK"))))) | V10: =IF($D10="","",IF(AND($S10="V",$T10>0),"「無使用調理設備」不可與設備欄同時勾選，請擇一修正",IF($S10="V","免調理半成品（外購/僅切配等），不列入設備風險評估",IF($T10=0,"未勾選任何設備，請補填或勾選「無使用調理設備」",IF($T10=1,"僅依賴1台設備，須確認故障/排修時之備援製程","無異常"))))) | Y10: =IF($C10="",0,IF(COUNTIF($C$5:$C10,$C10)=1,1,0)) -> 0 | Z10: =IF(Y10=1,SUM($Y$5:$Y10),"")
T11: =IF($D11="","",COUNTIF($H11:$R11,"V")) | U11: =IF($D11="","",IF(AND($S11="V",$T11>0),"⚠ 勾選矛盾",IF($S11="V","○ 免調理",IF($T11=0,"⚠ 資料缺漏",IF($T11=1,"▲ 單一設備依賴","OK"))))) | V11: =IF($D11="","",IF(AND($S11="V",$T11>0),"「無使用調理設備」不可與設備欄同時勾選，請擇一修正",IF($S11="V","免調理半成品（外購/僅切配等），不列入設備風險評估",IF($T11=0,"未勾選任何設備，請補填或勾選「無使用調理設備」",IF($T11=1,"僅依賴1台設備，須確認故障/排修時之備援製程","無異常"))))) | Y11: =IF($C11="",0,IF(COUNTIF($C$5:$C11,$C11)=1,1,0)) -> 0 | Z11: =IF(Y11=1,SUM($Y$5:$Y11),"")
T12: =IF($D12="","",COUNTIF($H12:$R12,"V")) | U12: =IF($D12="","",IF(AND($S12="V",$T12>0),"⚠ 勾選矛盾",IF($S12="V","○ 免調理",IF($T12=0,"⚠ 資料缺漏",IF($T12=1,"▲ 單一設備依賴","OK"))))) | V12: =IF($D12="","",IF(AND($S12="V",$T12>0),"「無使用調理設備」不可與設備欄同時勾選，請擇一修正",IF($S12="V","免調理半成品（外購/僅切配等），不列入設備風險評估",IF($T12=0,"未勾選任何設備，請補填或勾選「無使用調理設備」",IF($T12=1,"僅依賴1台設備，須確認故障/排修時之備援製程","無異常"))))) | Y12: =IF($C12="",0,IF(COUNTIF($C$5:$C12,$C12)=1,1,0)) -> 0 | Z12: =IF(Y12=1,SUM($Y$5:$Y12),"")
T13: =IF($D13="","",COUNTIF($H13:$R13,"V")) | U13: =IF($D13="","",IF(AND($S13="V",$T13>0),"⚠ 勾選矛盾",IF($S13="V","○ 免調理",IF($T13=0,"⚠ 資料缺漏",IF($T13=1,"▲ 單一設備依賴","OK"))))) | V13: =IF($D13="","",IF(AND($S13="V",$T13>0),"「無使用調理設備」不可與設備欄同時勾選，請擇一修正",IF($S13="V","免調理半成品（外購/僅切配等），不列入設備風險評估",IF($T13=0,"未勾選任何設備，請補填或勾選「無使用調理設備」",IF($T13=1,"僅依賴1台設備，須確認故障/排修時之備援製程","無異常"))))) | Y13: =IF($C13="",0,IF(COUNTIF($C$5:$C13,$C13)=1,1,0)) -> 0 | Z13: =IF(Y13=1,SUM($Y$5:$Y13),"")
T14: =IF($D14="","",COUNTIF($H14:$R14,"V")) | U14: =IF($D14="","",IF(AND($S14="V",$T14>0),"⚠ 勾選矛盾",IF($S14="V","○ 免調理",IF($T14=0,"⚠ 資料缺漏",IF($T14=1,"▲ 單一設備依賴","OK"))))) | V14: =IF($D14="","",IF(AND($S14="V",$T14>0),"「無使用調理設備」不可與設備欄同時勾選，請擇一修正",IF($S14="V","免調理半成品（外購/僅切配等），不列入設備風險評估",IF($T14=0,"未勾選任何設備，請補填或勾選「無使用調理設備」",IF($T14=1,"僅依賴1台設備，須確認故障/排修時之備援製程","無異常"))))) | Y14: =IF($C14="",0,IF(COUNTIF($C$5:$C14,$C14)=1,1,0)) -> 0 | Z14: =IF(Y14=1,SUM($Y$5:$Y14),"")
T15: =IF($D15="","",COUNTIF($H15:$R15,"V")) | U15: =IF($D15="","",IF(AND($S15="V",$T15>0),"⚠ 勾選矛盾",IF($S15="V","○ 免調理",IF($T15=0,"⚠ 資料缺漏",IF($T15=1,"▲ 單一設備依賴","OK"))))) | V15: =IF($D15="","",IF(AND($S15="V",$T15>0),"「無使用調理設備」不可與設備欄同時勾選，請擇一修正",IF($S15="V","免調理半成品（外購/僅切配等），不列入設備風險評估",IF($T15=0,"未勾選任何設備，請補填或勾選「無使用調理設備」",IF($T15=1,"僅依賴1台設備，須確認故障/排修時之備援製程","無異常"))))) | Y15: =IF($C15="",0,IF(COUNTIF($C$5:$C15,$C15)=1,1,0)) -> 0 | Z15: =IF(Y15=1,SUM($Y$5:$Y15),"")
T16: =IF($D16="","",COUNTIF($H16:$R16,"V")) | U16: =IF($D16="","",IF(AND($S16="V",$T16>0),"⚠ 勾選矛盾",IF($S16="V","○ 免調理",IF($T16=0,"⚠ 資料缺漏",IF($T16=1,"▲ 單一設備依賴","OK"))))) | V16: =IF($D16="","",IF(AND($S16="V",$T16>0),"「無使用調理設備」不可與設備欄同時勾選，請擇一修正",IF($S16="V","免調理半成品（外購/僅切配等），不列入設備風險評估",IF($T16=0,"未勾選任何設備，請補填或勾選「無使用調理設備」",IF($T16=1,"僅依賴1台設備，須確認故障/排修時之備援製程","無異常"))))) | Y16: =IF($C16="",0,IF(COUNTIF($C$5:$C16,$C16)=1,1,0)) -> 0 | Z16: =IF(Y16=1,SUM($Y$5:$Y16),"")
T17: =IF($D17="","",COUNTIF($H17:$R17,"V")) | U17: =IF($D17="","",IF(AND($S17="V",$T17>0),"⚠ 勾選矛盾",IF($S17="V","○ 免調理",IF($T17=0,"⚠ 資料缺漏",IF($T17=1,"▲ 單一設備依賴","OK"))))) | V17: =IF($D17="","",IF(AND($S17="V",$T17>0),"「無使用調理設備」不可與設備欄同時勾選，請擇一修正",IF($S17="V","免調理半成品（外購/僅切配等），不列入設備風險評估",IF($T17=0,"未勾選任何設備，請補填或勾選「無使用調理設備」",IF($T17=1,"僅依賴1台設備，須確認故障/排修時之備援製程","無異常"))))) | Y17: =IF($C17="",0,IF(COUNTIF($C$5:$C17,$C17)=1,1,0)) -> 0 | Z17: =IF(Y17=1,SUM($Y$5:$Y17),"")
T18: =IF($D18="","",COUNTIF($H18:$R18,"V")) | U18: =IF($D18="","",IF(AND($S18="V",$T18>0),"⚠ 勾選矛盾",IF($S18="V","○ 免調理",IF($T18=0,"⚠ 資料缺漏",IF($T18=1,"▲ 單一設備依賴","OK"))))) | V18: =IF($D18="","",IF(AND($S18="V",$T18>0),"「無使用調理設備」不可與設備欄同時勾選，請擇一修正",IF($S18="V","免調理半成品（外購/僅切配等），不列入設備風險評估",IF($T18=0,"未勾選任何設備，請補填或勾選「無使用調理設備」",IF($T18=1,"僅依賴1台設備，須確認故障/排修時之備援製程","無異常"))))) | Y18: =IF($C18="",0,IF(COUNTIF($C$5:$C18,$C18)=1,1,0)) -> 0 | Z18: =IF(Y18=1,SUM($Y$5:$Y18),"")
... T304: =IF($D304="","",COUNTIF($H304:$R304,"V")) | U304: =IF($D304="","",IF(AND($S304="V",$T304>0),"⚠ 勾選矛盾",IF($S304="V","○ 免調理",IF($T304=0,"⚠ 資料缺漏",IF($T304=1,"▲ 單一設備依賴","OK"))))) | V304: =IF($D304="","",IF(AND($S304="V",$T304>0),"「無使用調理設備」不可與設備欄同時勾選，請擇一修正",IF($S304="V","免調理半成品（外購/僅切配等），不列入設備風險評估",IF($T304=0,"未勾選任何設備，請補填或勾選「無使用調理設備」",IF($T304=1,"僅依賴1台設備，須確認故障/排修時之備援製程","無異常"))))) | Y304: =IF($C304="",0,IF(COUNTIF($C$5:$C304,$C304)=1,1,0)) -> 0 | Z304: =IF(Y304=1,SUM($Y$5:$Y304),"")

Sheet 4℃飯
A1: 商品半成品與調理設備應用展開一覽表｜4℃飯
A2: 商品資訊 | H2: 熱調理區（使用者填「V」；免調理者勾最右欄） | T2: 自動計算與風險檢核（勿手動修改） | W2: 建檔資訊（手填）
A3: 工廠 | B3: 商品分類 (細分品類) | C3: 商品名稱 | D3: 半成品名稱 | E3: 單位用量 | G3: 製程率 (填數字) | H3: 炊飯 | I3: 煮麵 | J3: 烤箱 | K3: 炙燒 | L3: 蒸箱 | M3: 油炸機 | N3: 二重釜 | O3: 平釜 (日) | P3: 平釜 (台) | Q3: 蛋皮機 | R3: 壓力鍋 | S3: 無使用 調理設備 | T3: 使用 設備數 | U3: 檢核結果 | V3: 風險說明 | W3: 備註 (指示書編號/版本) | X3: 建檔人員 | Y3: 系統用Y | Z3: 系統用Z
E4: 數值 | F4: 單位
T5: =IF($D5="","",COUNTIF($H5:$R5,"V")) | U5: =IF($D5="","",IF(AND($S5="V",$T5>0),"⚠ 勾選矛盾",IF($S5="V","○ 免調理",IF($T5=0,"⚠ 資料缺漏",IF($T5=1,"▲ 單一設備依賴","OK"))))) | V5: =IF($D5="","",IF(AND($S5="V",$T5>0),"「無使用調理設備」不可與設備欄同時勾選，請擇一修正",IF($S5="V","免調理半成品（外購/僅切配等），不列入設備風險評估",IF($T5=0,"未勾選任何設備，請補填或勾選「無使用調理設備」",IF($T5=1,"僅依賴1台設備，須確認故障/排修時之備援製程","無異常"))))) | W5: 1140514蔬咖哩飯.確認版(1) | X5: 例：王小美 | Y5: =IF($C5="",0,IF(COUNTIF($C$5:$C5,$C5)=1,1,0)) -> 0 | Z5: =IF(Y5=1,SUM($Y$5:$Y5),"")
T6: =IF($D6="","",COUNTIF($H6:$R6,"V")) | U6: =IF($D6="","",IF(AND($S6="V",$T6>0),"⚠ 勾選矛盾",IF($S6="V","○ 免調理",IF($T6=0,"⚠ 資料缺漏",IF($T6=1,"▲ 單一設備依賴","OK"))))) | V6: =IF($D6="","",IF(AND($S6="V",$T6>0),"「無使用調理設備」不可與設備欄同時勾選，請擇一修正",IF($S6="V","免調理半成品（外購/僅切配等），不列入設備風險評估",IF($T6=0,"未勾選任何設備，請補填或勾選「無使用調理設備」",IF($T6=1,"僅依賴1台設備，須確認故障/排修時之備援製程","無異常"))))) | W6: 1140514蔬咖哩飯.確認版(1) | X6: 例：王小美 | Y6: =IF($C6="",0,IF(COUNTIF($C$5:$C6,$C6)=1,1,0)) -> 0 | Z6: =IF(Y6=1,SUM($Y$5:$Y6),"")
T7: =IF($D7="","",COUNTIF($H7:$R7,"V")) | U7: =IF($D7="","",IF(AND($S7="V",$T7>0),"⚠ 勾選矛盾",IF($S7="V","○ 免調理",IF($T7=0,"⚠ 資料缺漏",IF($T7=1,"▲ 單一設備依賴","OK"))))) | V7: =IF($D7="","",IF(AND($S7="V",$T7>0),"「無使用調理設備」不可與設備欄同時勾選，請擇一修正",IF($S7="V","免調理半成品（外購/僅切配等），不列入設備風險評估",IF($T7=0,"未勾選任何設備，請補填或勾選「無使用調理設備」",IF($T7=1,"僅依賴1台設備，須確認故障/排修時之備援製程","無異常"))))) | W7: 1140514蔬咖哩飯.確認版(1) | X7: 例：王小美 | Y7: =IF($C7="",0,IF(COUNTIF($C$5:$C7,$C7)=1,1,0)) -> 0 | Z7: =IF(Y7=1,SUM($Y$5:$Y7),"")
T8: =IF($D8="","",COUNTIF($H8:$R8,"V")) | U8: =IF($D8="","",IF(AND($S8="V",$T8>0),"⚠ 勾選矛盾",IF($S8="V","○ 免調理",IF($T8=0,"⚠ 資料缺漏",IF($T8=1,"▲ 單一設備依賴","OK"))))) | V8: =IF($D8="","",IF(AND($S8="V",$T8>0),"「無使用調理設備」不可與設備欄同時勾選，請擇一修正",IF($S8="V","免調理半成品（外購/僅切配等），不列入設備風險評估",IF($T8=0,"未勾選任何設備，請補填或勾選「無使用調理設備」",IF($T8=1,"僅依賴1台設備，須確認故障/排修時之備援製程","無異常"))))) | W8: 1140514蔬咖哩飯.確認版(1) | X8: 例：王小美 | Y8: =IF($C8="",0,IF(COUNTIF($C$5:$C8,$C8)=1,1,0)) -> 0 | Z8: =IF(Y8=1,SUM($Y$5:$Y8),"")
T9: =IF($D9="","",COUNTIF($H9:$R9,"V")) | U9: =IF($D9="","",IF(AND($S9="V",$T9>0),"⚠ 勾選矛盾",IF($S9="V","○ 免調理",IF($T9=0,"⚠ 資料缺漏",IF($T9=1,"▲ 單一設備依賴","OK"))))) | V9: =IF($D9="","",IF(AND($S9="V",$T9>0),"「無使用調理設備」不可與設備欄同時勾選，請擇一修正",IF($S9="V","免調理半成品（外購/僅切配等），不列入設備風險評估",IF($T9=0,"未勾選任何設備，請補填或勾選「無使用調理設備」",IF($T9=1,"僅依賴1台設備，須確認故障/排修時之備援製程","無異常"))))) | Y9: =IF($C9="",0,IF(COUNTIF($C$5:$C9,$C9)=1,1,0)) -> 0 | Z9: =IF(Y9=1,SUM($Y$5:$Y9),"")
T10: =IF($D10="","",COUNTIF($H10:$R10,"V")) | U10: =IF($D10="","",IF(AND($S10="V",$T10>0),"⚠ 勾選矛盾",IF($S10="V","○ 免調理",IF($T10=0,"⚠ 資料缺漏",IF($T10=1,"▲ 單一設備依賴","OK"))))) | V10: =IF($D10="","",IF(AND($S10="V",$T10>0),"「無使用調理設備」不可與設備欄同時勾選，請擇一修正",IF($S10="V","免調理半成品（外購/僅切配等），不列入設備風險評估",IF($T10=0,"未勾選任何設備，請補填或勾選「無使用調理設備」",IF($T10=1,"僅依賴1台設備，須確認故障/排修時之備援製程","無異常"))))) | Y10: =IF($C10="",0,IF(COUNTIF($C$5:$C10,$C10)=1,1,0)) -> 0 | Z10: =IF(Y10=1,SUM($Y$5:$Y10),"")
T11: =IF($D11="","",COUNTIF($H11:$R11,"V")) | U11: =IF($D11="","",IF(AND($S11="V",$T11>0),"⚠ 勾選矛盾",IF($S11="V","○ 免調理",IF($T11=0,"⚠ 資料缺漏",IF($T11=1,"▲ 單一設備依賴","OK"))))) | V11: =IF($D11="","",IF(AND($S11="V",$T11>0),"「無使用調理設備」不可與設備欄同時勾選，請擇一修正",IF($S11="V","免調理半成品（外購/僅切配等），不列入設備風險評估",IF($T11=0,"未勾選任何設備，請補填或勾選「無使用調理設備」",IF($T11=1,"僅依賴1台設備，須確認故障/排修時之備援製程","無異常"))))) | Y11: =IF($C11="",0,IF(COUNTIF($C$5:$C11,$C11)=1,1,0)) -> 0 | Z11: =IF(Y11=1,SUM($Y$5:$Y11),"")
T12: =IF($D12="","",COUNTIF($H12:$R12,"V")) | U12: =IF($D12="","",IF(AND($S12="V",$T12>0),"⚠ 勾選矛盾",IF($S12="V","○ 免調理",IF($T12=0,"⚠ 資料缺漏",IF($T12=1,"▲ 單一設備依賴","OK"))))) | V12: =IF($D12="","",IF(AND($S12="V",$T12>0),"「無使用調理設備」不可與設備欄同時勾選，請擇一修正",IF($S12="V","免調理半成品（外購/僅切配等），不列入設備風險評估",IF($T12=0,"未勾選任何設備，請補填或勾選「無使用調理設備」",IF($T12=1,"僅依賴1台設備，須確認故障/排修時之備援製程","無異常"))))) | Y12: =IF($C12="",0,IF(COUNTIF($C$5:$C12,$C12)=1,1,0)) -> 0 | Z12: =IF(Y12=1,SUM($Y$5:$Y12),"")
T13: =IF($D13="","",COUNTIF($H13:$R13,"V")) | U13: =IF($D13="","",IF(AND($S13="V",$T13>0),"⚠ 勾選矛盾",IF($S13="V","○ 免調理",IF($T13=0,"⚠ 資料缺漏",IF($T13=1,"▲ 單一設備依賴","OK"))))) | V13: =IF($D13="","",IF(AND($S13="V",$T13>0),"「無使用調理設備」不可與設備欄同時勾選，請擇一修正",IF($S13="V","免調理半成品（外購/僅切配等），不列入設備風險評估",IF($T13=0,"未勾選任何設備，請補填或勾選「無使用調理設備」",IF($T13=1,"僅依賴1台設備，須確認故障/排修時之備援製程","無異常"))))) | Y13: =IF($C13="",0,IF(COUNTIF($C$5:$C13,$C13)=1,1,0)) -> 0 | Z13: =IF(Y13=1,SUM($Y$5:$Y13),"")
T14: =IF($D14="","",COUNTIF($H14:$R14,"V")) | U14: =IF($D14="","",IF(AND($S14="V",$T14>0),"⚠ 勾選矛盾",IF($S14="V","○ 免調理",IF($T14=0,"⚠ 資料缺漏",IF($T14=1,"▲ 單一設備依賴","OK"))))) | V14: =IF($D14="","",IF(AND($S14="V",$T14>0),"「無使用調理設備」不可與設備欄同時勾選，請擇一修正",IF($S14="V","免調理半成品（外購/僅切配等），不列入設備風險評估",IF($T14=0,"未勾選任何設備，請補填或勾選「無使用調理設備」",IF($T14=1,"僅依賴1台設備，須確認故障/排修時之備援製程","無異常"))))) | Y14: =IF($C14="",0,IF(COUNTIF($C$5:$C14,$C14)=1,1,0)) -> 0 | Z14: =IF(Y14=1,SUM($Y$5:$Y14),"")
T15: =IF($D15="","",COUNTIF($H15:$R15,"V")) | U15: =IF($D15="","",IF(AND($S15="V",$T15>0),"⚠ 勾選矛盾",IF($S15="V","○ 免調理",IF($T15=0,"⚠ 資料缺漏",IF($T15=1,"▲ 單一設備依賴","OK"))))) | V15: =IF($D15="","",IF(AND($S15="V",$T15>0),"「無使用調理設備」不可與設備欄同時勾選，請擇一修正",IF($S15="V","免調理半成品（外購/僅切配等），不列入設備風險評估",IF($T15=0,"未勾選任何設備，請補填或勾選「無使用調理設備」",IF($T15=1,"僅依賴1台設備，須確認故障/排修時之備援製程","無異常"))))) | Y15: =IF($C15="",0,IF(COUNTIF($C$5:$C15,$C15)=1,1,0)) -> 0 | Z15: =IF(Y15=1,SUM($Y$5:$Y15),"")
T16: =IF($D16="","",COUNTIF($H16:$R16,"V")) | U16: =IF($D16="","",IF(AND($S16="V",$T16>0),"⚠ 勾選矛盾",IF($S16="V","○ 免調理",IF($T16=0,"⚠ 資料缺漏",IF($T16=1,"▲ 單一設備依賴","OK"))))) | V16: =IF($D16="","",IF(AND($S16="V",$T16>0),"「無使用調理設備」不可與設備欄同時勾選，請擇一修正",IF($S16="V","免調理半成品（外購/僅切配等），不列入設備風險評估",IF($T16=0,"未勾選任何設備，請補填或勾選「無使用調理設備」",IF($T16=1,"僅依賴1台設備，須確認故障/排修時之備援製程","無異常"))))) | Y16: =IF($C16="",0,IF(COUNTIF($C$5:$C16,$C16)=1,1,0)) -> 0 | Z16: =IF(Y16=1,SUM($Y$5:$Y16),"")
T17: =IF($D17="","",COUNTIF($H17:$R17,"V")) | U17: =IF($D17="","",IF(AND($S17="V",$T17>0),"⚠ 勾選矛盾",IF($S17="V","○ 免調理",IF($T17=0,"⚠ 資料缺漏",IF($T17=1,"▲ 單一設備依賴","OK"))))) | V17: =IF($D17="","",IF(AND($S17="V",$T17>0),"「無使用調理設備」不可與設備欄同時勾選，請擇一修正",IF($S17="V","免調理半成品（外購/僅切配等），不列入設備風險評估",IF($T17=0,"未勾選任何設備，請補填或勾選「無使用調理設備」",IF($T17=1,"僅依賴1台設備，須確認故障/排修時之備援製程","無異常"))))) | Y17: =IF($C17="",0,IF(COUNTIF($C$5:$C17,$C17)=1,1,0)) -> 0 | Z17: =IF(Y17=1,SUM($Y$5:$Y17),"")
T18: =IF($D18="","",COUNTIF($H18:$R18,"V")) | U18: =IF($D18="","",IF(AND($S18="V",$T18>0),"⚠ 勾選矛盾",IF($S18="V","○ 免調理",IF($T18=0,"⚠ 資料缺漏",IF($T18=1,"▲ 單一設備依賴","OK"))))) | V18: =IF($D18="","",IF(AND($S18="V",$T18>0),"「無使用調理設備」不可與設備欄同時勾選，請擇一修正",IF($S18="V","免調理半成品（外購/僅切配等），不列入設備風險評估",IF($T18=0,"未勾選任何設備，請補填或勾選「無使用調理設備」",IF($T18=1,"僅依賴1台設備，須確認故障/排修時之備援製程","無異常"))))) | Y18: =IF($C18="",0,IF(COUNTIF($C$5:$C18,$C18)=1,1,0)) -> 0 | Z18: =IF(Y18=1,SUM($Y$5:$Y18),"")
T19: =IF($D19="","",COUNTIF($H19:$R19,"V")) | U19: =IF($D19="","",IF(AND($S19="V",$T19>0),"⚠ 勾選矛盾",IF($S19="V","○ 免調理",IF($T19=0,"⚠ 資料缺漏",IF($T19=1,"▲ 單一設備依賴","OK"))))) | V19: =IF($D19="","",IF(AND($S19="V",$T19>0),"「無使用調理設備」不可與設備欄同時勾選，請擇一修正",IF($S19="V","免調理半成品（外購/僅切配等），不列入設備風險評估",IF($T19=0,"未勾選任何設備，請補填或勾選「無使用調理設備」",IF($T19=1,"僅依賴1台設備，須確認故障/排修時之備援製程","無異常"))))) | Y19: =IF($C19="",0,IF(COUNTIF($C$5:$C19,$C19)=1,1,0)) -> 0 | Z19: =IF(Y19=1,SUM($Y$5:$Y19),"")
T20: =IF($D20="","",COUNTIF($H20:$R20,"V")) | U20: =IF($D20="","",IF(AND($S20="V",$T20>0),"⚠ 勾選矛盾",IF($S20="V","○ 免調理",IF($T20=0,"⚠ 資料缺漏",IF($T20=1,"▲ 單一設備依賴","OK"))))) | V20: =IF($D20="","",IF(AND($S20="V",$T20>0),"「無使用調理設備」不可與設備欄同時勾選，請擇一修正",IF($S20="V","免調理半成品（外購/僅切配等），不列入設備風險評估",IF($T20=0,"未勾選任何設備，請補填或勾選「無使用調理設備」",IF($T20=1,"僅依賴1台設備，須確認故障/排修時之備援製程","無異常"))))) | Y20: =IF($C20="",0,IF(COUNTIF($C$5:$C20,$C20)=1,1,0)) -> 0 | Z20: =IF(Y20=1,SUM($Y$5:$Y20),"")
... T304: =IF($D304="","",COUNTIF($H304:$R304,"V")) | U304: =IF($D304="","",IF(AND($S304="V",$T304>0),"⚠ 勾選矛盾",IF($S304="V","○ 免調理",IF($T304=0,"⚠ 資料缺漏",IF($T304=1,"▲ 單一設備依賴","OK"))))) | V304: =IF($D304="","",IF(AND($S304="V",$T304>0),"「無使用調理設備」不可與設備欄同時勾選，請擇一修正",IF($S304="V","免調理半成品（外購/僅切配等），不列入設備風險評估",IF($T304=0,"未勾選任何設備，請補填或勾選「無使用調理設備」",IF($T304=1,"僅依賴1台設備，須確認故障/排修時之備援製程","無異常"))))) | Y304: =IF($C304="",0,IF(COUNTIF($C$5:$C304,$C304)=1,1,0)) -> 0 | Z304: =IF(Y304=1,SUM($Y$5:$Y304),"")

Sheet 4℃麵
A1: 商品半成品與調理設備應用展開一覽表｜4℃麵
A2: 商品資訊 | I2: 熱調理區（使用者填「V」；免調理者勾最右欄） | U2: 自動計算與風險檢核（勿手動修改） | X2: 建檔資訊（手填）
A3: 狀態 | B3: 工廠 | C3: 商品分類 (細分品類) | D3: 商品名稱 | E3: 半成品名稱 | F3: 單位用量 | H3: 製程率 (填數字) | I3: 炊飯 | J3: 煮麵 | K3: 烤箱 | L3: 炙燒 | M3: 蒸箱 | N3: 油炸機 | O3: 二重釜 | P3: 平釜 (日) | Q3: 平釜 (台) | R3: 蛋皮機 | S3: 壓力鍋 | T3: 無使用 調理設備 | U3: 使用 設備數 | V3: 檢核結果 | W3: 風險說明 | X3: 備註 (指示書編號/版本) | Y3: 建檔人員 | Z3: 系統用Y | AA3: 系統用Z
F4: 數值 | G4: 單位
A5: 下架 | B5: 長家 | C5: 熱食義麵 | D5: 金沙豆腐義大利麵 | E5: 煮日製義大利麵(115) | F5: 220 | G5: 公克 | H5: 240 | J5: V | U5: =IF($E5="","",COUNTIF($I5:$S5,"V")) -> 1 | V5: =IF($E5="","",IF(AND($T5="V",$U5>0),"⚠ 勾選矛盾",IF($T5="V","○ 免調理",IF($U5=0,"⚠ 資料缺漏",IF($U5=1,"▲ 單一設備依賴","OK"))))) -> ▲ 單一設備依賴 | W5: =IF($E5="","",IF(AND($T5="V",$U5>0),"「無使用調理設備」不可與設備欄同時勾選，請擇一修正",IF($T5="V","免調理半成品（外購/僅切配等），不列入設備風險評估",IF($U5=0,"未勾選任何設備，請補填或勾選「無使用調理設備」",IF($U5=1,"僅依賴1台設備，須確認故障/排修時之備援製程","無異常"))))) -> 僅依賴1台設備，須確認故障/排修時之備援製程 | Z5: =IF($D5="",0,IF(COUNTIF($D$5:$D5,$D5)=1,1,0)) -> 1 | AA5: =IF(Z5=1,SUM($Z$5:$Z5),"") -> 1
A6: 下架 | B6: 長家 | C6: 熱食義麵 | D6: 金沙豆腐義大利麵 | E6: (V)義麵-金沙奶醬(115年) | F6: 100 | G6: 公克 | H6: 82 | O6: V | U6: =IF($E6="","",COUNTIF($I6:$S6,"V")) -> 1 | V6: =IF($E6="","",IF(AND($T6="V",$U6>0),"⚠ 勾選矛盾",IF($T6="V","○ 免調理",IF($U6=0,"⚠ 資料缺漏",IF($U6=1,"▲ 單一設備依賴","OK"))))) -> ▲ 單一設備依賴 | W6: =IF($E6="","",IF(AND($T6="V",$U6>0),"「無使用調理設備」不可與設備欄同時勾選，請擇一修正",IF($T6="V","免調理半成品（外購/僅切配等），不列入設備風險評估",IF($U6=0,"未勾選任何設備，請補填或勾選「無使用調理設備」",IF($U6=1,"僅依賴1台設備，須確認故障/排修時之備援製程","無異常"))))) -> 僅依賴1台設備，須確認故障/排修時之備援製程 | Z6: =IF($D6="",0,IF(COUNTIF($D$5:$D6,$D6)=1,1,0)) -> 0 | AA6: =IF(Z6=1,SUM($Z$5:$Z6),"")
A7: 下架 | B7: 長家 | C7: 熱食義麵 | D7: 金沙豆腐義大利麵 | E7: 烤12切豆腐 | F7: 60 | G7: 公克 | H7: 100 | K7: V | U7: =IF($E7="","",COUNTIF($I7:$S7,"V")) -> 1 | V7: =IF($E7="","",IF(AND($T7="V",$U7>0),"⚠ 勾選矛盾",IF($T7="V","○ 免調理",IF($U7=0,"⚠ 資料缺漏",IF($U7=1,"▲ 單一設備依賴","OK"))))) -> ▲ 單一設備依賴 | W7: =IF($E7="","",IF(AND($T7="V",$U7>0),"「無使用調理設備」不可與設備欄同時勾選，請擇一修正",IF($T7="V","免調理半成品（外購/僅切配等），不列入設備風險評估",IF($U7=0,"未勾選任何設備，請補填或勾選「無使用調理設備」",IF($U7=1,"僅依賴1台設備，須確認故障/排修時之備援製程","無異常"))))) -> 僅依賴1台設備，須確認故障/排修時之備援製程 | Z7: =IF($D7="",0,IF(COUNTIF($D$5:$D7,$D7)=1,1,0)) -> 0 | AA7: =IF(Z7=1,SUM($Z$5:$Z7),"")
A8: 下架 | B8: 長家 | C8: 熱食義麵 | D8: 金沙豆腐義大利麵 | E8: 烤帶皮南瓜丁 | F8: 8 | G8: 公克 | H8: 50 | K8: V | U8: =IF($E8="","",COUNTIF($I8:$S8,"V")) -> 1 | V8: =IF($E8="","",IF(AND($T8="V",$U8>0),"⚠ 勾選矛盾",IF($T8="V","○ 免調理",IF($U8=0,"⚠ 資料缺漏",IF($U8=1,"▲ 單一設備依賴","OK"))))) -> ▲ 單一設備依賴 | W8: =IF($E8="","",IF(AND($T8="V",$U8>0),"「無使用調理設備」不可與設備欄同時勾選，請擇一修正",IF($T8="V","免調理半成品（外購/僅切配等），不列入設備風險評估",IF($U8=0,"未勾選任何設備，請補填或勾選「無使用調理設備」",IF($U8=1,"僅依賴1台設備，須確認故障/排修時之備援製程","無異常"))))) -> 僅依賴1台設備，須確認故障/排修時之備援製程 | Z8: =IF($D8="",0,IF(COUNTIF($D$5:$D8,$D8)=1,1,0)) -> 0 | AA8: =IF(Z8=1,SUM($Z$5:$Z8),"")
A9: 下架 | B9: 長家 | C9: 熱食義麵 | D9: 金沙豆腐義大利麵 | E9: 蒸鹹蛋黃碎 | F9: 3 | G9: 公克 | H9: 91 | M9: V | U9: =IF($E9="","",COUNTIF($I9:$S9,"V")) -> 1 | V9: =IF($E9="","",IF(AND($T9="V",$U9>0),"⚠ 勾選矛盾",IF($T9="V","○ 免調理",IF($U9=0,"⚠ 資料缺漏",IF($U9=1,"▲ 單一設備依賴","OK"))))) -> ▲ 單一設備依賴 | W9: =IF($E9="","",IF(AND($T9="V",$U9>0),"「無使用調理設備」不可與設備欄同時勾選，請擇一修正",IF($T9="V","免調理半成品（外購/僅切配等），不列入設備風險評估",IF($U9=0,"未勾選任何設備，請補填或勾選「無使用調理設備」",IF($U9=1,"僅依賴1台設備，須確認故障/排修時之備援製程","無異常"))))) -> 僅依賴1台設備，須確認故障/排修時之備援製程 | Z9: =IF($D9="",0,IF(COUNTIF($D$5:$D9,$D9)=1,1,0)) -> 0 | AA9: =IF(Z9=1,SUM($Z$5:$Z9),"")
A10: 下架 | B10: 長家 | C10: 熱食義麵 | D10: 金沙豆腐義大利麵 | E10: 洋香菜葉KU | F10: 0.2 | G10: 公克 | H10: 100 | T10: V | U10: =IF($E10="","",COUNTIF($I10:$S10,"V")) -> 0 | V10: =IF($E10="","",IF(AND($T10="V",$U10>0),"⚠ 勾選矛盾",IF($T10="V","○ 免調理",IF($U10=0,"⚠ 資料缺漏",IF($U10=1,"▲ 單一設備依賴","OK"))))) -> ○ 免調理 | W10: =IF($E10="","",IF(AND($T10="V",$U10>0),"「無使用調理設備」不可與設備欄同時勾選，請擇一修正",IF($T10="V","免調理半成品（外購/僅切配等），不列入設備風險評估",IF($U10=0,"未勾選任何設備，請補填或勾選「無使用調理設備」",IF($U10=1,"僅依賴1台設備，須確認故障/排修時之備援製程","無異常"))))) -> 免調理半成品（外購/僅切配等），不列入設備風險評估 | Z10: =IF($D10="",0,IF(COUNTIF($D$5:$D10,$D10)=1,1,0)) -> 0 | AA10: =IF(Z10=1,SUM($Z$5:$Z10),"")
A11: 架上 | B11: 長家 | C11: 熱食義麵 | D11: 奶油培根義大利麵RN | E11: 煮日製義大利麵(115) | F11: 220 | G11: 公克 | H11: 235 | J11: V | U11: =IF($E11="","",COUNTIF($I11:$S11,"V")) -> 1 | V11: =IF($E11="","",IF(AND($T11="V",$U11>0),"⚠ 勾選矛盾",IF($T11="V","○ 免調理",IF($U11=0,"⚠ 資料缺漏",IF($U11=1,"▲ 單一設備依賴","OK"))))) -> ▲ 單一設備依賴 | W11: =IF($E11="","",IF(AND($T11="V",$U11>0),"「無使用調理設備」不可與設備欄同時勾選，請擇一修正",IF($T11="V","免調理半成品（外購/僅切配等），不列入設備風險評估",IF($U11=0,"未勾選任何設備，請補填或勾選「無使用調理設備」",IF($U11=1,"僅依賴1台設備，須確認故障/排修時之備援製程","無異常"))))) -> 僅依賴1台設備，須確認故障/排修時之備援製程 | Z11: =IF($D11="",0,IF(COUNTIF($D$5:$D11,$D11)=1,1,0)) -> 1 | AA11: =IF(Z11=1,SUM($Z$5:$Z11),"") -> 2
A12: 架上 | B12: 長家 | C12: 熱食義麵 | D12: 奶油培根義大利麵RN | E12: 奶香白醬 | F12: 80 | G12: 公克 | H12: 55 | O12: V | U12: =IF($E12="","",COUNTIF($I12:$S12,"V")) -> 1 | V12: =IF($E12="","",IF(AND($T12="V",$U12>0),"⚠ 勾選矛盾",IF($T12="V","○ 免調理",IF($U12=0,"⚠ 資料缺漏",IF($U12=1,"▲ 單一設備依賴","OK"))))) -> ▲ 單一設備依賴 | W12: =IF($E12="","",IF(AND($T12="V",$U12>0),"「無使用調理設備」不可與設備欄同時勾選，請擇一修正",IF($T12="V","免調理半成品（外購/僅切配等），不列入設備風險評估",IF($U12=0,"未勾選任何設備，請補填或勾選「無使用調理設備」",IF($U12=1,"僅依賴1台設備，須確認故障/排修時之備援製程","無異常"))))) -> 僅依賴1台設備，須確認故障/排修時之備援製程 | Z12: =IF($D12="",0,IF(COUNTIF($D$5:$D12,$D12)=1,1,0)) -> 0 | AA12: =IF(Z12=1,SUM($Z$5:$Z12),"")
A13: 架上 | B13: 長家 | C13: 熱食義麵 | D13: 奶油培根義大利麵RN | E13: 切-烤重煙燻培根片(湖)15mm | F13: 20 | G13: 公克 | H13: 60 | K13: V | U13: =IF($E13="","",COUNTIF($I13:$S13,"V")) -> 1 | V13: =IF($E13="","",IF(AND($T13="V",$U13>0),"⚠ 勾選矛盾",IF($T13="V","○ 免調理",IF($U13=0,"⚠ 資料缺漏",IF($U13=1,"▲ 單一設備依賴","OK"))))) -> ▲ 單一設備依賴 | W13: =IF($E13="","",IF(AND($T13="V",$U13>0),"「無使用調理設備」不可與設備欄同時勾選，請擇一修正",IF($T13="V","免調理半成品（外購/僅切配等），不列入設備風險評估",IF($U13=0,"未勾選任何設備，請補填或勾選「無使用調理設備」",IF($U13=1,"僅依賴1台設備，須確認故障/排修時之備援製程","無異常"))))) -> 僅依賴1台設備，須確認故障/排修時之備援製程 | Z13: =IF($D13="",0,IF(COUNTIF($D$5:$D13,$D13)=1,1,0)) -> 0 | AA13: =IF(Z13=1,SUM($Z$5:$Z13),"")
A14: 架上 | B14: 長家 | C14: 熱食義麵 | D14: 奶油培根義大利麵RN | E14: 解凍黑胡椒燻豬腿肉(湖) | F14: 10 | G14: 公克 | H14: 94 | T14: V | U14: =IF($E14="","",COUNTIF($I14:$S14,"V")) -> 0 | V14: =IF($E14="","",IF(AND($T14="V",$U14>0),"⚠ 勾選矛盾",IF($T14="V","○ 免調理",IF($U14=0,"⚠ 資料缺漏",IF($U14=1,"▲ 單一設備依賴","OK"))))) -> ○ 免調理 | W14: =IF($E14="","",IF(AND($T14="V",$U14>0),"「無使用調理設備」不可與設備欄同時勾選，請擇一修正",IF($T14="V","免調理半成品（外購/僅切配等），不列入設備風險評估",IF($U14=0,"未勾選任何設備，請補填或勾選「無使用調理設備」",IF($U14=1,"僅依賴1台設備，須確認故障/排修時之備援製程","無異常"))))) -> 免調理半成品（外購/僅切配等），不列入設備風險評估 | Z14: =IF($D14="",0,IF(COUNTIF($D$5:$D14,$D14)=1,1,0)) -> 0 | AA14: =IF(Z14=1,SUM($Z$5:$Z14),"")
A15: 架上 | B15: 長家 | C15: 熱食義麵 | D15: 奶油培根義大利麵RN | E15: 洋香菜葉KU | F15: 0.2 | G15: 公克 | H15: 100 | T15: V | U15: =IF($E15="","",COUNTIF($I15:$S15,"V")) -> 0 | V15: =IF($E15="","",IF(AND($T15="V",$U15>0),"⚠ 勾選矛盾",IF($T15="V","○ 免調理",IF($U15=0,"⚠ 資料缺漏",IF($U15=1,"▲ 單一設備依賴","OK"))))) -> ○ 免調理 | W15: =IF($E15="","",IF(AND($T15="V",$U15>0),"「無使用調理設備」不可與設備欄同時勾選，請擇一修正",IF($T15="V","免調理半成品（外購/僅切配等），不列入設備風險評估",IF($U15=0,"未勾選任何設備，請補填或勾選「無使用調理設備」",IF($U15=1,"僅依賴1台設備，須確認故障/排修時之備援製程","無異常"))))) -> 免調理半成品（外購/僅切配等），不列入設備風險評估 | Z15: =IF($D15="",0,IF(COUNTIF($D$5:$D15,$D15)=1,1,0)) -> 0 | AA15: =IF(Z15=1,SUM($Z$5:$Z15),"")
A16: 架上 | B16: 長家 | C16: 熱食義麵 | D16: 奶油培根義大利麵RN | E16: 紅切達起司絲 | F16: 3 | G16: 公克 | H16: 100 | T16: V | U16: =IF($E16="","",COUNTIF($I16:$S16,"V")) -> 0 | V16: =IF($E16="","",IF(AND($T16="V",$U16>0),"⚠ 勾選矛盾",IF($T16="V","○ 免調理",IF($U16=0,"⚠ 資料缺漏",IF($U16=1,"▲ 單一設備依賴","OK"))))) -> ○ 免調理 | W16: =IF($E16="","",IF(AND($T16="V",$U16>0),"「無使用調理設備」不可與設備欄同時勾選，請擇一修正",IF($T16="V","免調理半成品（外購/僅切配等），不列入設備風險評估",IF($U16=0,"未勾選任何設備，請補填或勾選「無使用調理設備」",IF($U16=1,"僅依賴1台設備，須確認故障/排修時之備援製程","無異常"))))) -> 免調理半成品（外購/僅切配等），不列入設備風險評估 | Z16: =IF($D16="",0,IF(COUNTIF($D$5:$D16,$D16)=1,1,0)) -> 0 | AA16: =IF(Z16=1,SUM($Z$5:$Z16),"")
A17: 下架 | B17: 長家 | C17: 熱食義麵 | D17: 奶油鮮蝦明太子細扁麵 | E17: 煮Pazar細扁麵 | F17: 220 | G17: 公克 | H17: 215 | J17: V | U17: =IF($E17="","",COUNTIF($I17:$S17,"V")) -> 1 | V17: =IF($E17="","",IF(AND($T17="V",$U17>0),"⚠ 勾選矛盾",IF($T17="V","○ 免調理",IF($U17=0,"⚠ 資料缺漏",IF($U17=1,"▲ 單一設備依賴","OK"))))) -> ▲ 單一設備依賴 | W17: =IF($E17="","",IF(AND($T17="V",$U17>0),"「無使用調理設備」不可與設備欄同時勾選，請擇一修正",IF($T17="V","免調理半成品（外購/僅切配等），不列入設備風險評估",IF($U17=0,"未勾選任何設備，請補填或勾選「無使用調理設備」",IF($U17=1,"僅依賴1台設備，須確認故障/排修時之備援製程","無異常"))))) -> 僅依賴1台設備，須確認故障/排修時之備援製程 | Z17: =IF($D17="",0,IF(COUNTIF($D$5:$D17,$D17)=1,1,0)) -> 1 | AA17: =IF(Z17=1,SUM($Z$5:$Z17),"") -> 3
A18: 下架 | B18: 長家 | C18: 熱食義麵 | D18: 奶油鮮蝦明太子細扁麵 | E18: 義麵-粉紅辣味奶醬 | F18: 80 | G18: 公克 | H18: 73 | O18: V | U18: =IF($E18="","",COUNTIF($I18:$S18,"V")) -> 1 | V18: =IF($E18="","",IF(AND($T18="V",$U18>0),"⚠ 勾選矛盾",IF($T18="V","○ 免調理",IF($U18=0,"⚠ 資料缺漏",IF($U18=1,"▲ 單一設備依賴","OK"))))) -> ▲ 單一設備依賴 | W18: =IF($E18="","",IF(AND($T18="V",$U18>0),"「無使用調理設備」不可與設備欄同時勾選，請擇一修正",IF($T18="V","免調理半成品（外購/僅切配等），不列入設備風險評估",IF($U18=0,"未勾選任何設備，請補填或勾選「無使用調理設備」",IF($U18=1,"僅依賴1台設備，須確認故障/排修時之備援製程","無異常"))))) -> 僅依賴1台設備，須確認故障/排修時之備援製程 | Z18: =IF($D18="",0,IF(COUNTIF($D$5:$D18,$D18)=1,1,0)) -> 0 | AA18: =IF(Z18=1,SUM($Z$5:$Z18),"")
A19: 下架 | B19: 長家 | C19: 熱食義麵 | D19: 奶油鮮蝦明太子細扁麵 | E19: 帕瑪森乾酪粉(500g) | F19: 5 | G19: 公克 | H19: 100 | T19: V | U19: =IF($E19="","",COUNTIF($I19:$S19,"V")) -> 0 | V19: =IF($E19="","",IF(AND($T19="V",$U19>0),"⚠ 勾選矛盾",IF($T19="V","○ 免調理",IF($U19=0,"⚠ 資料缺漏",IF($U19=1,"▲ 單一設備依賴","OK"))))) -> ○ 免調理 | W19: =IF($E19="","",IF(AND($T19="V",$U19>0),"「無使用調理設備」不可與設備欄同時勾選，請擇一修正",IF($T19="V","免調理半成品（外購/僅切配等），不列入設備風險評估",IF($U19=0,"未勾選任何設備，請補填或勾選「無使用調理設備」",IF($U19=1,"僅依賴1台設備，須確認故障/排修時之備援製程","無異常"))))) -> 免調理半成品（外購/僅切配等），不列入設備風險評估 | Z19: =IF($D19="",0,IF(COUNTIF($D$5:$D19,$D19)=1,1,0)) -> 0 | AA19: =IF(Z19=1,SUM($Z$5:$Z19),"")
A20: 下架 | B20: 長家 | C20: 熱食義麵 | D20: 奶油鮮蝦明太子細扁麵 | E20: 川燙9號蝦 | F20: 20 | G20: 公克 | H20: 50 | O20: V | U20: =IF($E20="","",COUNTIF($I20:$S20,"V")) -> 1 | V20: =IF($E20="","",IF(AND($T20="V",$U20>0),"⚠ 勾選矛盾",IF($T20="V","○ 免調理",IF($U20=0,"⚠ 資料缺漏",IF($U20=1,"▲ 單一設備依賴","OK"))))) -> ▲ 單一設備依賴 | W20: =IF($E20="","",IF(AND($T20="V",$U20>0),"「無使用調理設備」不可與設備欄同時勾選，請擇一修正",IF($T20="V","免調理半成品（外購/僅切配等），不列入設備風險評估",IF($U20=0,"未勾選任何設備，請補填或勾選「無使用調理設備」",IF($U20=1,"僅依賴1台設備，須確認故障/排修時之備援製程","無異常"))))) -> 僅依賴1台設備，須確認故障/排修時之備援製程 | Z20: =IF($D20="",0,IF(COUNTIF($D$5:$D20,$D20)=1,1,0)) -> 0 | AA20: =IF(Z20=1,SUM($Z$5:$Z20),"")
A21: 下架 | B21: 長家 | C21: 熱食義麵 | D21: 奶油鮮蝦明太子細扁麵 | E21: 解凍-辛子明太子醬 | F21: 12 | G21: 公克 | H21: 100 | T21: V | U21: =IF($E21="","",COUNTIF($I21:$S21,"V")) -> 0 | V21: =IF($E21="","",IF(AND($T21="V",$U21>0),"⚠ 勾選矛盾",IF($T21="V","○ 免調理",IF($U21=0,"⚠ 資料缺漏",IF($U21=1,"▲ 單一設備依賴","OK"))))) -> ○ 免調理 | W21: =IF($E21="","",IF(AND($T21="V",$U21>0),"「無使用調理設備」不可與設備欄同時勾選，請擇一修正",IF($T21="V","免調理半成品（外購/僅切配等），不列入設備風險評估",IF($U21=0,"未勾選任何設備，請補填或勾選「無使用調理設備」",IF($U21=1,"僅依賴1台設備，須確認故障/排修時之備援製程","無異常"))))) -> 免調理半成品（外購/僅切配等），不列入設備風險評估 | Z21: =IF($D21="",0,IF(COUNTIF($D$5:$D21,$D21)=1,1,0)) -> 0 | AA21: =IF(Z21=1,SUM($Z$5:$Z21),"")
A22: 下架 | B22: 長家 | C22: 熱食義麵 | D22: 奶油鮮蝦明太子細扁麵 | E22: 清洗蔥花 | F22: 3 | G22: 公克 | H22: 95 | T22: V | U22: =IF($E22="","",COUNTIF($I22:$S22,"V")) -> 0 | V22: =IF($E22="","",IF(AND($T22="V",$U22>0),"⚠ 勾選矛盾",IF($T22="V","○ 免調理",IF($U22=0,"⚠ 資料缺漏",IF($U22=1,"▲ 單一設備依賴","OK"))))) -> ○ 免調理 | W22: =IF($E22="","",IF(AND($T22="V",$U22>0),"「無使用調理設備」不可與設備欄同時勾選，請擇一修正",IF($T22="V","免調理半成品（外購/僅切配等），不列入設備風險評估",IF($U22=0,"未勾選任何設備，請補填或勾選「無使用調理設備」",IF($U22=1,"僅依賴1台設備，須確認故障/排修時之備援製程","無異常"))))) -> 免調理半成品（外購/僅切配等），不列入設備風險評估 | Z22: =IF($D22="",0,IF(COUNTIF($D$5:$D22,$D22)=1,1,0)) -> 0 | AA22: =IF(Z22=1,SUM($Z$5:$Z22),"")
A23: 架上 | B23: 長家 | C23: 熱食義麵 | D23: 白酒清炒鮮蛤義大利麵 | E23: 煮日製義大利麵(115) | F23: 220 | G23: 公克 | H23: 240 | J23: V | U23: =IF($E23="","",COUNTIF($I23:$S23,"V")) -> 1 | V23: =IF($E23="","",IF(AND($T23="V",$U23>0),"⚠ 勾選矛盾",IF($T23="V","○ 免調理",IF($U23=0,"⚠ 資料缺漏",IF($U23=1,"▲ 單一設備依賴","OK"))))) -> ▲ 單一設備依賴 | W23: =IF($E23="","",IF(AND($T23="V",$U23>0),"「無使用調理設備」不可與設備欄同時勾選，請擇一修正",IF($T23="V","免調理半成品（外購/僅切配等），不列入設備風險評估",IF($U23=0,"未勾選任何設備，請補填或勾選「無使用調理設備」",IF($U23=1,"僅依賴1台設備，須確認故障/排修時之備援製程","無異常"))))) -> 僅依賴1台設備，須確認故障/排修時之備援製程 | Z23: =IF($D23="",0,IF(COUNTIF($D$5:$D23,$D23)=1,1,0)) -> 1 | AA23: =IF(Z23=1,SUM($Z$5:$Z23),"") -> 4
A24: 架上 | B24: 長家 | C24: 熱食義麵 | D24: 白酒清炒鮮蛤義大利麵 | E24: 義麵-海鮮湯凍(115年) | F24: 75 | G24: 公克 | H24: 82 | O24: V | U24: =IF($E24="","",COUNTIF($I24:$S24,"V")) -> 1 | V24: =IF($E24="","",IF(AND($T24="V",$U24>0),"⚠ 勾選矛盾",IF($T24="V","○ 免調理",IF($U24=0,"⚠ 資料缺漏",IF($U24=1,"▲ 單一設備依賴","OK"))))) -> ▲ 單一設備依賴 | W24: =IF($E24="","",IF(AND($T24="V",$U24>0),"「無使用調理設備」不可與設備欄同時勾選，請擇一修正",IF($T24="V","免調理半成品（外購/僅切配等），不列入設備風險評估",IF($U24=0,"未勾選任何設備，請補填或勾選「無使用調理設備」",IF($U24=1,"僅依賴1台設備，須確認故障/排修時之備援製程","無異常"))))) -> 僅依賴1台設備，須確認故障/排修時之備援製程 | Z24: =IF($D24="",0,IF(COUNTIF($D$5:$D24,$D24)=1,1,0)) -> 0 | AA24: =IF(Z24=1,SUM($Z$5:$Z24),"")
A25: 架上 | B25: 長家 | C25: 熱食義麵 | D25: 白酒清炒鮮蛤義大利麵 | E25: 蒸蛤蜊-肉(112年) | F25: 40 | G25: 公克 | H25: 50 | M25: V | U25: =IF($E25="","",COUNTIF($I25:$S25,"V")) -> 1 | V25: =IF($E25="","",IF(AND($T25="V",$U25>0),"⚠ 勾選矛盾",IF($T25="V","○ 免調理",IF($U25=0,"⚠ 資料缺漏",IF($U25=1,"▲ 單一設備依賴","OK"))))) -> ▲ 單一設備依賴 | W25: =IF($E25="","",IF(AND($T25="V",$U25>0),"「無使用調理設備」不可與設備欄同時勾選，請擇一修正",IF($T25="V","免調理半成品（外購/僅切配等），不列入設備風險評估",IF($U25=0,"未勾選任何設備，請補填或勾選「無使用調理設備」",IF($U25=1,"僅依賴1台設備，須確認故障/排修時之備援製程","無異常"))))) -> 僅依賴1台設備，須確認故障/排修時之備援製程 | Z25: =IF($D25="",0,IF(COUNTIF($D$5:$D25,$D25)=1,1,0)) -> 0 | AA25: =IF(Z25=1,SUM($Z$5:$Z25),"")
A26: 架上 | B26: 長家 | C26: 熱食義麵 | D26: 白酒清炒鮮蛤義大利麵 | E26: 川燙青花菜(N7) | F26: 8 | G26: 公克 | H26: 68 | O26: V | U26: =IF($E26="","",COUNTIF($I26:$S26,"V")) -> 1 | V26: =IF($E26="","",IF(AND($T26="V",$U26>0),"⚠ 勾選矛盾",IF($T26="V","○ 免調理",IF($U26=0,"⚠ 資料缺漏",IF($U26=1,"▲ 單一設備依賴","OK"))))) -> ▲ 單一設備依賴 | W26: =IF($E26="","",IF(AND($T26="V",$U26>0),"「無使用調理設備」不可與設備欄同時勾選，請擇一修正",IF($T26="V","免調理半成品（外購/僅切配等），不列入設備風險評估",IF($U26=0,"未勾選任何設備，請補填或勾選「無使用調理設備」",IF($U26=1,"僅依賴1台設備，須確認故障/排修時之備援製程","無異常"))))) -> 僅依賴1台設備，須確認故障/排修時之備援製程 | Z26: =IF($D26="",0,IF(COUNTIF($D$5:$D26,$D26)=1,1,0)) -> 0 | AA26: =IF(Z26=1,SUM($Z$5:$Z26),"")
A27: 架上 | B27: 長家 | C27: 熱食義麵 | D27: 白酒清炒鮮蛤義大利麵 | E27: (殺菌)AD辣椒圈 | F27: 0.3 | G27: 公克 | H27: 100 | T27: V | U27: =IF($E27="","",COUNTIF($I27:$S27,"V")) -> 0 | V27: =IF($E27="","",IF(AND($T27="V",$U27>0),"⚠ 勾選矛盾",IF($T27="V","○ 免調理",IF($U27=0,"⚠ 資料缺漏",IF($U27=1,"▲ 單一設備依賴","OK"))))) -> ○ 免調理 | W27: =IF($E27="","",IF(AND($T27="V",$U27>0),"「無使用調理設備」不可與設備欄同時勾選，請擇一修正",IF($T27="V","免調理半成品（外購/僅切配等），不列入設備風險評估",IF($U27=0,"未勾選任何設備，請補填或勾選「無使用調理設備」",IF($U27=1,"僅依賴1台設備，須確認故障/排修時之備援製程","無異常"))))) -> 免調理半成品（外購/僅切配等），不列入設備風險評估 | Z27: =IF($D27="",0,IF(COUNTIF($D$5:$D27,$D27)=1,1,0)) -> 0 | AA27: =IF(Z27=1,SUM($Z$5:$Z27),"")
A28: 下架 | B28: 長家 | C28: 熱食義麵 | D28: 沙茶豬肉炒麵 | E28: 煮調色蒜味燴汁湯凍 | F28: 18 | G28: 公克 | H28: 69 | O28: V | U28: =IF($E28="","",COUNTIF($I28:$S28,"V")) -> 1 | V28: =IF($E28="","",IF(AND($T28="V",$U28>0),"⚠ 勾選矛盾",IF($T28="V","○ 免調理",IF($U28=0,"⚠ 資料缺漏",IF($U28=1,"▲ 單一設備依賴","OK"))))) -> ▲ 單一設備依賴 | W28: =IF($E28="","",IF(AND($T28="V",$U28>0),"「無使用調理設備」不可與設備欄同時勾選，請擇一修正",IF($T28="V","免調理半成品（外購/僅切配等），不列入設備風險評估",IF($U28=0,"未勾選任何設備，請補填或勾選「無使用調理設備」",IF($U28=1,"僅依賴1台設備，須確認故障/排修時之備援製程","無異常"))))) -> 僅依賴1台設備，須確認故障/排修時之備援製程 | Z28: =IF($D28="",0,IF(COUNTIF($D$5:$D28,$D28)=1,1,0)) -> 1 | AA28: =IF(Z28=1,SUM($Z$5:$Z28),"") -> 5
A29: 下架 | B29: 長家 | C29: 熱食義麵 | D29: 沙茶豬肉炒麵 | E29: 炒沙茶炒麵 | F29: 234 | G29: 公克 | H29: 80 | J29: V | P29: V | U29: =IF($E29="","",COUNTIF($I29:$S29,"V")) -> 2 | V29: =IF($E29="","",IF(AND($T29="V",$U29>0),"⚠ 勾選矛盾",IF($T29="V","○ 免調理",IF($U29=0,"⚠ 資料缺漏",IF($U29=1,"▲ 單一設備依賴","OK"))))) -> OK | W29: =IF($E29="","",IF(AND($T29="V",$U29>0),"「無使用調理設備」不可與設備欄同時勾選，請擇一修正",IF($T29="V","免調理半成品（外購/僅切配等），不列入設備風險評估",IF($U29=0,"未勾選任何設備，請補填或勾選「無使用調理設備」",IF($U29=1,"僅依賴1台設備，須確認故障/排修時之備援製程","無異常"))))) -> 無異常 | Z29: =IF($D29="",0,IF(COUNTIF($D$5:$D29,$D29)=1,1,0)) -> 0 | AA29: =IF(Z29=1,SUM($Z$5:$Z29),"")
A30: 下架 | B30: 長家 | C30: 熱食義麵 | D30: 沙茶豬肉炒麵 | E30: 113年煮沙茶炒麵湯凍 | F30: 42 | G30: 公克 | H30: 70 | O30: V | U30: =IF($E30="","",COUNTIF($I30:$S30,"V")) -> 1 | V30: =IF($E30="","",IF(AND($T30="V",$U30>0),"⚠ 勾選矛盾",IF($T30="V","○ 免調理",IF($U30=0,"⚠ 資料缺漏",IF($U30=1,"▲ 單一設備依賴","OK"))))) -> ▲ 單一設備依賴 | W30: =IF($E30="","",IF(AND($T30="V",$U30>0),"「無使用調理設備」不可與設備欄同時勾選，請擇一修正",IF($T30="V","免調理半成品（外購/僅切配等），不列入設備風險評估",IF($U30=0,"未勾選任何設備，請補填或勾選「無使用調理設備」",IF($U30=1,"僅依賴1台設備，須確認故障/排修時之備援製程","無異常"))))) -> 僅依賴1台設備，須確認故障/排修時之備援製程 | Z30: =IF($D30="",0,IF(COUNTIF($D$5:$D30,$D30)=1,1,0)) -> 0 | AA30: =IF(Z30=1,SUM($Z$5:$Z30),"")
A31: 下架 | B31: 長家 | C31: 熱食義麵 | D31: 沙茶豬肉炒麵 | E31: 113年炒沙茶豬肉片 | F31: 25 | G31: 公克 | H31: 60 | O31: V | U31: =IF($E31="","",COUNTIF($I31:$S31,"V")) -> 1 | V31: =IF($E31="","",IF(AND($T31="V",$U31>0),"⚠ 勾選矛盾",IF($T31="V","○ 免調理",IF($U31=0,"⚠ 資料缺漏",IF($U31=1,"▲ 單一設備依賴","OK"))))) -> ▲ 單一設備依賴 | W31: =IF($E31="","",IF(AND($T31="V",$U31>0),"「無使用調理設備」不可與設備欄同時勾選，請擇一修正",IF($T31="V","免調理半成品（外購/僅切配等），不列入設備風險評估",IF($U31=0,"未勾選任何設備，請補填或勾選「無使用調理設備」",IF($U31=1,"僅依賴1台設備，須確認故障/排修時之備援製程","無異常"))))) -> 僅依賴1台設備，須確認故障/排修時之備援製程 | Z31: =IF($D31="",0,IF(COUNTIF($D$5:$D31,$D31)=1,1,0)) -> 0 | AA31: =IF(Z31=1,SUM($Z$5:$Z31),"")
A32: 下架 | B32: 長家 | C32: 熱食義麵 | D32: 沙茶豬肉炒麵 | E32: 炒高麗菜紅蘿蔔絲 | F32: 12 | G32: 公克 | H32: 68 | O32: V | U32: =IF($E32="","",COUNTIF($I32:$S32,"V")) -> 1 | V32: =IF($E32="","",IF(AND($T32="V",$U32>0),"⚠ 勾選矛盾",IF($T32="V","○ 免調理",IF($U32=0,"⚠ 資料缺漏",IF($U32=1,"▲ 單一設備依賴","OK"))))) -> ▲ 單一設備依賴 | W32: =IF($E32="","",IF(AND($T32="V",$U32>0),"「無使用調理設備」不可與設備欄同時勾選，請擇一修正",IF($T32="V","免調理半成品（外購/僅切配等），不列入設備風險評估",IF($U32=0,"未勾選任何設備，請補填或勾選「無使用調理設備」",IF($U32=1,"僅依賴1台設備，須確認故障/排修時之備援製程","無異常"))))) -> 僅依賴1台設備，須確認故障/排修時之備援製程 | Z32: =IF($D32="",0,IF(COUNTIF($D$5:$D32,$D32)=1,1,0)) -> 0 | AA32: =IF(Z32=1,SUM($Z$5:$Z32),"")
A33: 下架 | B33: 長家 | C33: 熱食義麵 | D33: 沙茶豬肉炒麵 | E33: 炒沙茶醬 | F33: 5 | G33: 公克 | H33: 80 | O33: V | U33: =IF($E33="","",COUNTIF($I33:$S33,"V")) -> 1 | V33: =IF($E33="","",IF(AND($T33="V",$U33>0),"⚠ 勾選矛盾",IF($T33="V","○ 免調理",IF($U33=0,"⚠ 資料缺漏",IF($U33=1,"▲ 單一設備依賴","OK"))))) -> ▲ 單一設備依賴 | W33: =IF($E33="","",IF(AND($T33="V",$U33>0),"「無使用調理設備」不可與設備欄同時勾選，請擇一修正",IF($T33="V","免調理半成品（外購/僅切配等），不列入設備風險評估",IF($U33=0,"未勾選任何設備，請補填或勾選「無使用調理設備」",IF($U33=1,"僅依賴1台設備，須確認故障/排修時之備援製程","無異常"))))) -> 僅依賴1台設備，須確認故障/排修時之備援製程 | Z33: =IF($D33="",0,IF(COUNTIF($D$5:$D33,$D33)=1,1,0)) -> 0 | AA33: =IF(Z33=1,SUM($Z$5:$Z33),"")
A34: 下架 | B34: 長家 | C34: 熱食義麵 | D34: 沙茶豬肉炒麵 | E34: 油炒辣椒圈 | F34: 1 | G34: 公克 | H34: 74 | O34: V | U34: =IF($E34="","",COUNTIF($I34:$S34,"V")) -> 1 | V34: =IF($E34="","",IF(AND($T34="V",$U34>0),"⚠ 勾選矛盾",IF($T34="V","○ 免調理",IF($U34=0,"⚠ 資料缺漏",IF($U34=1,"▲ 單一設備依賴","OK"))))) -> ▲ 單一設備依賴 | W34: =IF($E34="","",IF(AND($T34="V",$U34>0),"「無使用調理設備」不可與設備欄同時勾選，請擇一修正",IF($T34="V","免調理半成品（外購/僅切配等），不列入設備風險評估",IF($U34=0,"未勾選任何設備，請補填或勾選「無使用調理設備」",IF($U34=1,"僅依賴1台設備，須確認故障/排修時之備援製程","無異常"))))) -> 僅依賴1台設備，須確認故障/排修時之備援製程 | Z34: =IF($D34="",0,IF(COUNTIF($D$5:$D34,$D34)=1,1,0)) -> 0 | AA34: =IF(Z34=1,SUM($Z$5:$Z34),"")
A35: 架上 | B35: 長家 | C35: 熱食義麵 | D35: 府城鹽水意麵 | E35: 煮鹽水意麵 | F35: 230 | G35: 公克 | H35: 160 | J35: V | U35: =IF($E35="","",COUNTIF($I35:$S35,"V")) -> 1 | V35: =IF($E35="","",IF(AND($T35="V",$U35>0),"⚠ 勾選矛盾",IF($T35="V","○ 免調理",IF($U35=0,"⚠ 資料缺漏",IF($U35=1,"▲ 單一設備依賴","OK"))))) -> ▲ 單一設備依賴 | W35: =IF($E35="","",IF(AND($T35="V",$U35>0),"「無使用調理設備」不可與設備欄同時勾選，請擇一修正",IF($T35="V","免調理半成品（外購/僅切配等），不列入設備風險評估",IF($U35=0,"未勾選任何設備，請補填或勾選「無使用調理設備」",IF($U35=1,"僅依賴1台設備，須確認故障/排修時之備援製程","無異常"))))) -> 僅依賴1台設備，須確認故障/排修時之備援製程 | Z35: =IF($D35="",0,IF(COUNTIF($D$5:$D35,$D35)=1,1,0)) -> 1 | AA35: =IF(Z35=1,SUM($Z$5:$Z35),"") -> 6
A36: 架上 | B36: 長家 | C36: 熱食義麵 | D36: 府城鹽水意麵 | E36: 煮意麵肉燥 | F36: 70 | G36: 公克 | H36: 53 | O36: V | U36: =IF($E36="","",COUNTIF($I36:$S36,"V")) -> 1 | V36: =IF($E36="","",IF(AND($T36="V",$U36>0),"⚠ 勾選矛盾",IF($T36="V","○ 免調理",IF($U36=0,"⚠ 資料缺漏",IF($U36=1,"▲ 單一設備依賴","OK"))))) -> ▲ 單一設備依賴 | W36: =IF($E36="","",IF(AND($T36="V",$U36>0),"「無使用調理設備」不可與設備欄同時勾選，請擇一修正",IF($T36="V","免調理半成品（外購/僅切配等），不列入設備風險評估",IF($U36=0,"未勾選任何設備，請補填或勾選「無使用調理設備」",IF($U36=1,"僅依賴1台設備，須確認故障/排修時之備援製程","無異常"))))) -> 僅依賴1台設備，須確認故障/排修時之備援製程 | Z36: =IF($D36="",0,IF(COUNTIF($D$5:$D36,$D36)=1,1,0)) -> 0 | AA36: =IF(Z36=1,SUM($Z$5:$Z36),"")
A37: 架上 | B37: 長家 | C37: 熱食義麵 | D37: 府城鹽水意麵 | E37: 切蒸前腿肉 | F37: 8 | G37: 公克 | H37: 66 | M37: V | U37: =IF($E37="","",COUNTIF($I37:$S37,"V")) -> 1 | V37: =IF($E37="","",IF(AND($T37="V",$U37>0),"⚠ 勾選矛盾",IF($T37="V","○ 免調理",IF($U37=0,"⚠ 資料缺漏",IF($U37=1,"▲ 單一設備依賴","OK"))))) -> ▲ 單一設備依賴 | W37: =IF($E37="","",IF(AND($T37="V",$U37>0),"「無使用調理設備」不可與設備欄同時勾選，請擇一修正",IF($T37="V","免調理半成品（外購/僅切配等），不列入設備風險評估",IF($U37=0,"未勾選任何設備，請補填或勾選「無使用調理設備」",IF($U37=1,"僅依賴1台設備，須確認故障/排修時之備援製程","無異常"))))) -> 僅依賴1台設備，須確認故障/排修時之備援製程 | Z37: =IF($D37="",0,IF(COUNTIF($D$5:$D37,$D37)=1,1,0)) -> 0 | AA37: =IF(Z37=1,SUM($Z$5:$Z37),"")
A38: 架上 | B38: 長家 | C38: 熱食義麵 | D38: 府城鹽水意麵 | E38: 對切滷蛋 | F38: 20 | G38: 公克 | H38: 200 | T38: V | U38: =IF($E38="","",COUNTIF($I38:$S38,"V")) -> 0 | V38: =IF($E38="","",IF(AND($T38="V",$U38>0),"⚠ 勾選矛盾",IF($T38="V","○ 免調理",IF($U38=0,"⚠ 資料缺漏",IF($U38=1,"▲ 單一設備依賴","OK"))))) -> ○ 免調理 | W38: =IF($E38="","",IF(AND($T38="V",$U38>0),"「無使用調理設備」不可與設備欄同時勾選，請擇一修正",IF($T38="V","免調理半成品（外購/僅切配等），不列入設備風險評估",IF($U38=0,"未勾選任何設備，請補填或勾選「無使用調理設備」",IF($U38=1,"僅依賴1台設備，須確認故障/排修時之備援製程","無異常"))))) -> 免調理半成品（外購/僅切配等），不列入設備風險評估 | Z38: =IF($D38="",0,IF(COUNTIF($D$5:$D38,$D38)=1,1,0)) -> 0 | AA38: =IF(Z38=1,SUM($Z$5:$Z38),"")
